Workbook

Sheet summary
A1: DAILY CREW MONITORING
A2: MAY | B2: Count of Crew | F2: Effective Personnel Count | G2: Effective Monthly Capability | H2: Effective Weekly Capability | I2: Effective Daily Capabiity
A3: CONTRACTOR | B3: Basket | C3: Stake | D3: Trucco | E3: Crane
A4: AVECO | B4: 3 | C4: 1 | D4: 1 | E4: 1 | F4: =(B4*4)+(C4*6)+(D4*4)+(E4*3) -> 25 | G4: =($F4*8*26)/1.8245 -> 2850.0959 | H4: =G4/4 -> 712.52398 | I4: =($F4*8)/1.8245 -> 109.61907
A5: CHALLENGER | B5: 2 | C5: 1 | D5: 1 | E5: 1 | F5: =(B5*4)+(C5*6)+(D5*4)+(E5*3) -> 21 | G5: =($F5*8*26)/1.8245 -> 2394.0806 | H5: =G5/4 -> 598.52014 | I5: =($F5*8)/1.8245 -> 92.080022
A6: ECOM | B6: 2 | C6: 1 | D6: 1 | E6: 1 | F6: =(B6*4)+(C6*6)+(D6*4)+(E6*3) -> 21 | G6: =($F6*8*26)/1.8245 -> 2394.0806 | H6: =G6/4 -> 598.52014 | I6: =($F6*8)/1.8245 -> 92.080022
A7: POWERHOUSE | B7: 2 | C7: 1 | D7: 1 | E7: 1 | F7: =(B7*4)+(C7*6)+(D7*4)+(E7*3) -> 21 | G7: =($F7*8*26)/1.8245 -> 2394.0806 | H7: =G7/4 -> 598.52014 | I7: =($F7*8)/1.8245 -> 92.080022
A8: VJC | B8: 2 | C8: 1 | E8: 1 | F8: =(B8*4)+(C8*6)+(D8*4)+(E8*3) -> 17 | G8: =($F8*8*26)/1.8245 -> 1938.0652 | H8: =G8/4 -> 484.51631 | I8: =($F8*8)/1.8245 -> 74.54097
A9: TOTAL | B9: =SUM(B4:B8) -> 11 | C9: =SUM(C4:C8) -> 5 | D9: =SUM(D4:D8) -> 4 | E9: =SUM(E4:E8) -> 5 | F9: =SUM(F4:F8) -> 105 | G9: =(F9*8*26)/1.8245 -> 11970.403 | H9: =SUM(H4:H8) -> 2992.6007 | I9: =SUM(I4:I8) -> 460.40011
B11: calculate total duty mhrs for the day
A12: DATE | B12: AVECO | C12: CCBC | D12: ECOM | E12: PH | F12: VJC | G12: TOTAL | H12: Remarks, if incomplete crew
A13: 45799 | B13: ='MAY 2025'!G14 -> 0 | C13: ='MAY 2025'!M14 -> 61.386681 | D13: ='MAY 2025'!S14 -> 61.386681 | E13: ='MAY 2025'!Y14 -> 0 | F13: ='MAY 2025'!AE14 -> 17.539052 | G13: =SUM(B13:F13) -> 140.31241 | H13: Aveco assigned to C2
A14: 45800 | B14: ='MAY 2025'!G15 -> 17.539052 | C14: ='MAY 2025'!M15 -> 74.54097 | D14: ='MAY 2025'!S15 -> 57.001918 | E14: ='MAY 2025'!Y15 -> 17.539052 | F14: ='MAY 2025'!AE15 -> 61.386681 | G14: =SUM(B14:F14) -> 228.00767 | H14: Powerhouse-C2 po Muna habol lang sa preparation Ng pai sa marina
A15: 45801 | B15: ='MAY 2025'!G16 -> 109.61907 | C15: ='MAY 2025'!M16 -> 74.54097 | D15: ='MAY 2025'!S16 -> 43.847629 | E15: ='MAY 2025'!Y16 -> 0 | F15: ='MAY 2025'!AE16 -> 35.078104 | G15: =SUM(B15:F15) -> 263.08578 | H15: Powerhouse-c/o C2; 1 BT & 1 ST of VJC - assist sa Pasig PAI
A16: 45802 | B16: ='MAY 2025'!G17 -> 57.001918 | C16: ='MAY 2025'!M17 -> 0 | D16: ='MAY 2025'!S17 -> 0 | E16: ='MAY 2025'!Y17 -> 0 | F16: ='MAY 2025'!AE17 -> 0 | G16: =SUM(B16:F16) -> 57.001918 | H16: Aveco, Powerhouse, CCBC c/o C2. VJC no duty teambuilding
A17: 45803 | B17: ='MAY 2025'!G18 -> 43.847629 | C17: ='MAY 2025'!M18 -> 74.54097 | D17: ='MAY 2025'!S18 -> 57.001918 | E17: ='MAY 2025'!Y18 -> 0 | F17: ='MAY 2025'!AE18 -> 0 | G17: =SUM(B17:F17) -> 175.39052 | H17: VJC no duty teambuilding. Powerhouse konti pumasok tao at napalaban kahapon sa pai
A18: 45804 | B18: ='MAY 2025'!G19 -> 92.080022 | C18: ='MAY 2025'!M19 -> 61.386681 | D18: ='MAY 2025'!S19 -> 57.001918 | E18: ='MAY 2025'!Y19 -> 57.001918 | F18: ='MAY 2025'!AE19 -> 35.078104 | G18: =SUM(B18:F18) -> 302.54864 | H18: VJC with C2 duty 2BT and hauler
A19: 45805 | B19: ='MAY 2025'!G20 -> 57.001918 | C19: ='MAY 2025'!M20 -> 74.54097 | D19: ='MAY 2025'!S20 -> 61.386681 | E19: ='MAY 2025'!Y20 -> 52.617155 | F19: ='MAY 2025'!AE20 -> 61.386681 | G19: =SUM(B19:F19) -> 306.93341 | H19: 1 Aveco BT assigned to MN; VJC crane assist to Pasig sector
A20: 45806 | B20: ='MAY 2025'!G21 -> 17.539052 | C20: ='MAY 2025'!M21 -> 74.54097 | D20: ='MAY 2025'!S21 -> 61.386681 | E20: ='MAY 2025'!Y21 -> 65.771444 | F20: ='MAY 2025'!AE21 -> 0 | G20: =SUM(B20:F20) -> 219.23815 | H20: VJC 2 BTc/o C2 & crane assist to Pasig sector; Aveco ST assigned to MN
A21: 45807 | B21: ='MAY 2025'!G22 -> 61.386681 | C21: ='MAY 2025'!M22 -> 149.08194 | D21: ='MAY 2025'!S22 -> 61.386681 | E21: ='MAY 2025'!Y22 -> 65.771444 | F21: ='MAY 2025'!AE22 -> 35.078104 | G21: =SUM(B21:F21) -> 372.70485 | H21: CCBC with night duty
A22: 45808 | B22: ='MAY 2025'!G23 -> 92.080022 | C22: ='MAY 2025'!M23 -> 74.54097 | D22: ='MAY 2025'!S23 -> 74.54097 | E22: ='MAY 2025'!Y23 -> 0 | F22: ='MAY 2025'!AE23 -> 61.386681 | G22: =SUM(B22:F22) -> 302.54864 | H22: PH no duty, galing 3rd shift; 1 VJC BT - assigned to C2
G23: =SUM(G13:G22) -> 2367.772
A26: JUNE | B26: Count of Crew | F26: Effective Personnel Count | G26: Effective Monthly Capability | H26: Effective Weekly Capability | I26: Effective Daily Capabiity
A27: CONTRACTOR | B27: Basket | C27: Stake | D27: Trucco | E27: Crane
A28: AVECO | B28: 3 | C28: 1 | D28: 1 | E28: 1 | F28: =(B28*4)+(C28*6)+(D28*4)+(E28*3) -> 25 | G28: =($F28*8*26)/1.8245 -> 2850.0959 | H28: =G28/4 -> 712.52398 | I28: =($F28*8)/1.8245 -> 109.61907
A29: CHALLENGER | B29: 2 | C29: 1 | D29: 1 | E29: 1 | F29: =(B29*4)+(C29*6)+(D29*4)+(E29*3) -> 21 | G29: =($F29*8*26)/1.8245 -> 2394.0806 | H29: =G29/4 -> 598.52014 | I29: =($F29*8)/1.8245 -> 92.080022
A30: ECOM | B30: 2 | C30: 1 | D30: 1 | E30: 1 | F30: =(B30*4)+(C30*6)+(D30*4)+(E30*3) -> 21 | G30: =($F30*8*26)/1.8245 -> 2394.0806 | H30: =G30/4 -> 598.52014 | I30: =($F30*8)/1.8245 -> 92.080022
A31: POWERHOUSE | B31: 2 | C31: 1 | D31: 1 | E31: 1 | F31: =(B31*4)+(C31*6)+(D31*4)+(E31*3) -> 21 | G31: =($F31*8*26)/1.8245 -> 2394.0806 | H31: =G31/4 -> 598.52014 | I31: =($F31*8)/1.8245 -> 92.080022
A32: VJC | B32: 2 | C32: 1 | E32: 1 | F32: =(B32*4)+(C32*6)+(D32*4)+(E32*3) -> 17 | G32: =($F32*8*26)/1.8245 -> 1938.0652 | H32: =G32/4 -> 484.51631 | I32: =($F32*8)/1.8245 -> 74.54097
A33: TOTAL | B33: =SUM(B28:B32) -> 11 | C33: =SUM(C28:C32) -> 5 | D33: =SUM(D28:D32) -> 4 | E33: =SUM(E28:E32) -> 5 | F33: =SUM(F28:F32) -> 105 | G33: =(F33*8*26)/1.8245 -> 11970.403 | H33: =SUM(H28:H32) -> 2992.6007 | I33: =SUM(I28:I32) -> 460.40011
B35: calculate total duty mhrs for the day
A36: DATE | B36: AVECO | C36: CCBC | D36: ECOM | E36: PH | F36: VJC | G36: TOTAL | H36: Remarks, if incomplete crew
A37: 45809 | B37: ='JUNE 2025'!G16 -> 0 | C37: ='JUNE 2025'!M16 -> 0 | D37: ='JUNE 2025'!S16 -> 0 | E37: ='JUNE 2025'!Y16 -> 0 | F37: ='JUNE 2025'!AE16 -> 0 | G37: =SUM(B37:F37) -> 0 | H37: NO SIGN-ON. DAY OFF ALL?
A38: 45810 | B38: ='JUNE 2025'!G17 -> 26.308578 | C38: ='JUNE 2025'!M17 -> 74.54097 | D38: ='JUNE 2025'!S17 -> 57.001918 | E38: ='JUNE 2025'!Y17 -> 35.078104 | F38: ='JUNE 2025'!AE17 -> 0 | G38: =SUM(B38:F38) -> 192.92957 | H38: VJC DAYOFF, AVECO dissolved po yung mga basket namin dahil late ang mga lineman sa safety meeting po
A39: 45811 | B39: ='JUNE 2025'!G18 -> 57.001918 | C39: ='JUNE 2025'!M18 -> 61.386681 | D39: ='JUNE 2025'!S18 -> 57.001918 | E39: ='JUNE 2025'!Y18 -> 127.15813 | F39: ='JUNE 2025'!AE18 -> 61.386681 | G39: =SUM(B39:F39) -> 363.93532
A40: 45812 | B40: ='JUNE 2025'!G19 -> 74.54097 | C40: ='JUNE 2025'!M19 -> 61.386681 | D40: ='JUNE 2025'!S19 -> 57.001918 | E40: ='JUNE 2025'!Y19 -> 17.539052 | F40: ='JUNE 2025'!AE19 -> 70.156207 | G40: =SUM(B40:F40) -> 280.62483 | H40: VJC STAKE TRUCK & CRANE ASSIST PASIG SECTOR; PH basket and crane truck namin ay currently may truck trouble; AVECO w/ C2 WORKS 2 LOCATION EMC & RECONDUCTORING
A41: 45813 | B41: ='JUNE 2025'!G20 -> 74.54097 | C41: ='JUNE 2025'!M20 -> 74.54097 | D41: ='JUNE 2025'!S20 -> 74.54097 | E41: ='JUNE 2025'!Y20 -> 0 | F41: ='JUNE 2025'!AE20 -> 43.847629 | G41: =SUM(B41:F41) -> 267.47054 | H41: VJC CRANE ASSIST PASIG SECTOR; POWERHOUSE cancelled duty due to crane trouble & redirected to the Estrada compound — doon po sa nasunugan
A42: 45814 | B42: ='JUNE 2025'!G21 -> 0 | C42: ='JUNE 2025'!M21 -> 0 | D42: ='JUNE 2025'!S21 -> 0 | E42: ='JUNE 2025'!Y21 -> 0 | F42: ='JUNE 2025'!AE21 -> 57.001918 | G42: =SUM(B42:F42) -> 57.001918 | H42: PH wala po pasok ang mga basket digging lang patrabaho; AVECO , ECOM & CCBC no duty holiday;
A43: 45815 | B43: ='JUNE 2025'!G22 -> 43.847629 | C43: ='JUNE 2025'!M22 -> 74.54097 | D43: ='JUNE 2025'!S22 -> 61.386681 | E43: ='JUNE 2025'!Y22 -> 92.080022 | F43: ='JUNE 2025'!AE22 -> 74.54097 | G43: =SUM(B43:F43) -> 346.39627 | H43: AVECO w/ MN work diging works
A44: 45816 | B44: ='JUNE 2025'!G23 -> 0 | C44: ='JUNE 2025'!M23 -> 0 | D44: ='JUNE 2025'!S23 -> 0 | E44: ='JUNE 2025'!Y23 -> 0 | F44: ='JUNE 2025'!AE23 -> 0 | G44: =SUM(B44:F44) -> 0 | H44: DAY OFF
...

Sheet MAY 2025
A1: DAILY CREW MONITORING
A2: MAY | B2: Count of Crew | F2: Effective Personnel Count | G2: Effective Monthly Capability | H2: Effective Weekly Capability | I2: Effective Daily Capabiity
A3: CONTRACTOR | B3: Basket | C3: Stake | D3: Trucco | E3: Crane | L3: TOTAL CAPABILITY FOR MAY
A4: AVECO | B4: 3 | C4: 1 | D4: 1 | E4: 1 | F4: =(B4*4)+(C4*6)+(D4*4)+(E4*3) -> 25 | G4: =($F4*8*26)/1.8245 -> 2850.0959 | H4: =G4/4 -> 712.52398 | I4: =($F4*8)/1.8245 -> 109.61907 | J4: =I4*19 -> 2082.7624 | K4: =G24 -> 548.09537 | L4: =J4+K4 -> 2630.8578 | P4: =I9*19 -> 8747.6021 | Q4: May 1-21 | R4: fixed cap
A5: CHALLENGER | B5: 2 | C5: 1 | D5: 1 | E5: 1 | F5: =(B5*4)+(C5*6)+(D5*4)+(E5*3) -> 21 | G5: =($F5*8*26)/1.8245 -> 2394.0806 | H5: =G5/4 -> 598.52014 | I5: =($F5*8)/1.8245 -> 92.080022 | J5: =I5*19 -> 1749.5204 | K5: =M24 -> 719.10112 | L5: =J5+K5 -> 2468.6215 | P5: =SUM(AF14:AF23) -> 2367.772 | Q5: May 22-31 | R5: daily monitoring
A6: ECOM | B6: 2 | C6: 1 | D6: 1 | E6: 1 | F6: =(B6*4)+(C6*6)+(D6*4)+(E6*3) -> 21 | G6: =($F6*8*26)/1.8245 -> 2394.0806 | H6: =G6/4 -> 598.52014 | I6: =($F6*8)/1.8245 -> 92.080022 | J6: =I6*19 -> 1749.5204 | K6: =S24 -> 534.94108 | L6: =J6+K6 -> 2284.4615 | P6: =P4+P5 -> 11115.374
A7: POWERHOUSE | B7: 2 | C7: 1 | D7: 1 | E7: 1 | F7: =(B7*4)+(C7*6)+(D7*4)+(E7*3) -> 21 | G7: =($F7*8*26)/1.8245 -> 2394.0806 | H7: =G7/4 -> 598.52014 | I7: =($F7*8)/1.8245 -> 92.080022 | J7: =I7*19 -> 1749.5204 | K7: =Y24 -> 258.70101 | L7: =J7+K7 -> 2008.2214
A8: VJC | B8: 2 | C8: 1 | E8: 1 | F8: =(B8*4)+(C8*6)+(D8*4)+(E8*3) -> 17 | G8: =($F8*8*26)/1.8245 -> 1938.0652 | H8: =G8/4 -> 484.51631 | I8: =($F8*8)/1.8245 -> 74.54097 | J8: =I8*19 -> 1416.2784 | K8: =AE24 -> 306.93341 | L8: =J8+K8 -> 1723.2118
A9: TOTAL | B9: =SUM(B4:B8) -> 11 | C9: =SUM(C4:C8) -> 5 | D9: =SUM(D4:D8) -> 4 | E9: =SUM(E4:E8) -> 5 | F9: =SUM(F4:F8) -> 105 | G9: =(F9*8*26)/1.8245 -> 11970.403 | H9: =SUM(H4:H8) -> 2992.6007 | I9: =SUM(I4:I8) -> 460.40011 | L9: =SUM(L4:L8) -> 11115.374 | M9: =P6/G9 -> 0.92857143
B11: AVECO | H11: CCBC | N11: ECOM | T11: POWERHOUSE | Z11: VJC | AF11: TOTAL
B12: Count of Crew | F12: Effective Personnel Count | G12: Crew Capability | H12: Count of Crew | L12: Effective Personnel Count | M12: Crew Capability | N12: Count of Crew | R12: Effective Personnel Count | S12: Crew Capability | T12: Count of Crew | X12: Effective Personnel Count | Y12: Crew Capability | Z12: Count of Crew | AD12: Effective Personnel Count | AE12: Crew Capability
A13: DATE | B13: Basket | C13: Stake | D13: Trucco | E13: Crane | H13: Basket | I13: Stake | J13: Trucco | K13: Crane | N13: Basket | O13: Stake | P13: Trucco | Q13: Crane | T13: Basket | U13: Stake | V13: Trucco | W13: Crane | Z13: Basket | AA13: Stake | AB13: Trucco | AC13: Crane
A14: 45799 | F14: =(B14*4)+(C14*6)+(D14*4)+(E14*3) -> 0 | G14: =(F14*8)/1.8245 -> 0 | H14: 2 | I14: 1 | L14: =(H14*4)+(I14*6)+(J14*4)+(K14*3) -> 14 | M14: =(L14*8)/1.8245 -> 61.386681 | N14: 2 | O14: 1 | R14: =(N14*4)+(O14*6)+(P14*4)+(Q14*3) -> 14 | S14: =(R14*8)/1.8245 -> 61.386681 | X14: =(T14*4)+(U14*6)+(V14*4)+(W14*3) -> 0 | Y14: =(X14*8)/1.8245 -> 0 | Z14: 1 | AD14: =(Z14*4)+(AA14*6)+(AB14*4)+(AC14*3) -> 4 | AE14: =(AD14*8)/1.8245 -> 17.539052 | AF14: =G14+M14+AE14+S14+Y14 -> 140.31241
A15: 45800 | B15: 1 | F15: =(B15*4)+(C15*6)+(D15*4)+(E15*3) -> 4 | G15: =(F15*8)/1.8245 -> 17.539052 | H15: 2 | I15: 1 | K15: 1 | L15: =(H15*4)+(I15*6)+(J15*4)+(K15*3) -> 17 | M15: =(L15*8)/1.8245 -> 74.54097 | N15: 1 | O15: 1 | Q15: 1 | R15: =(N15*4)+(O15*6)+(P15*4)+(Q15*3) -> 13 | S15: =(R15*8)/1.8245 -> 57.001918 | V15: 1 | X15: =(T15*4)+(U15*6)+(V15*4)+(W15*3) -> 4 | Y15: =(X15*8)/1.8245 -> 17.539052 | Z15: 2 | AA15: 1 | AD15: =(Z15*4)+(AA15*6)+(AB15*4)+(AC15*3) -> 14 | AE15: =(AD15*8)/1.8245 -> 61.386681 | AF15: =G15+M15+AE15+S15+Y15 -> 228.00767
A16: 45801 | B16: 3 | C16: 1 | D16: 1 | E16: 1 | F16: =(B16*4)+(C16*6)+(D16*4)+(E16*3) -> 25 | G16: =(F16*8)/1.8245 -> 109.61907 | H16: 2 | I16: 1 | K16: 1 | L16: =(H16*4)+(I16*6)+(J16*4)+(K16*3) -> 17 | M16: =(L16*8)/1.8245 -> 74.54097 | N16: 1 | O16: 1 | R16: =(N16*4)+(O16*6)+(P16*4)+(Q16*3) -> 10 | S16: =(R16*8)/1.8245 -> 43.847629 | X16: =(T16*4)+(U16*6)+(V16*4)+(W16*3) -> 0 | Y16: =(X16*8)/1.8245 -> 0 | Z16: 1 | AB16: 1 | AD16: =(Z16*4)+(AA16*6)+(AB16*4)+(AC16*3) -> 8 | AE16: =(AD16*8)/1.8245 -> 35.078104 | AF16: =G16+M16+AE16+S16+Y16 -> 263.08578
A17: 45802 | B17: 1 | C17: 1 | E17: 1 | F17: =(B17*4)+(C17*6)+(D17*4)+(E17*3) -> 13 | G17: =(F17*8)/1.8245 -> 57.001918 | L17: =(H17*4)+(I17*6)+(J17*4)+(K17*3) -> 0 | M17: =(L17*8)/1.8245 -> 0 | R17: =(N17*4)+(O17*6)+(P17*4)+(Q17*3) -> 0 | S17: =(R17*8)/1.8245 -> 0 | X17: =(T17*4)+(U17*6)+(V17*4)+(W17*3) -> 0 | Y17: =(X17*8)/1.8245 -> 0 | AD17: =(Z17*4)+(AA17*6)+(AB17*4)+(AC17*3) -> 0 | AE17: =(AD17*8)/1.8245 -> 0 | AF17: =G17+M17+AE17+S17+Y17 -> 57.001918
A18: 45803 | B18: 1 | C18: 1 | F18: =(B18*4)+(C18*6)+(D18*4)+(E18*3) -> 10 | G18: =(F18*8)/1.8245 -> 43.847629 | H18: 2 | I18: 1 | K18: 1 | L18: =(H18*4)+(I18*6)+(J18*4)+(K18*3) -> 17 | M18: =(L18*8)/1.8245 -> 74.54097 | N18: 1 | O18: 1 | Q18: 1 | R18: =(N18*4)+(O18*6)+(P18*4)+(Q18*3) -> 13 | S18: =(R18*8)/1.8245 -> 57.001918 | X18: =(T18*4)+(U18*6)+(V18*4)+(W18*3) -> 0 | Y18: =(X18*8)/1.8245 -> 0 | AD18: =(Z18*4)+(AA18*6)+(AB18*4)+(AC18*3) -> 0 | AE18: =(AD18*8)/1.8245 -> 0 | AF18: =G18+M18+AE18+S18+Y18 -> 175.39052
A19: 45804 | B19: 2 | C19: 1 | D19: 1 | E19: 1 | F19: =(B19*4)+(C19*6)+(D19*4)+(E19*3) -> 21 | G19: =(F19*8)/1.8245 -> 92.080022 | H19: 2 | I19: 1 | L19: =(H19*4)+(I19*6)+(J19*4)+(K19*3) -> 14 | M19: =(L19*8)/1.8245 -> 61.386681 | N19: 1 | O19: 1 | Q19: 1 | R19: =(N19*4)+(O19*6)+(P19*4)+(Q19*3) -> 13 | S19: =(R19*8)/1.8245 -> 57.001918 | T19: 1 | U19: 1 | W19: 1 | X19: =(T19*4)+(U19*6)+(V19*4)+(W19*3) -> 13 | Y19: =(X19*8)/1.8245 -> 57.001918 | Z19: 2 | AD19: =(Z19*4)+(AA19*6)+(AB19*4)+(AC19*3) -> 8 | AE19: =(AD19*8)/1.8245 -> 35.078104 | AF19: =G19+M19+AE19+S19+Y19 -> 302.54864
A20: 45805 | B20: 1 | C20: 1 | E20: 1 | F20: =(B20*4)+(C20*6)+(D20*4)+(E20*3) -> 13 | G20: =(F20*8)/1.8245 -> 57.001918 | H20: 2 | I20: 1 | K20: 1 | L20: =(H20*4)+(I20*6)+(J20*4)+(K20*3) -> 17 | M20: =(L20*8)/1.8245 -> 74.54097 | N20: 2 | O20: 1 | R20: =(N20*4)+(O20*6)+(P20*4)+(Q20*3) -> 14 | S20: =(R20*8)/1.8245 -> 61.386681 | T20: 2 | V20: 1 | X20: =(T20*4)+(U20*6)+(V20*4)+(W20*3) -> 12 | Y20: =(X20*8)/1.8245 -> 52.617155 | Z20: 2 | AA20: 1 | AD20: =(Z20*4)+(AA20*6)+(AB20*4)+(AC20*3) -> 14 | AE20: =(AD20*8)/1.8245 -> 61.386681 | AF20: =G20+M20+AE20+S20+Y20 -> 306.93341
A21: 45806 | B21: 1 | F21: =(B21*4)+(C21*6)+(D21*4)+(E21*3) -> 4 | G21: =(F21*8)/1.8245 -> 17.539052 | H21: 2 | I21: 1 | K21: 1 | L21: =(H21*4)+(I21*6)+(J21*4)+(K21*3) -> 17 | M21: =(L21*8)/1.8245 -> 74.54097 | N21: 2 | O21: 1 | R21: =(N21*4)+(O21*6)+(P21*4)+(Q21*3) -> 14 | S21: =(R21*8)/1.8245 -> 61.386681 | T21: 2 | V21: 1 | W21: 1 | X21: =(T21*4)+(U21*6)+(V21*4)+(W21*3) -> 15 | Y21: =(X21*8)/1.8245 -> 65.771444 | AD21: =(Z21*4)+(AA21*6)+(AB21*4)+(AC21*3) -> 0 | AE21: =(AD21*8)/1.8245 -> 0 | AF21: =G21+M21+AE21+S21+Y21 -> 219.23815
A22: 45807 | B22: 1 | C22: 1 | D22: 1 | F22: =(B22*4)+(C22*6)+(D22*4)+(E22*3) -> 14 | G22: =(F22*8)/1.8245 -> 61.386681 | H22: 4 | I22: 2 | K22: 2 | L22: =(H22*4)+(I22*6)+(J22*4)+(K22*3) -> 34 | M22: =(L22*8)/1.8245 -> 149.08194 | N22: 2 | O22: 1 | R22: =(N22*4)+(O22*6)+(P22*4)+(Q22*3) -> 14 | S22: =(R22*8)/1.8245 -> 61.386681 | T22: 2 | V22: 1 | W22: 1 | X22: =(T22*4)+(U22*6)+(V22*4)+(W22*3) -> 15 | Y22: =(X22*8)/1.8245 -> 65.771444 | Z22: 2 | AD22: =(Z22*4)+(AA22*6)+(AB22*4)+(AC22*3) -> 8 | AE22: =(AD22*8)/1.8245 -> 35.078104 | AF22: =G22+M22+AE22+S22+Y22 -> 372.70485
A23: 45808 | B23: 2 | C23: 1 | D23: 1 | E23: 1 | F23: =(B23*4)+(C23*6)+(D23*4)+(E23*3) -> 21 | G23: =(F23*8)/1.8245 -> 92.080022 | H23: 2 | I23: 1 | K23: 1 | L23: =(H23*4)+(I23*6)+(J23*4)+(K23*3) -> 17 | M23: =(L23*8)/1.8245 -> 74.54097 | N23: 1 | O23: 1 | P23: 1 | Q23: 1 | R23: =(N23*4)+(O23*6)+(P23*4)+(Q23*3) -> 17 | S23: =(R23*8)/1.8245 -> 74.54097 | X23: =(T23*4)+(U23*6)+(V23*4)+(W23*3) -> 0 | Y23: =(X23*8)/1.8245 -> 0 | Z23: 2 | AA23: 1 | AD23: =(Z23*4)+(AA23*6)+(AB23*4)+(AC23*3) -> 14 | AE23: =(AD23*8)/1.8245 -> 61.386681 | AF23: =G23+M23+AE23+S23+Y23 -> 302.54864
G24: =SUM(G14:G23) -> 548.09537 | M24: =SUM(M14:M23) -> 719.10112 | S24: =SUM(S14:S23) -> 534.94108 | Y24: =SUM(Y14:Y23) -> 258.70101 | AE24: =SUM(AE14:AE23) -> 306.93341 | AF24: =SUM(AF14:AF23) -> 2367.772

Sheet JUNE 2025
A1: DAILY CREW MONITORING
A2: JUNE | B2: Count of Crew | F2: Effective Personnel Count | G2: Effective Monthly Capability | H2: Effective Weekly Capability | I2: Effective Daily Capabiity
A3: CONTRACTOR | B3: Basket | C3: Stake | D3: Trucco | E3: Crane | L3: ACTUAL CAPABILITY FOR JUNE
A4: AVECO | B4: 3 | C4: 1 | D4: 1 | E4: 1 | F4: =(B4*4)+(C4*6)+(D4*4)+(E4*3) -> 25 | G4: =($F4*8*26)/1.8245 -> 2850.0959 | H4: =G4/4 -> 712.52398 | I4: =($F4*8)/1.8245 -> 109.61907 | J4: =M4/G4 -> 0.29846154 | L4: AVECO | M4: =SUM(G16:G45) -> 850.64401
A5: CHALLENGER | B5: 2 | C5: 1 | D5: 1 | E5: 1 | F5: =(B5*4)+(C5*6)+(D5*4)+(E5*3) -> 21 | G5: =($F5*8*26)/1.8245 -> 2394.0806 | H5: =G5/4 -> 598.52014 | I5: =($F5*8)/1.8245 -> 92.080022 | J5: =M5/G5 -> 0.57326007 | L5: CCBC | M5: =SUM(M16:M45) -> 1372.4308
A6: ECOM | B6: 2 | C6: 1 | D6: 1 | E6: 1 | F6: =(B6*4)+(C6*6)+(D6*4)+(E6*3) -> 21 | G6: =($F6*8*26)/1.8245 -> 2394.0806 | H6: =G6/4 -> 598.52014 | I6: =($F6*8)/1.8245 -> 92.080022 | J6: =M6/G6 -> 0.55128205 | L6: ECOM | M6: =SUM(S16:S45) -> 1319.8136
A7: POWERHOUSE | B7: 2 | C7: 1 | D7: 1 | E7: 1 | F7: =(B7*4)+(C7*6)+(D7*4)+(E7*3) -> 21 | G7: =($F7*8*26)/1.8245 -> 2394.0806 | H7: =G7/4 -> 598.52014 | I7: =($F7*8)/1.8245 -> 92.080022 | J7: =M7/G7 -> 0.42673993 | L7: POWERHOUSE | M7: =SUM(Y16:Y45) -> 1021.6498
A8: VJC | B8: 2 | C8: 1 | E8: 1 | F8: =(B8*4)+(C8*6)+(D8*4)+(E8*3) -> 17 | G8: =($F8*8*26)/1.8245 -> 1938.0652 | H8: =G8/4 -> 484.51631 | I8: =($F8*8)/1.8245 -> 74.54097 | J8: =M8/G8 -> 0.6719457 | L8: VJC | M8: =SUM(AE16:AE45) -> 1302.2746 | N8: June 1-13 | O8: June 14-30
A9: C2 | B9: 1 | F9: =(B9*4)+(C9*6)+(D9*4)+(E9*3) -> 4 | G9: =($F9*8*26)/1.8245 -> 456.01535 | H9: =G9/4 -> 114.00384 | I9: =($F9*8)/1.8245 -> 17.539052 | L9: C2 | M9: =N9+O9 -> 1582.903 | N9: 407.783 | O9: 1175.12
A10: MN | B10: 4 | F10: =(B10*4)+(C10*6)+(D10*4)+(E10*3) -> 16 | G10: =($F10*8*26)/1.8245 -> 1824.0614 | H10: =G10/4 -> 456.01535 | I10: =($F10*8)/1.8245 -> 70.156207 | L10: MN | M10: =N10+O10 -> 59.626 | N10: 59.626
A11: TOTAL | B11: =SUM(B4:B10) -> 16 | C11: =SUM(C4:C8) -> 5 | D11: =SUM(D4:D8) -> 4 | E11: =SUM(E4:E8) -> 5 | F11: =SUM(F4:F10) -> 125 | G11: =(F11*8*26)/1.8245 -> 14250.48 | H11: =SUM(H4:H10) -> 3562.6199 | I11: =SUM(I4:I8) -> 460.40011 | M11: =SUM(M4:M8) -> 5866.8128
G12: =SUM(G4:G8) -> 11970.403 | H12: C1 ONLY
B13: AVECO | H13: CCBC | N13: ECOM | T13: POWERHOUSE | Z13: VJC | AF13: TOTAL
B14: Count of Crew | F14: Effective Personnel Count | G14: Crew Capability | H14: Count of Crew | L14: Effective Personnel Count | M14: Crew Capability | N14: Count of Crew | R14: Effective Personnel Count | S14: Crew Capability | T14: Count of Crew | X14: Effective Personnel Count | Y14: Crew Capability | Z14: Count of Crew | AD14: Effective Personnel Count | AE14: Crew Capability
A15: DATE | B15: Basket | C15: Stake | D15: Trucco | E15: Crane | H15: Basket | I15: Stake | J15: Trucco | K15: Crane | N15: Basket | O15: Stake | P15: Trucco | Q15: Crane | T15: Basket | U15: Stake | V15: Trucco | W15: Crane | Z15: Basket | AA15: Stake | AB15: Trucco | AC15: Crane
A16: 45809 | F16: =(B16*4)+(C16*6)+(D16*4)+(E16*3) -> 0 | G16: =(F16*8)/1.8245 -> 0 | L16: =(H16*4)+(I16*6)+(J16*4)+(K16*3) -> 0 | M16: =(L16*8)/1.8245 -> 0 | R16: =(N16*4)+(O16*6)+(P16*4)+(Q16*3) -> 0 | S16: =(R16*8)/1.8245 -> 0 | X16: =(T16*4)+(U16*6)+(V16*4)+(W16*3) -> 0 | Y16: =(X16*8)/1.8245 -> 0 | AD16: =(Z16*4)+(AA16*6)+(AB16*4)+(AC16*3) -> 0 | AE16: =(AD16*8)/1.8245 -> 0 | AF16: =G16+M16+AE16+S16+Y16 -> 0
A17: 45810 | C17: 1 | F17: =(B17*4)+(C17*6)+(D17*4)+(E17*3) -> 6 | G17: =(F17*8)/1.8245 -> 26.308578 | H17: 2 | I17: 1 | K17: 1 | L17: =(H17*4)+(I17*6)+(J17*4)+(K17*3) -> 17 | M17: =(L17*8)/1.8245 -> 74.54097 | N17: 1 | O17: 1 | Q17: 1 | R17: =(N17*4)+(O17*6)+(P17*4)+(Q17*3) -> 13 | S17: =(R17*8)/1.8245 -> 57.001918 | T17: 2 | X17: =(T17*4)+(U17*6)+(V17*4)+(W17*3) -> 8 | Y17: =(X17*8)/1.8245 -> 35.078104 | AD17: =(Z17*4)+(AA17*6)+(AB17*4)+(AC17*3) -> 0 | AE17: =(AD17*8)/1.8245 -> 0 | AF17: =G17+M17+AE17+S17+Y17 -> 192.92957
A18: 45811 | B18: 1 | C18: 1 | E18: 1 | F18: =(B18*4)+(C18*6)+(D18*4)+(E18*3) -> 13 | G18: =(F18*8)/1.8245 -> 57.001918 | H18: 2 | I18: 1 | L18: =(H18*4)+(I18*6)+(J18*4)+(K18*3) -> 14 | M18: =(L18*8)/1.8245 -> 61.386681 | N18: 1 | O18: 1 | Q18: 1 | R18: =(N18*4)+(O18*6)+(P18*4)+(Q18*3) -> 13 | S18: =(R18*8)/1.8245 -> 57.001918 | T18: 2 | U18: 3 | W18: 1 | X18: =(T18*4)+(U18*6)+(V18*4)+(W18*3) -> 29 | Y18: =(X18*8)/1.8245 -> 127.15813 | Z18: 2 | AA18: 1 | AD18: =(Z18*4)+(AA18*6)+(AB18*4)+(AC18*3) -> 14 | AE18: =(AD18*8)/1.8245 -> 61.386681 | AF18: =G18+M18+AE18+S18+Y18 -> 363.93532
A19: 45812 | B19: 2 | C19: 1 | E19: 1 | F19: =(B19*4)+(C19*6)+(D19*4)+(E19*3) -> 17 | G19: =(F19*8)/1.8245 -> 74.54097 | H19: 2 | I19: 1 | L19: =(H19*4)+(I19*6)+(J19*4)+(K19*3) -> 14 | M19: =(L19*8)/1.8245 -> 61.386681 | N19: 1 | O19: 1 | Q19: 1 | R19: =(N19*4)+(O19*6)+(P19*4)+(Q19*3) -> 13 | S19: =(R19*8)/1.8245 -> 57.001918 | T19: 1 | X19: =(T19*4)+(U19*6)+(V19*4)+(W19*3) -> 4 | Y19: =(X19*8)/1.8245 -> 17.539052 | Z19: 4 | AD19: =(Z19*4)+(AA19*6)+(AB19*4)+(AC19*3) -> 16 | AE19: =(AD19*8)/1.8245 -> 70.156207 | AF19: =G19+M19+AE19+S19+Y19 -> 280.62483
A20: 45813 | B20: 2 | C20: 1 | E20: 1 | F20: =(B20*4)+(C20*6)+(D20*4)+(E20*3) -> 17 | G20: =(F20*8)/1.8245 -> 74.54097 | H20: 2 | I20: 1 | K20: 1 | L20: =(H20*4)+(I20*6)+(J20*4)+(K20*3) -> 17 | M20: =(L20*8)/1.8245 -> 74.54097 | N20: 2 | O20: 1 | Q20: 1 | R20: =(N20*4)+(O20*6)+(P20*4)+(Q20*3) -> 17 | S20: =(R20*8)/1.8245 -> 74.54097 | X20: =(T20*4)+(U20*6)+(V20*4)+(W20*3) -> 0 | Y20: =(X20*8)/1.8245 -> 0 | Z20: 1 | AA20: 1 | AD20: =(Z20*4)+(AA20*6)+(AB20*4)+(AC20*3) -> 10 | AE20: =(AD20*8)/1.8245 -> 43.847629 | AF20: =G20+M20+AE20+S20+Y20 -> 267.47054
A21: 45814 | F21: =(B21*4)+(C21*6)+(D21*4)+(E21*3) -> 0 | G21: =(F21*8)/1.8245 -> 0 | L21: =(H21*4)+(I21*6)+(J21*4)+(K21*3) -> 0 | M21: =(L21*8)/1.8245 -> 0 | R21: =(N21*4)+(O21*6)+(P21*4)+(Q21*3) -> 0 | S21: =(R21*8)/1.8245 -> 0 | X21: =(T21*4)+(U21*6)+(V21*4)+(W21*3) -> 0 | Y21: =(X21*8)/1.8245 -> 0 | Z21: 1 | AA21: 1 | AC21: 1 | AD21: =(Z21*4)+(AA21*6)+(AB21*4)+(AC21*3) -> 13 | AE21: =(AD21*8)/1.8245 -> 57.001918 | AF21: =G21+M21+AE21+S21+Y21 -> 57.001918
A22: 45815 | B22: 1 | C22: 1 | F22: =(B22*4)+(C22*6)+(D22*4)+(E22*3) -> 10 | G22: =(F22*8)/1.8245 -> 43.847629 | H22: 2 | I22: 1 | K22: 1 | L22: =(H22*4)+(I22*6)+(J22*4)+(K22*3) -> 17 | M22: =(L22*8)/1.8245 -> 74.54097 | N22: 2 | O22: 1 | R22: =(N22*4)+(O22*6)+(P22*4)+(Q22*3) -> 14 | S22: =(R22*8)/1.8245 -> 61.386681 | T22: 3 | U22: 1 | W22: 1 | X22: =(T22*4)+(U22*6)+(V22*4)+(W22*3) -> 21 | Y22: =(X22*8)/1.8245 -> 92.080022 | Z22: 2 | AA22: 1 | AC22: 1 | AD22: =(Z22*4)+(AA22*6)+(AB22*4)+(AC22*3) -> 17 | AE22: =(AD22*8)/1.8245 -> 74.54097 | AF22: =G22+M22+AE22+S22+Y22 -> 346.39627
A23: 45816 | F23: =(B23*4)+(C23*6)+(D23*4)+(E23*3) -> 0 | G23: =(F23*8)/1.8245 -> 0 | L23: =(H23*4)+(I23*6)+(J23*4)+(K23*3) -> 0 | M23: =(L23*8)/1.8245 -> 0 | R23: =(N23*4)+(O23*6)+(P23*4)+(Q23*3) -> 0 | S23: =(R23*8)/1.8245 -> 0 | X23: =(T23*4)+(U23*6)+(V23*4)+(W23*3) -> 0 | Y23: =(X23*8)/1.8245 -> 0 | AD23: =(Z23*4)+(AA23*6)+(AB23*4)+(AC23*3) -> 0 | AE23: =(AD23*8)/1.8245 -> 0 | AF23: =G23+M23+AE23+S23+Y23 -> 0
A24: 45817 | B24: 1 | C24: 2 | F24: =(B24*4)+(C24*6)+(D24*4)+(E24*3) -> 16 | G24: =(F24*8)/1.8245 -> 70.156207 | H24: 2 | I24: 1 | L24: =(H24*4)+(I24*6)+(J24*4)+(K24*3) -> 14 | M24: =(L24*8)/1.8245 -> 61.386681 | R24: =(N24*4)+(O24*6)+(P24*4)+(Q24*3) -> 0 | S24: =(R24*8)/1.8245 -> 0 | T24: 3 | U24: 1 | W24: 1 | X24: =(T24*4)+(U24*6)+(V24*4)+(W24*3) -> 21 | Y24: =(X24*8)/1.8245 -> 92.080022 | AD24: =(Z24*4)+(AA24*6)+(AB24*4)+(AC24*3) -> 0 | AE24: =(AD24*8)/1.8245 -> 0 | AF24: =G24+M24+AE24+S24+Y24 -> 223.62291
A25: 45818 | B25: 1 | C25: 1 | F25: =(B25*4)+(C25*6)+(D25*4)+(E25*3) -> 10 | G25: =(F25*8)/1.8245 -> 43.847629 | H25: 2 | I25: 1 | K25: 1 | L25: =(H25*4)+(I25*6)+(J25*4)+(K25*3) -> 17 | M25: =(L25*8)/1.8245 -> 74.54097 | N25: 1 | O25: 2 | R25: =(N25*4)+(O25*6)+(P25*4)+(Q25*3) -> 16 | S25: =(R25*8)/1.8245 -> 70.156207 | V25: 1 | W25: 1 | X25: =(T25*4)+(U25*6)+(V25*4)+(W25*3) -> 7 | Y25: =(X25*8)/1.8245 -> 30.693341 | Z25: 1 | AA25: 1 | AC25: 1 | AD25: =(Z25*4)+(AA25*6)+(AB25*4)+(AC25*3) -> 13 | AE25: =(AD25*8)/1.8245 -> 57.001918 | AF25: =G25+M25+AE25+S25+Y25 -> 276.24007
A26: 45819 | B26: 2 | C26: 1 | F26: =(B26*4)+(C26*6)+(D26*4)+(E26*3) -> 14 | G26: =(F26*8)/1.8245 -> 61.386681 | H26: 2 | I26: 1 | K26: 1 | L26: =(H26*4)+(I26*6)+(J26*4)+(K26*3) -> 17 | M26: =(L26*8)/1.8245 -> 74.54097 | O26: 1 | Q26: 1 | R26: =(N26*4)+(O26*6)+(P26*4)+(Q26*3) -> 9 | S26: =(R26*8)/1.8245 -> 39.462867 | T26: 2 | W26: 1 | X26: =(T26*4)+(U26*6)+(V26*4)+(W26*3) -> 11 | Y26: =(X26*8)/1.8245 -> 48.232392 | Z26: 1 | AA26: 1 | AC26: 1 | AD26: =(Z26*4)+(AA26*6)+(AB26*4)+(AC26*3) -> 13 | AE26: =(AD26*8)/1.8245 -> 57.001918 | AF26: =G26+M26+AE26+S26+Y26 -> 280.62483
A27: 45820 | F27: =(B27*4)+(C27*6)+(D27*4)+(E27*3) -> 0 | G27: =(F27*8)/1.8245 -> 0 | L27: =(H27*4)+(I27*6)+(J27*4)+(K27*3) -> 0 | M27: =(L27*8)/1.8245 -> 0 | R27: =(N27*4)+(O27*6)+(P27*4)+(Q27*3) -> 0 | S27: =(R27*8)/1.8245 -> 0 | X27: =(T27*4)+(U27*6)+(V27*4)+(W27*3) -> 0 | Y27: =(X27*8)/1.8245 -> 0 | Z27: 1 | AD27: =(Z27*4)+(AA27*6)+(AB27*4)+(AC27*3) -> 4 | AE27: =(AD27*8)/1.8245 -> 17.539052 | AF27: =G27+M27+AE27+S27+Y27 -> 17.539052
A28: 45821 | C28: 1 | F28: =(B28*4)+(C28*6)+(D28*4)+(E28*3) -> 6 | G28: =(F28*8)/1.8245 -> 26.308578 | H28: 2 | I28: 1 | K28: 1 | L28: =(H28*4)+(I28*6)+(J28*4)+(K28*3) -> 17 | M28: =(L28*8)/1.8245 -> 74.54097 | N28: 2 | O28: 1 | Q28: 1 | R28: =(N28*4)+(O28*6)+(P28*4)+(Q28*3) -> 17 | S28: =(R28*8)/1.8245 -> 74.54097 | T28: 2 | U28: 2 | W28: 1 | X28: =(T28*4)+(U28*6)+(V28*4)+(W28*3) -> 23 | Y28: =(X28*8)/1.8245 -> 100.84955 | Z28: 2 | AA28: 1 | AC28: 1 | AD28: =(Z28*4)+(AA28*6)+(AB28*4)+(AC28*3) -> 17 | AE28: =(AD28*8)/1.8245 -> 74.54097 | AF28: =G28+M28+AE28+S28+Y28 -> 350.78104
A29: 45822 | F29: =(B29*4)+(C29*6)+(D29*4)+(E29*3) -> 0 | G29: =(F29*8)/1.8245 -> 0 | H29: 2 | I29: 1 | K29: 1 | L29: =(H29*4)+(I29*6)+(J29*4)+(K29*3) -> 17 | M29: =(L29*8)/1.8245 -> 74.54097 | N29: 1 | O29: 1 | Q29: 1 | R29: =(N29*4)+(O29*6)+(P29*4)+(Q29*3) -> 13 | S29: =(R29*8)/1.8245 -> 57.001918 | X29: =(T29*4)+(U29*6)+(V29*4)+(W29*3) -> 0 | Y29: =(X29*8)/1.8245 -> 0 | Z29: 2 | AA29: 1 | AC29: 1 | AD29: =(Z29*4)+(AA29*6)+(AB29*4)+(AC29*3) -> 17 | AE29: =(AD29*8)/1.8245 -> 74.54097 | AF29: =G29+M29+AE29+S29+Y29 -> 206.08386
A30: 45823 | F30: =(B30*4)+(C30*6)+(D30*4)+(E30*3) -> 0 | G30: =(F30*8)/1.8245 -> 0 | L30: =(H30*4)+(I30*6)+(J30*4)+(K30*3) -> 0 | M30: =(L30*8)/1.8245 -> 0 | R30: =(N30*4)+(O30*6)+(P30*4)+(Q30*3) -> 0 | S30: =(R30*8)/1.8245 -> 0 | X30: =(T30*4)+(U30*6)+(V30*4)+(W30*3) -> 0 | Y30: =(X30*8)/1.8245 -> 0 | AD30: =(Z30*4)+(AA30*6)+(AB30*4)+(AC30*3) -> 0 | AE30: =(AD30*8)/1.8245 -> 0 | AF30: =G30+M30+AE30+S30+Y30 -> 0
A31: 45824 | C31: 1 | F31: =(B31*4)+(C31*6)+(D31*4)+(E31*3) -> 6 | G31: =(F31*8)/1.8245 -> 26.308578 | H31: 2 | I31: 1 | L31: =(H31*4)+(I31*6)+(J31*4)+(K31*3) -> 14 | M31: =(L31*8)/1.8245 -> 61.386681 | N31: 2 | O31: 1 | Q31: 1 | R31: =(N31*4)+(O31*6)+(P31*4)+(Q31*3) -> 17 | S31: =(R31*8)/1.8245 -> 74.54097 | T31: 1 | U31: 1 | W31: 1 | X31: =(T31*4)+(U31*6)+(V31*4)+(W31*3) -> 13 | Y31: =(X31*8)/1.8245 -> 57.001918 | AD31: =(Z31*4)+(AA31*6)+(AB31*4)+(AC31*3) -> 0 | AE31: =(AD31*8)/1.8245 -> 0 | AF31: =G31+M31+AE31+S31+Y31 -> 219.23815
A32: 45825 | B32: 1 | F32: =(B32*4)+(C32*6)+(D32*4)+(E32*3) -> 4 | G32: =(F32*8)/1.8245 -> 17.539052 | H32: 2 | I32: 1 | K32: 1 | L32: =(H32*4)+(I32*6)+(J32*4)+(K32*3) -> 17 | M32: =(L32*8)/1.8245 -> 74.54097 | N32: 2 | O32: 2 | Q32: 1 | R32: =(N32*4)+(O32*6)+(P32*4)+(Q32*3) -> 23 | S32: =(R32*8)/1.8245 -> 100.84955 | T32: 1 | U32: 2 | W32: 1 | X32: =(T32*4)+(U32*6)+(V32*4)+(W32*3) -> 19 | Y32: =(X32*8)/1.8245 -> 83.310496 | Z32: 2 | AA32: 1 | AC32: 1 | AD32: =(Z32*4)+(AA32*6)+(AB32*4)+(AC32*3) -> 17 | AE32: =(AD32*8)/1.8245 -> 74.54097 | AF32: =G32+M32+AE32+S32+Y32 -> 350.78104
A33: 45826 | F33: =(B33*4)+(C33*6)+(D33*4)+(E33*3) -> 0 | G33: =(F33*8)/1.8245 -> 0 | L33: =(H33*4)+(I33*6)+(J33*4)+(K33*3) -> 0 | M33: =(L33*8)/1.8245 -> 0 | N33: 2 | O33: 1 | Q33: 1 | R33: =(N33*4)+(O33*6)+(P33*4)+(Q33*3) -> 17 | S33: =(R33*8)/1.8245 -> 74.54097 | X33: =(T33*4)+(U33*6)+(V33*4)+(W33*3) -> 0 | Y33: =(X33*8)/1.8245 -> 0 | Z33: 3 | AC33: 1 | AD33: =(Z33*4)+(AA33*6)+(AB33*4)+(AC33*3) -> 15 | AE33: =(AD33*8)/1.8245 -> 65.771444 | AF33: =G33+M33+AE33+S33+Y33 -> 140.31241
A34: 45827 | B34: 1 | F34: =(B34*4)+(C34*6)+(D34*4)+(E34*3) -> 4 | G34: =(F34*8)/1.8245 -> 17.539052 | L34: =(H34*4)+(I34*6)+(J34*4)+(K34*3) -> 0 | M34: =(L34*8)/1.8245 -> 0 | R34: =(N34*4)+(O34*6)+(P34*4)+(Q34*3) -> 0 | S34: =(R34*8)/1.8245 -> 0 | X34: =(T34*4)+(U34*6)+(V34*4)+(W34*3) -> 0 | Y34: =(X34*8)/1.8245 -> 0 | AD34: =(Z34*4)+(AA34*6)+(AB34*4)+(AC34*3) -> 0 | AE34: =(AD34*8)/1.8245 -> 0 | AF34: =G34+M34+AE34+S34+Y34 -> 17.539052
A35: 45828 | F35: =(B35*4)+(C35*6)+(D35*4)+(E35*3) -> 0 | G35: =(F35*8)/1.8245 -> 0 | H35: 2 | K35: 1 | L35: =(H35*4)+(I35*6)+(J35*4)+(K35*3) -> 11 | M35: =(L35*8)/1.8245 -> 48.232392 | N35: 2 | R35: =(N35*4)+(O35*6)+(P35*4)+(Q35*3) -> 8 | S35: =(R35*8)/1.8245 -> 35.078104 | T35: 1 | X35: =(T35*4)+(U35*6)+(V35*4)+(W35*3) -> 4 | Y35: =(X35*8)/1.8245 -> 17.539052 | Z35: 2 | AD35: =(Z35*4)+(AA35*6)+(AB35*4)+(AC35*3) -> 8 | AE35: =(AD35*8)/1.8245 -> 35.078104 | AF35: =G35+M35+AE35+S35+Y35 -> 135.92765
A36: 45829 | F36: =(B36*4)+(C36*6)+(D36*4)+(E36*3) -> 0 | G36: =(F36*8)/1.8245 -> 0 | H36: 2 | I36: 1 | K36: 1 | L36: =(H36*4)+(I36*6)+(J36*4)+(K36*3) -> 17 | M36: =(L36*8)/1.8245 -> 74.54097 | N36: 1 | O36: 1 | R36: =(N36*4)+(O36*6)+(P36*4)+(Q36*3) -> 10 | S36: =(R36*8)/1.8245 -> 43.847629 | U36: 1 | X36: =(T36*4)+(U36*6)+(V36*4)+(W36*3) -> 6 | Y36: =(X36*8)/1.8245 -> 26.308578 | Z36: 2 | AA36: 1 | AC36: 1 | AD36: =(Z36*4)+(AA36*6)+(AB36*4)+(AC36*3) -> 17 | AE36: =(AD36*8)/1.8245 -> 74.54097 | AF36: =G36+M36+AE36+S36+Y36 -> 219.23815
A37: 45830 | F37: =(B37*4)+(C37*6)+(D37*4)+(E37*3) -> 0 | G37: =(F37*8)/1.8245 -> 0 | L37: =(H37*4)+(I37*6)+(J37*4)+(K37*3) -> 0 | M37: =(L37*8)/1.8245 -> 0 | R37: =(N37*4)+(O37*6)+(P37*4)+(Q37*3) -> 0 | S37: =(R37*8)/1.8245 -> 0 | X37: =(T37*4)+(U37*6)+(V37*4)+(W37*3) -> 0 | Y37: =(X37*8)/1.8245 -> 0 | AD37: =(Z37*4)+(AA37*6)+(AB37*4)+(AC37*3) -> 0 | AE37: =(AD37*8)/1.8245 -> 0 | AF37: =G37+M37+AE37+S37+Y37 -> 0
A38: 45831 | B38: 2 | C38: 2 | E38: 1 | F38: =(B38*4)+(C38*6)+(D38*4)+(E38*3) -> 23 | G38: =(F38*8)/1.8245 -> 100.84955 | H38: 2 | I38: 1 | K38: 1 | L38: =(H38*4)+(I38*6)+(J38*4)+(K38*3) -> 17 | M38: =(L38*8)/1.8245 -> 74.54097 | N38: 1 | O38: 1 | Q38: 1 | R38: =(N38*4)+(O38*6)+(P38*4)+(Q38*3) -> 13 | S38: =(R38*8)/1.8245 -> 57.001918 | T38: 3 | U38: 1 | W38: 1 | X38: =(T38*4)+(U38*6)+(V38*4)+(W38*3) -> 21 | Y38: =(X38*8)/1.8245 -> 92.080022 | AA38: 1 | AC38: 1 | AD38: =(Z38*4)+(AA38*6)+(AB38*4)+(AC38*3) -> 9 | AE38: =(AD38*8)/1.8245 -> 39.462867 | AF38: =G38+M38+AE38+S38+Y38 -> 363.93532
A39: 45832 | F39: =(B39*4)+(C39*6)+(D39*4)+(E39*3) -> 0 | G39: =(F39*8)/1.8245 -> 0 | L39: =(H39*4)+(I39*6)+(J39*4)+(K39*3) -> 0 | M39: =(L39*8)/1.8245 -> 0 | N39: 2 | O39: 1 | Q39: 1 | R39: =(N39*4)+(O39*6)+(P39*4)+(Q39*3) -> 17 | S39: =(R39*8)/1.8245 -> 74.54097 | X39: =(T39*4)+(U39*6)+(V39*4)+(W39*3) -> 0 | Y39: =(X39*8)/1.8245 -> 0 | Z39: 2 | AA39: 2 | AC39: 1 | AD39: =(Z39*4)+(AA39*6)+(AB39*4)+(AC39*3) -> 23 | AE39: =(AD39*8)/1.8245 -> 100.84955 | AF39: =G39+M39+AE39+S39+Y39 -> 175.39052
A40: 45833 | F40: =(B40*4)+(C40*6)+(D40*4)+(E40*3) -> 0 | G40: =(F40*8)/1.8245 -> 0 | H40: 2 | I40: 1 | K40: 1 | L40: =(H40*4)+(I40*6)+(J40*4)+(K40*3) -> 17 | M40: =(L40*8)/1.8245 -> 74.54097 | N40: 2 | O40: 2 | R40: =(N40*4)+(O40*6)+(P40*4)+(Q40*3) -> 20 | S40: =(R40*8)/1.8245 -> 87.695259 | T40: 3 | U40: 1 | W40: 1 | X40: =(T40*4)+(U40*6)+(V40*4)+(W40*3) -> 21 | Y40: =(X40*8)/1.8245 -> 92.080022 | Z40: 2 | AA40: 1 | AC40: 1 | AD40: =(Z40*4)+(AA40*6)+(AB40*4)+(AC40*3) -> 17 | AE40: =(AD40*8)/1.8245 -> 74.54097 | AF40: =G40+M40+AE40+S40+Y40 -> 328.85722
...

Sheet JULY 2025
A1: DAILY CREW MONITORING
A2: JULY | B2: Count of Crew | F2: Effective Personnel Count | G2: Effective Monthly Capability | H2: Effective Weekly Capability | I2: Effective Daily Capabiity
A3: CONTRACTOR | B3: Basket | C3: Stake | D3: Trucco | E3: Crane | L3: ACTUAL CAPABILITY FOR JULY
A4: AVECO | B4: 3 | C4: 1 | D4: 1 | E4: 1 | F4: =(B4*4)+(C4*6)+(D4*4)+(E4*3) -> 25 | G4: =($F4*8*26)/1.8245 -> 2850.0959 | H4: =G4/4 -> 712.52398 | I4: =($F4*8)/1.8245 -> 109.61907 | L4: AVECO | M4: =SUM(G16:G46) -> 1289.1203
A5: CHALLENGER | B5: 2 | C5: 1 | D5: 1 | E5: 1 | F5: =(B5*4)+(C5*6)+(D5*4)+(E5*3) -> 21 | G5: =($F5*8*26)/1.8245 -> 2394.0806 | H5: =G5/4 -> 598.52014 | I5: =($F5*8)/1.8245 -> 92.080022 | L5: CCBC | M5: =SUM(M16:M46) -> 1565.3604
A6: ECOM | B6: 2 | C6: 1 | D6: 1 | E6: 1 | F6: =(B6*4)+(C6*6)+(D6*4)+(E6*3) -> 21 | G6: =($F6*8*26)/1.8245 -> 2394.0806 | H6: =G6/4 -> 598.52014 | I6: =($F6*8)/1.8245 -> 92.080022 | L6: ECOM | M6: =SUM(S16:S46) -> 855.02878
A7: POWERHOUSE | B7: 2 | C7: 1 | D7: 1 | E7: 1 | F7: =(B7*4)+(C7*6)+(D7*4)+(E7*3) -> 21 | G7: =($F7*8*26)/1.8245 -> 2394.0806 | H7: =G7/4 -> 598.52014 | I7: =($F7*8)/1.8245 -> 92.080022 | L7: POWERHOUSE | M7: =SUM(Y16:Y46) -> 1753.9052
A8: VJC | B8: 2 | C8: 1 | E8: 1 | F8: =(B8*4)+(C8*6)+(D8*4)+(E8*3) -> 17 | G8: =($F8*8*26)/1.8245 -> 1938.0652 | H8: =G8/4 -> 484.51631 | I8: =($F8*8)/1.8245 -> 74.54097 | L8: VJC | M8: =SUM(AE16:AE46) -> 1753.9052
A9: C2 | B9: 1 | F9: =(B9*4)+(C9*6)+(D9*4)+(E9*3) -> 4 | G9: =($F9*8*26)/1.8245 -> 456.01535 | H9: =G9/4 -> 114.00384 | I9: =($F9*8)/1.8245 -> 17.539052 | L9: C2
A10: MN | B10: 4 | F10: =(B10*4)+(C10*6)+(D10*4)+(E10*3) -> 16 | G10: =($F10*8*26)/1.8245 -> 1824.0614 | H10: =G10/4 -> 456.01535 | I10: =($F10*8)/1.8245 -> 70.156207 | L10: MN
A11: TOTAL | B11: =SUM(B4:B10) -> 16 | C11: =SUM(C4:C8) -> 5 | D11: =SUM(D4:D8) -> 4 | E11: =SUM(E4:E8) -> 5 | F11: =SUM(F4:F10) -> 125 | G11: =(F11*8*26)/1.8245 -> 14250.48 | H11: =SUM(H4:H10) -> 3562.6199 | I11: =SUM(I4:I8) -> 460.40011 | M11: =SUM(M4:M8) -> 7217.3198
G12: =SUM(G4:G8) -> 11970.403
B13: AVECO | H13: CCBC | N13: ECOM | T13: POWERHOUSE | Z13: VJC | AF13: TOTAL
B14: Count of Crew | F14: Effective Personnel Count | G14: Crew Capability | H14: Count of Crew | L14: Effective Personnel Count | M14: Crew Capability | N14: Count of Crew | R14: Effective Personnel Count | S14: Crew Capability | T14: Count of Crew | X14: Effective Personnel Count | Y14: Crew Capability | Z14: Count of Crew | AD14: Effective Personnel Count | AE14: Crew Capability
A15: DATE | B15: Basket | C15: Stake | D15: Trucco | E15: Crane | H15: Basket | I15: Stake | J15: Trucco | K15: Crane | N15: Basket | O15: Stake | P15: Trucco | Q15: Crane | T15: Basket | U15: Stake | V15: Trucco | W15: Crane | Z15: Basket | AA15: Stake | AB15: Trucco | AC15: Crane
A16: 45839 | B16: 1 | C16: 1 | E16: 1 | F16: =(B16*4)+(C16*6)+(D16*4)+(E16*3) -> 13 | G16: =(F16*8)/1.8245 -> 57.001918 | H16: 2 | I16: 1 | L16: =(H16*4)+(I16*6)+(J16*4)+(K16*3) -> 14 | M16: =(L16*8)/1.8245 -> 61.386681 | R16: =(N16*4)+(O16*6)+(P16*4)+(Q16*3) -> 0 | S16: =(R16*8)/1.8245 -> 0 | U16: 1 | X16: =(T16*4)+(U16*6)+(V16*4)+(W16*3) -> 6 | Y16: =(X16*8)/1.8245 -> 26.308578 | Z16: 1 | AA16: 1 | AD16: =(Z16*4)+(AA16*6)+(AB16*4)+(AC16*3) -> 10 | AE16: =(AD16*8)/1.8245 -> 43.847629 | AF16: =G16+M16+AE16+S16+Y16 -> 188.54481
A17: 45840 | B17: 1 | C17: 1 | F17: =(B17*4)+(C17*6)+(D17*4)+(E17*3) -> 10 | G17: =(F17*8)/1.8245 -> 43.847629 | H17: 2 | I17: 1 | L17: =(H17*4)+(I17*6)+(J17*4)+(K17*3) -> 14 | M17: =(L17*8)/1.8245 -> 61.386681 | N17: 2 | O17: 1 | Q17: 1 | R17: =(N17*4)+(O17*6)+(P17*4)+(Q17*3) -> 17 | S17: =(R17*8)/1.8245 -> 74.54097 | T17: 2 | U17: 2 | W17: 1 | X17: =(T17*4)+(U17*6)+(V17*4)+(W17*3) -> 23 | Y17: =(X17*8)/1.8245 -> 100.84955 | Z17: 4 | AA17: 1 | AD17: =(Z17*4)+(AA17*6)+(AB17*4)+(AC17*3) -> 22 | AE17: =(AD17*8)/1.8245 -> 96.464785 | AF17: =G17+M17+AE17+S17+Y17 -> 377.08961
A18: 45841 | C18: 1 | F18: =(B18*4)+(C18*6)+(D18*4)+(E18*3) -> 6 | G18: =(F18*8)/1.8245 -> 26.308578 | H18: 2 | I18: 1 | L18: =(H18*4)+(I18*6)+(J18*4)+(K18*3) -> 14 | M18: =(L18*8)/1.8245 -> 61.386681 | N18: 1 | O18: 1 | R18: =(N18*4)+(O18*6)+(P18*4)+(Q18*3) -> 10 | S18: =(R18*8)/1.8245 -> 43.847629 | T18: 2 | U18: 1 | W18: 1 | X18: =(T18*4)+(U18*6)+(V18*4)+(W18*3) -> 17 | Y18: =(X18*8)/1.8245 -> 74.54097 | Z18: 4 | AA18: 2 | AC18: 1 | AD18: =(Z18*4)+(AA18*6)+(AB18*4)+(AC18*3) -> 31 | AE18: =(AD18*8)/1.8245 -> 135.92765 | AF18: =G18+M18+AE18+S18+Y18 -> 342.01151
A19: 45842 | B19: 1 | C19: 2 | E19: 1 | F19: =(B19*4)+(C19*6)+(D19*4)+(E19*3) -> 19 | G19: =(F19*8)/1.8245 -> 83.310496 | H19: 2 | I19: 1 | K19: 1 | L19: =(H19*4)+(I19*6)+(J19*4)+(K19*3) -> 17 | M19: =(L19*8)/1.8245 -> 74.54097 | R19: =(N19*4)+(O19*6)+(P19*4)+(Q19*3) -> 0 | S19: =(R19*8)/1.8245 -> 0 | T19: 3 | U19: 2 | W19: 1 | X19: =(T19*4)+(U19*6)+(V19*4)+(W19*3) -> 27 | Y19: =(X19*8)/1.8245 -> 118.3886 | Z19: 3 | AA19: 2 | AC19: 1 | AD19: =(Z19*4)+(AA19*6)+(AB19*4)+(AC19*3) -> 27 | AE19: =(AD19*8)/1.8245 -> 118.3886 | AF19: =G19+M19+AE19+S19+Y19 -> 394.62867
A20: 45843 | B20: 1 | F20: =(B20*4)+(C20*6)+(D20*4)+(E20*3) -> 4 | G20: =(F20*8)/1.8245 -> 17.539052 | H20: 2 | I20: 1 | K20: 1 | L20: =(H20*4)+(I20*6)+(J20*4)+(K20*3) -> 17 | M20: =(L20*8)/1.8245 -> 74.54097 | N20: 1 | Q20: 1 | R20: =(N20*4)+(O20*6)+(P20*4)+(Q20*3) -> 7 | S20: =(R20*8)/1.8245 -> 30.693341 | X20: =(T20*4)+(U20*6)+(V20*4)+(W20*3) -> 0 | Y20: =(X20*8)/1.8245 -> 0 | Z20: 2 | AA20: 1 | AC20: 1 | AD20: =(Z20*4)+(AA20*6)+(AB20*4)+(AC20*3) -> 17 | AE20: =(AD20*8)/1.8245 -> 74.54097 | AF20: =G20+M20+AE20+S20+Y20 -> 197.31433
A21: 45844 | F21: =(B21*4)+(C21*6)+(D21*4)+(E21*3) -> 0 | G21: =(F21*8)/1.8245 -> 0 | L21: =(H21*4)+(I21*6)+(J21*4)+(K21*3) -> 0 | M21: =(L21*8)/1.8245 -> 0 | R21: =(N21*4)+(O21*6)+(P21*4)+(Q21*3) -> 0 | S21: =(R21*8)/1.8245 -> 0 | X21: =(T21*4)+(U21*6)+(V21*4)+(W21*3) -> 0 | Y21: =(X21*8)/1.8245 -> 0 | AD21: =(Z21*4)+(AA21*6)+(AB21*4)+(AC21*3) -> 0 | AE21: =(AD21*8)/1.8245 -> 0 | AF21: =G21+M21+AE21+S21+Y21 -> 0
A22: 45845 | B22: 1 | C22: 1 | F22: =(B22*4)+(C22*6)+(D22*4)+(E22*3) -> 10 | G22: =(F22*8)/1.8245 -> 43.847629 | H22: 2 | I22: 1 | L22: =(H22*4)+(I22*6)+(J22*4)+(K22*3) -> 14 | M22: =(L22*8)/1.8245 -> 61.386681 | R22: =(N22*4)+(O22*6)+(P22*4)+(Q22*3) -> 0 | S22: =(R22*8)/1.8245 -> 0 | T22: 2 | U22: 2 | W22: 1 | X22: =(T22*4)+(U22*6)+(V22*4)+(W22*3) -> 23 | Y22: =(X22*8)/1.8245 -> 100.84955 | Z22: 1 | AA22: 1 | AC22: 1 | AD22: =(Z22*4)+(AA22*6)+(AB22*4)+(AC22*3) -> 13 | AE22: =(AD22*8)/1.8245 -> 57.001918 | AF22: =G22+M22+AE22+S22+Y22 -> 263.08578
A23: 45846 | B23: 2 | C23: 2 | F23: =(B23*4)+(C23*6)+(D23*4)+(E23*3) -> 20 | G23: =(F23*8)/1.8245 -> 87.695259 | H23: 2 | I23: 1 | K23: 1 | L23: =(H23*4)+(I23*6)+(J23*4)+(K23*3) -> 17 | M23: =(L23*8)/1.8245 -> 74.54097 | N23: 1 | O23: 1 | Q23: 1 | R23: =(N23*4)+(O23*6)+(P23*4)+(Q23*3) -> 13 | S23: =(R23*8)/1.8245 -> 57.001918 | T23: 1 | X23: =(T23*4)+(U23*6)+(V23*4)+(W23*3) -> 4 | Y23: =(X23*8)/1.8245 -> 17.539052 | Z23: 3 | AA23: 2 | AC23: 1 | AD23: =(Z23*4)+(AA23*6)+(AB23*4)+(AC23*3) -> 27 | AE23: =(AD23*8)/1.8245 -> 118.3886 | AF23: =G23+M23+AE23+S23+Y23 -> 355.1658
A24: 45847 | F24: =(B24*4)+(C24*6)+(D24*4)+(E24*3) -> 0 | G24: =(F24*8)/1.8245 -> 0 | H24: 2 | I24: 1 | K24: 1 | L24: =(H24*4)+(I24*6)+(J24*4)+(K24*3) -> 17 | M24: =(L24*8)/1.8245 -> 74.54097 | N24: 2 | O24: 1 | R24: =(N24*4)+(O24*6)+(P24*4)+(Q24*3) -> 14 | S24: =(R24*8)/1.8245 -> 61.386681 | T24: 1 | U24: 2 | W24: 1 | X24: =(T24*4)+(U24*6)+(V24*4)+(W24*3) -> 19 | Y24: =(X24*8)/1.8245 -> 83.310496 | Z24: 3 | AD24: =(Z24*4)+(AA24*6)+(AB24*4)+(AC24*3) -> 12 | AE24: =(AD24*8)/1.8245 -> 52.617155 | AF24: =G24+M24+AE24+S24+Y24 -> 271.8553
A25: 45848 | B25: 1 | C25: 2 | E25: 1 | F25: =(B25*4)+(C25*6)+(D25*4)+(E25*3) -> 19 | G25: =(F25*8)/1.8245 -> 83.310496 | H25: 2 | I25: 1 | K25: 1 | L25: =(H25*4)+(I25*6)+(J25*4)+(K25*3) -> 17 | M25: =(L25*8)/1.8245 -> 74.54097 | N25: 2 | O25: 1 | R25: =(N25*4)+(O25*6)+(P25*4)+(Q25*3) -> 14 | S25: =(R25*8)/1.8245 -> 61.386681 | U25: 1 | X25: =(T25*4)+(U25*6)+(V25*4)+(W25*3) -> 6 | Y25: =(X25*8)/1.8245 -> 26.308578 | Z25: 2 | AA25: 1 | AC25: 1 | AD25: =(Z25*4)+(AA25*6)+(AB25*4)+(AC25*3) -> 17 | AE25: =(AD25*8)/1.8245 -> 74.54097 | AF25: =G25+M25+AE25+S25+Y25 -> 320.0877
A26: 45849 | B26: 1 | C26: 2 | E26: 1 | F26: =(B26*4)+(C26*6)+(D26*4)+(E26*3) -> 19 | G26: =(F26*8)/1.8245 -> 83.310496 | H26: 2 | I26: 1 | L26: =(H26*4)+(I26*6)+(J26*4)+(K26*3) -> 14 | M26: =(L26*8)/1.8245 -> 61.386681 | N26: 2 | O26: 1 | Q26: 1 | R26: =(N26*4)+(O26*6)+(P26*4)+(Q26*3) -> 17 | S26: =(R26*8)/1.8245 -> 74.54097 | T26: 1 | U26: 2 | W26: 1 | X26: =(T26*4)+(U26*6)+(V26*4)+(W26*3) -> 19 | Y26: =(X26*8)/1.8245 -> 83.310496 | Z26: 3 | AD26: =(Z26*4)+(AA26*6)+(AB26*4)+(AC26*3) -> 12 | AE26: =(AD26*8)/1.8245 -> 52.617155 | AF26: =G26+M26+AE26+S26+Y26 -> 355.1658
A27: 45850 | B27: 2 | C27: 1 | F27: =(B27*4)+(C27*6)+(D27*4)+(E27*3) -> 14 | G27: =(F27*8)/1.8245 -> 61.386681 | H27: 2 | I27: 1 | K27: 1 | L27: =(H27*4)+(I27*6)+(J27*4)+(K27*3) -> 17 | M27: =(L27*8)/1.8245 -> 74.54097 | N27: 1 | O27: 1 | Q27: 1 | R27: =(N27*4)+(O27*6)+(P27*4)+(Q27*3) -> 13 | S27: =(R27*8)/1.8245 -> 57.001918 | T27: 2 | U27: 1 | W27: 1 | X27: =(T27*4)+(U27*6)+(V27*4)+(W27*3) -> 17 | Y27: =(X27*8)/1.8245 -> 74.54097 | Z27: 1 | AD27: =(Z27*4)+(AA27*6)+(AB27*4)+(AC27*3) -> 4 | AE27: =(AD27*8)/1.8245 -> 17.539052 | AF27: =G27+M27+AE27+S27+Y27 -> 285.00959
A28: 45851 | F28: =(B28*4)+(C28*6)+(D28*4)+(E28*3) -> 0 | G28: =(F28*8)/1.8245 -> 0 | L28: =(H28*4)+(I28*6)+(J28*4)+(K28*3) -> 0 | M28: =(L28*8)/1.8245 -> 0 | R28: =(N28*4)+(O28*6)+(P28*4)+(Q28*3) -> 0 | S28: =(R28*8)/1.8245 -> 0 | X28: =(T28*4)+(U28*6)+(V28*4)+(W28*3) -> 0 | Y28: =(X28*8)/1.8245 -> 0 | Z28: 3 | AA28: 2 | AC28: 1 | AD28: =(Z28*4)+(AA28*6)+(AB28*4)+(AC28*3) -> 27 | AE28: =(AD28*8)/1.8245 -> 118.3886 | AF28: =G28+M28+AE28+S28+Y28 -> 118.3886
A29: 45852 | B29: 2 | C29: 1 | E29: 1 | F29: =(B29*4)+(C29*6)+(D29*4)+(E29*3) -> 17 | G29: =(F29*8)/1.8245 -> 74.54097 | H29: 2 | I29: 1 | K29: 1 | L29: =(H29*4)+(I29*6)+(J29*4)+(K29*3) -> 17 | M29: =(L29*8)/1.8245 -> 74.54097 | N29: 1 | O29: 1 | Q29: 1 | R29: =(N29*4)+(O29*6)+(P29*4)+(Q29*3) -> 13 | S29: =(R29*8)/1.8245 -> 57.001918 | T29: 1 | U29: 1 | X29: =(T29*4)+(U29*6)+(V29*4)+(W29*3) -> 10 | Y29: =(X29*8)/1.8245 -> 43.847629 | AD29: =(Z29*4)+(AA29*6)+(AB29*4)+(AC29*3) -> 0 | AE29: =(AD29*8)/1.8245 -> 0 | AF29: =G29+M29+AE29+S29+Y29 -> 249.93149
A30: 45853 | B30: 2 | C30: 1 | E30: 1 | F30: =(B30*4)+(C30*6)+(D30*4)+(E30*3) -> 17 | G30: =(F30*8)/1.8245 -> 74.54097 | H30: 2 | I30: 1 | K30: 1 | L30: =(H30*4)+(I30*6)+(J30*4)+(K30*3) -> 17 | M30: =(L30*8)/1.8245 -> 74.54097 | R30: =(N30*4)+(O30*6)+(P30*4)+(Q30*3) -> 0 | S30: =(R30*8)/1.8245 -> 0 | T30: 1 | U30: 1 | X30: =(T30*4)+(U30*6)+(V30*4)+(W30*3) -> 10 | Y30: =(X30*8)/1.8245 -> 43.847629 | Z30: 2 | AA30: 1 | AC30: 1 | AD30: =(Z30*4)+(AA30*6)+(AB30*4)+(AC30*3) -> 17 | AE30: =(AD30*8)/1.8245 -> 74.54097 | AF30: =G30+M30+AE30+S30+Y30 -> 267.47054
A31: 45854 | B31: 1 | C31: 1 | F31: =(B31*4)+(C31*6)+(D31*4)+(E31*3) -> 10 | G31: =(F31*8)/1.8245 -> 43.847629 | H31: 3 | I31: 1 | L31: =(H31*4)+(I31*6)+(J31*4)+(K31*3) -> 18 | M31: =(L31*8)/1.8245 -> 78.925733 | R31: =(N31*4)+(O31*6)+(P31*4)+(Q31*3) -> 0 | S31: =(R31*8)/1.8245 -> 0 | T31: 2 | U31: 2 | W31: 1 | X31: =(T31*4)+(U31*6)+(V31*4)+(W31*3) -> 23 | Y31: =(X31*8)/1.8245 -> 100.84955 | Z31: 3 | AC31: 1 | AD31: =(Z31*4)+(AA31*6)+(AB31*4)+(AC31*3) -> 15 | AE31: =(AD31*8)/1.8245 -> 65.771444 | AF31: =G31+M31+AE31+S31+Y31 -> 289.39435
A32: 45855 | B32: 1 | C32: 1 | F32: =(B32*4)+(C32*6)+(D32*4)+(E32*3) -> 10 | G32: =(F32*8)/1.8245 -> 43.847629 | H32: 2 | I32: 1 | L32: =(H32*4)+(I32*6)+(J32*4)+(K32*3) -> 14 | M32: =(L32*8)/1.8245 -> 61.386681 | N32: 2 | O32: 1 | R32: =(N32*4)+(O32*6)+(P32*4)+(Q32*3) -> 14 | S32: =(R32*8)/1.8245 -> 61.386681 | T32: 2 | U32: 1 | W32: 1 | X32: =(T32*4)+(U32*6)+(V32*4)+(W32*3) -> 17 | Y32: =(X32*8)/1.8245 -> 74.54097 | Z32: 2 | AD32: =(Z32*4)+(AA32*6)+(AB32*4)+(AC32*3) -> 8 | AE32: =(AD32*8)/1.8245 -> 35.078104 | AF32: =G32+M32+AE32+S32+Y32 -> 276.24007
A33: 45856 | F33: =(B33*4)+(C33*6)+(D33*4)+(E33*3) -> 0 | G33: =(F33*8)/1.8245 -> 0 | H33: 2 | I33: 1 | K33: 1 | L33: =(H33*4)+(I33*6)+(J33*4)+(K33*3) -> 17 | M33: =(L33*8)/1.8245 -> 74.54097 | R33: =(N33*4)+(O33*6)+(P33*4)+(Q33*3) -> 0 | S33: =(R33*8)/1.8245 -> 0 | T33: 3 | W33: 1 | X33: =(T33*4)+(U33*6)+(V33*4)+(W33*3) -> 15 | Y33: =(X33*8)/1.8245 -> 65.771444 | Z33: 3 | AD33: =(Z33*4)+(AA33*6)+(AB33*4)+(AC33*3) -> 12 | AE33: =(AD33*8)/1.8245 -> 52.617155 | AF33: =G33+M33+AE33+S33+Y33 -> 192.92957
A34: 45857 | B34: 2 | C34: 3 | E34: 1 | F34: =(B34*4)+(C34*6)+(D34*4)+(E34*3) -> 29 | G34: =(F34*8)/1.8245 -> 127.15813 | H34: 2 | I34: 1 | K34: 1 | L34: =(H34*4)+(I34*6)+(J34*4)+(K34*3) -> 17 | M34: =(L34*8)/1.8245 -> 74.54097 | R34: =(N34*4)+(O34*6)+(P34*4)+(Q34*3) -> 0 | S34: =(R34*8)/1.8245 -> 0 | T34: 2 | U34: 2 | W34: 1 | X34: =(T34*4)+(U34*6)+(V34*4)+(W34*3) -> 23 | Y34: =(X34*8)/1.8245 -> 100.84955 | AD34: =(Z34*4)+(AA34*6)+(AB34*4)+(AC34*3) -> 0 | AE34: =(AD34*8)/1.8245 -> 0 | AF34: =G34+M34+AE34+S34+Y34 -> 302.54864
A35: 45858 | F35: =(B35*4)+(C35*6)+(D35*4)+(E35*3) -> 0 | G35: =(F35*8)/1.8245 -> 0 | L35: =(H35*4)+(I35*6)+(J35*4)+(K35*3) -> 0 | M35: =(L35*8)/1.8245 -> 0 | R35: =(N35*4)+(O35*6)+(P35*4)+(Q35*3) -> 0 | S35: =(R35*8)/1.8245 -> 0 | X35: =(T35*4)+(U35*6)+(V35*4)+(W35*3) -> 0 | Y35: =(X35*8)/1.8245 -> 0 | AD35: =(Z35*4)+(AA35*6)+(AB35*4)+(AC35*3) -> 0 | AE35: =(AD35*8)/1.8245 -> 0 | AF35: =G35+M35+AE35+S35+Y35 -> 0
A36: 45859 | F36: =(B36*4)+(C36*6)+(D36*4)+(E36*3) -> 0 | G36: =(F36*8)/1.8245 -> 0 | L36: =(H36*4)+(I36*6)+(J36*4)+(K36*3) -> 0 | M36: =(L36*8)/1.8245 -> 0 | O36: 1 | R36: =(N36*4)+(O36*6)+(P36*4)+(Q36*3) -> 6 | S36: =(R36*8)/1.8245 -> 26.308578 | T36: 2 | U36: 3 | W36: 1 | X36: =(T36*4)+(U36*6)+(V36*4)+(W36*3) -> 29 | Y36: =(X36*8)/1.8245 -> 127.15813 | Z36: 3 | AD36: =(Z36*4)+(AA36*6)+(AB36*4)+(AC36*3) -> 12 | AE36: =(AD36*8)/1.8245 -> 52.617155 | AF36: =G36+M36+AE36+S36+Y36 -> 206.08386
A37: 45860 | F37: =(B37*4)+(C37*6)+(D37*4)+(E37*3) -> 0 | G37: =(F37*8)/1.8245 -> 0 | L37: =(H37*4)+(I37*6)+(J37*4)+(K37*3) -> 0 | M37: =(L37*8)/1.8245 -> 0 | R37: =(N37*4)+(O37*6)+(P37*4)+(Q37*3) -> 0 | S37: =(R37*8)/1.8245 -> 0 | T37: 1 | X37: =(T37*4)+(U37*6)+(V37*4)+(W37*3) -> 4 | Y37: =(X37*8)/1.8245 -> 17.539052 | Z37: 1 | AD37: =(Z37*4)+(AA37*6)+(AB37*4)+(AC37*3) -> 4 | AE37: =(AD37*8)/1.8245 -> 17.539052 | AF37: =G37+M37+AE37+S37+Y37 -> 35.078104
A38: 45861 | C38: 1 | F38: =(B38*4)+(C38*6)+(D38*4)+(E38*3) -> 6 | G38: =(F38*8)/1.8245 -> 26.308578 | H38: 2 | I38: 1 | L38: =(H38*4)+(I38*6)+(J38*4)+(K38*3) -> 14 | M38: =(L38*8)/1.8245 -> 61.386681 | R38: =(N38*4)+(O38*6)+(P38*4)+(Q38*3) -> 0 | S38: =(R38*8)/1.8245 -> 0 | T38: 2 | U38: 1 | W38: 1 | X38: =(T38*4)+(U38*6)+(V38*4)+(W38*3) -> 17 | Y38: =(X38*8)/1.8245 -> 74.54097 | Z38: 2 | AA38: 1 | AC38: 1 | AD38: =(Z38*4)+(AA38*6)+(AB38*4)+(AC38*3) -> 17 | AE38: =(AD38*8)/1.8245 -> 74.54097 | AF38: =G38+M38+AE38+S38+Y38 -> 236.7772
A39: 45862 | B39: 1 | C39: 2 | E39: 1 | F39: =(B39*4)+(C39*6)+(D39*4)+(E39*3) -> 19 | G39: =(F39*8)/1.8245 -> 83.310496 | H39: 2 | I39: 1 | L39: =(H39*4)+(I39*6)+(J39*4)+(K39*3) -> 14 | M39: =(L39*8)/1.8245 -> 61.386681 | O39: 1 | R39: =(N39*4)+(O39*6)+(P39*4)+(Q39*3) -> 6 | S39: =(R39*8)/1.8245 -> 26.308578 | T39: 3 | U39: 1 | X39: =(T39*4)+(U39*6)+(V39*4)+(W39*3) -> 18 | Y39: =(X39*8)/1.8245 -> 78.925733 | Z39: 2 | AA39: 1 | AC39: 1 | AD39: =(Z39*4)+(AA39*6)+(AB39*4)+(AC39*3) -> 17 | AE39: =(AD39*8)/1.8245 -> 74.54097 | AF39: =G39+M39+AE39+S39+Y39 -> 324.47246
A40: 45863 | B40: 2 | C40: 1 | F40: =(B40*4)+(C40*6)+(D40*4)+(E40*3) -> 14 | G40: =(F40*8)/1.8245 -> 61.386681 | H40: 5 | I40: 1 | L40: =(H40*4)+(I40*6)+(J40*4)+(K40*3) -> 26 | M40: =(L40*8)/1.8245 -> 114.00384 | N40: 1 | O40: 1 | R40: =(N40*4)+(O40*6)+(P40*4)+(Q40*3) -> 10 | S40: =(R40*8)/1.8245 -> 43.847629 | T40: 2 | U40: 2 | W40: 1 | X40: =(T40*4)+(U40*6)+(V40*4)+(W40*3) -> 23 | Y40: =(X40*8)/1.8245 -> 100.84955 | Z40: 3 | AA40: 1 | AC40: 1 | AD40: =(Z40*4)+(AA40*6)+(AB40*4)+(AC40*3) -> 21 | AE40: =(AD40*8)/1.8245 -> 92.080022 | AF40: =G40+M40+AE40+S40+Y40 -> 412.16772
...

Sheet AUG 2025
A1: DAILY CREW MONITORING
A2: AUGUST | B2: Count of Crew | F2: Effective Personnel Count | G2: Effective Monthly Capability | H2: Effective Weekly Capability | I2: Effective Daily Capabiity
A3: CONTRACTOR | B3: Basket | C3: Stake | D3: Trucco | E3: Crane | L3: ACTUAL CAPABILITY FOR AUGUST
A4: AVECO | B4: 3 | C4: 1 | D4: 1 | E4: 1 | F4: =(B4*4)+(C4*6)+(D4*4)+(E4*3) -> 25 | G4: =($F4*8*26)/1.8245 -> 2850.0959 | H4: =G4/4 -> 712.52398 | I4: =($F4*8)/1.8245 -> 109.61907 | L4: AVECO | M4: =SUM(G16:G38) -> 1293.5051
A5: CHALLENGER | B5: 2 | C5: 1 | D5: 1 | E5: 1 | F5: =(B5*4)+(C5*6)+(D5*4)+(E5*3) -> 21 | G5: =($F5*8*26)/1.8245 -> 2394.0806 | H5: =G5/4 -> 598.52014 | I5: =($F5*8)/1.8245 -> 92.080022 | L5: CCBC | M5: =SUM(M16:M38) -> 513.01727
A6: ECOM | B6: 2 | C6: 1 | D6: 1 | E6: 1 | F6: =(B6*4)+(C6*6)+(D6*4)+(E6*3) -> 21 | G6: =($F6*8*26)/1.8245 -> 2394.0806 | H6: =G6/4 -> 598.52014 | I6: =($F6*8)/1.8245 -> 92.080022 | L6: ECOM | M6: =SUM(S16:S38) -> 806.79638
A7: POWERHOUSE | B7: 2 | C7: 1 | D7: 1 | E7: 1 | F7: =(B7*4)+(C7*6)+(D7*4)+(E7*3) -> 21 | G7: =($F7*8*26)/1.8245 -> 2394.0806 | H7: =G7/4 -> 598.52014 | I7: =($F7*8)/1.8245 -> 92.080022 | L7: POWERHOUSE | M7: =SUM(Y16:Y38) -> 1258.427
A8: VJC | B8: 2 | C8: 1 | E8: 1 | F8: =(B8*4)+(C8*6)+(D8*4)+(E8*3) -> 17 | G8: =($F8*8*26)/1.8245 -> 1938.0652 | H8: =G8/4 -> 484.51631 | I8: =($F8*8)/1.8245 -> 74.54097 | L8: VJC | M8: =SUM(AE16:AE38) -> 982.1869
A9: C2 | B9: 1 | F9: =(B9*4)+(C9*6)+(D9*4)+(E9*3) -> 4 | G9: =($F9*8*26)/1.8245 -> 456.01535 | H9: =G9/4 -> 114.00384 | I9: =($F9*8)/1.8245 -> 17.539052 | L9: C2
A10: MN | B10: 4 | F10: =(B10*4)+(C10*6)+(D10*4)+(E10*3) -> 16 | G10: =($F10*8*26)/1.8245 -> 1824.0614 | H10: =G10/4 -> 456.01535 | I10: =($F10*8)/1.8245 -> 70.156207 | L10: MN
A11: TOTAL | B11: =SUM(B4:B10) -> 16 | C11: =SUM(C4:C8) -> 5 | D11: =SUM(D4:D8) -> 4 | E11: =SUM(E4:E8) -> 5 | F11: =SUM(F4:F10) -> 125 | G11: =(F11*8*26)/1.8245 -> 14250.48 | H11: =SUM(H4:H10) -> 3562.6199 | I11: =SUM(I4:I8) -> 460.40011 | M11: =SUM(M4:M8) -> 4853.9326
G12: =SUM(G4:G8) -> 11970.403
B13: AVECO | H13: CCBC | N13: ECOM | T13: POWERHOUSE | Z13: VJC | AF13: TOTAL
B14: Count of Crew | F14: Effective Personnel Count | G14: Crew Capability | H14: Count of Crew | L14: Effective Personnel Count | M14: Crew Capability | N14: Count of Crew | R14: Effective Personnel Count | S14: Crew Capability | T14: Count of Crew | X14: Effective Personnel Count | Y14: Crew Capability | Z14: Count of Crew | AD14: Effective Personnel Count | AE14: Crew Capability
A15: DATE | B15: Basket | C15: Stake | D15: Trucco | E15: Crane | H15: Basket | I15: Stake | J15: Trucco | K15: Crane | N15: Basket | O15: Stake | P15: Trucco | Q15: Crane | T15: Basket | U15: Stake | V15: Trucco | W15: Crane | Z15: Basket | AA15: Stake | AB15: Trucco | AC15: Crane
A16: 45870 | F16: =(B16*4)+(C16*6)+(D16*4)+(E16*3) -> 0 | G16: =(F16*8)/1.8245 -> 0 | L16: =(H16*4)+(I16*6)+(J16*4)+(K16*3) -> 0 | M16: =(L16*8)/1.8245 -> 0 | N16: 2 | O16: 1 | Q16: 1 | R16: =(N16*4)+(O16*6)+(P16*4)+(Q16*3) -> 17 | S16: =(R16*8)/1.8245 -> 74.54097 | T16: 2 | U16: 1 | W16: 1 | X16: =(T16*4)+(U16*6)+(V16*4)+(W16*3) -> 17 | Y16: =(X16*8)/1.8245 -> 74.54097 | Z16: 2 | AA16: 1 | AD16: =(Z16*4)+(AA16*6)+(AB16*4)+(AC16*3) -> 14 | AE16: =(AD16*8)/1.8245 -> 61.386681 | AF16: =G16+M16+AE16+S16+Y16 -> 210.46862
A17: 45871 | B17: 2 | C17: 1 | E17: 1 | F17: =(B17*4)+(C17*6)+(D17*4)+(E17*3) -> 17 | G17: =(F17*8)/1.8245 -> 74.54097 | L17: =(H17*4)+(I17*6)+(J17*4)+(K17*3) -> 0 | M17: =(L17*8)/1.8245 -> 0 | R17: =(N17*4)+(O17*6)+(P17*4)+(Q17*3) -> 0 | S17: =(R17*8)/1.8245 -> 0 | T17: 2 | U17: 2 | W17: 1 | X17: =(T17*4)+(U17*6)+(V17*4)+(W17*3) -> 23 | Y17: =(X17*8)/1.8245 -> 100.84955 | Z17: 3 | AD17: =(Z17*4)+(AA17*6)+(AB17*4)+(AC17*3) -> 12 | AE17: =(AD17*8)/1.8245 -> 52.617155 | AF17: =G17+M17+AE17+S17+Y17 -> 228.00767
A18: 45872 | F18: =(B18*4)+(C18*6)+(D18*4)+(E18*3) -> 0 | G18: =(F18*8)/1.8245 -> 0 | L18: =(H18*4)+(I18*6)+(J18*4)+(K18*3) -> 0 | M18: =(L18*8)/1.8245 -> 0 | R18: =(N18*4)+(O18*6)+(P18*4)+(Q18*3) -> 0 | S18: =(R18*8)/1.8245 -> 0 | X18: =(T18*4)+(U18*6)+(V18*4)+(W18*3) -> 0 | Y18: =(X18*8)/1.8245 -> 0 | Z18: 2 | AA18: 1 | AC18: 1 | AD18: =(Z18*4)+(AA18*6)+(AB18*4)+(AC18*3) -> 17 | AE18: =(AD18*8)/1.8245 -> 74.54097 | AF18: =G18+M18+AE18+S18+Y18 -> 74.54097
A19: 45873 | F19: =(B19*4)+(C19*6)+(D19*4)+(E19*3) -> 0 | G19: =(F19*8)/1.8245 -> 0 | L19: =(H19*4)+(I19*6)+(J19*4)+(K19*3) -> 0 | M19: =(L19*8)/1.8245 -> 0 | N19: 1 | O19: 1 | Q19: 1 | R19: =(N19*4)+(O19*6)+(P19*4)+(Q19*3) -> 13 | S19: =(R19*8)/1.8245 -> 57.001918 | T19: 1 | U19: 3 | W19: 2 | X19: =(T19*4)+(U19*6)+(V19*4)+(W19*3) -> 28 | Y19: =(X19*8)/1.8245 -> 122.77336 | AA19: 1 | AD19: =(Z19*4)+(AA19*6)+(AB19*4)+(AC19*3) -> 6 | AE19: =(AD19*8)/1.8245 -> 26.308578 | AF19: =G19+M19+AE19+S19+Y19 -> 206.08386
A20: 45874 | F20: =(B20*4)+(C20*6)+(D20*4)+(E20*3) -> 0 | G20: =(F20*8)/1.8245 -> 0 | H20: 2 | L20: =(H20*4)+(I20*6)+(J20*4)+(K20*3) -> 8 | M20: =(L20*8)/1.8245 -> 35.078104 | N20: 1 | R20: =(N20*4)+(O20*6)+(P20*4)+(Q20*3) -> 4 | S20: =(R20*8)/1.8245 -> 17.539052 | T20: 2 | U20: 1 | W20: 1 | X20: =(T20*4)+(U20*6)+(V20*4)+(W20*3) -> 17 | Y20: =(X20*8)/1.8245 -> 74.54097 | Z20: 2 | AA20: 1 | AC20: 1 | AD20: =(Z20*4)+(AA20*6)+(AB20*4)+(AC20*3) -> 17 | AE20: =(AD20*8)/1.8245 -> 74.54097 | AF20: =G20+M20+AE20+S20+Y20 -> 201.6991
A21: 45875 | F21: =(B21*4)+(C21*6)+(D21*4)+(E21*3) -> 0 | G21: =(F21*8)/1.8245 -> 0 | H21: 2 | L21: =(H21*4)+(I21*6)+(J21*4)+(K21*3) -> 8 | M21: =(L21*8)/1.8245 -> 35.078104 | N21: 2 | R21: =(N21*4)+(O21*6)+(P21*4)+(Q21*3) -> 8 | S21: =(R21*8)/1.8245 -> 35.078104 | T21: 2 | U21: 1 | W21: 1 | X21: =(T21*4)+(U21*6)+(V21*4)+(W21*3) -> 17 | Y21: =(X21*8)/1.8245 -> 74.54097 | Z21: 2 | AA21: 2 | AD21: =(Z21*4)+(AA21*6)+(AB21*4)+(AC21*3) -> 20 | AE21: =(AD21*8)/1.8245 -> 87.695259 | AF21: =G21+M21+AE21+S21+Y21 -> 232.39244
A22: 45876 | B22: 2 | C22: 1 | F22: =(B22*4)+(C22*6)+(D22*4)+(E22*3) -> 14 | G22: =(F22*8)/1.8245 -> 61.386681 | H22: 2 | L22: =(H22*4)+(I22*6)+(J22*4)+(K22*3) -> 8 | M22: =(L22*8)/1.8245 -> 35.078104 | N22: 2 | O22: 1 | Q22: 1 | R22: =(N22*4)+(O22*6)+(P22*4)+(Q22*3) -> 17 | S22: =(R22*8)/1.8245 -> 74.54097 | T22: 2 | U22: 1 | W22: 1 | X22: =(T22*4)+(U22*6)+(V22*4)+(W22*3) -> 17 | Y22: =(X22*8)/1.8245 -> 74.54097 | AD22: =(Z22*4)+(AA22*6)+(AB22*4)+(AC22*3) -> 0 | AE22: =(AD22*8)/1.8245 -> 0 | AF22: =G22+M22+AE22+S22+Y22 -> 245.54673
A23: 45877 | F23: =(B23*4)+(C23*6)+(D23*4)+(E23*3) -> 0 | G23: =(F23*8)/1.8245 -> 0 | H23: 2 | L23: =(H23*4)+(I23*6)+(J23*4)+(K23*3) -> 8 | M23: =(L23*8)/1.8245 -> 35.078104 | O23: 3 | R23: =(N23*4)+(O23*6)+(P23*4)+(Q23*3) -> 18 | S23: =(R23*8)/1.8245 -> 78.925733 | T23: 1 | U23: 1 | X23: =(T23*4)+(U23*6)+(V23*4)+(W23*3) -> 10 | Y23: =(X23*8)/1.8245 -> 43.847629 | Z23: 2 | AA23: 1 | AD23: =(Z23*4)+(AA23*6)+(AB23*4)+(AC23*3) -> 14 | AE23: =(AD23*8)/1.8245 -> 61.386681 | AF23: =G23+M23+AE23+S23+Y23 -> 219.23815
A24: 45878 | B24: 4 | C24: 3 | E24: 1 | F24: =(B24*4)+(C24*6)+(D24*4)+(E24*3) -> 37 | G24: =(F24*8)/1.8245 -> 162.23623 | L24: =(H24*4)+(I24*6)+(J24*4)+(K24*3) -> 0 | M24: =(L24*8)/1.8245 -> 0 | N24: 2 | O24: 1 | Q24: 1 | R24: =(N24*4)+(O24*6)+(P24*4)+(Q24*3) -> 17 | S24: =(R24*8)/1.8245 -> 74.54097 | T24: 1 | U24: 1 | W24: 1 | X24: =(T24*4)+(U24*6)+(V24*4)+(W24*3) -> 13 | Y24: =(X24*8)/1.8245 -> 57.001918 | Z24: 2 | AA24: 2 | AD24: =(Z24*4)+(AA24*6)+(AB24*4)+(AC24*3) -> 20 | AE24: =(AD24*8)/1.8245 -> 87.695259 | AF24: =G24+M24+AE24+S24+Y24 -> 381.47438
A25: 45879 | F25: =(B25*4)+(C25*6)+(D25*4)+(E25*3) -> 0 | G25: =(F25*8)/1.8245 -> 0 | L25: =(H25*4)+(I25*6)+(J25*4)+(K25*3) -> 0 | M25: =(L25*8)/1.8245 -> 0 | R25: =(N25*4)+(O25*6)+(P25*4)+(Q25*3) -> 0 | S25: =(R25*8)/1.8245 -> 0 | X25: =(T25*4)+(U25*6)+(V25*4)+(W25*3) -> 0 | Y25: =(X25*8)/1.8245 -> 0 | AD25: =(Z25*4)+(AA25*6)+(AB25*4)+(AC25*3) -> 0 | AE25: =(AD25*8)/1.8245 -> 0 | AF25: =G25+M25+AE25+S25+Y25 -> 0
A26: 45880 | B26: 1 | F26: =(B26*4)+(C26*6)+(D26*4)+(E26*3) -> 4 | G26: =(F26*8)/1.8245 -> 17.539052 | L26: =(H26*4)+(I26*6)+(J26*4)+(K26*3) -> 0 | M26: =(L26*8)/1.8245 -> 0 | N26: 1 | Q26: 1 | R26: =(N26*4)+(O26*6)+(P26*4)+(Q26*3) -> 7 | S26: =(R26*8)/1.8245 -> 30.693341 | T26: 3 | U26: 1 | W26: 1 | X26: =(T26*4)+(U26*6)+(V26*4)+(W26*3) -> 21 | Y26: =(X26*8)/1.8245 -> 92.080022 | AA26: 1 | AD26: =(Z26*4)+(AA26*6)+(AB26*4)+(AC26*3) -> 6 | AE26: =(AD26*8)/1.8245 -> 26.308578 | AF26: =G26+M26+AE26+S26+Y26 -> 166.62099
A27: 45881 | B27: 2 | C27: 2 | F27: =(B27*4)+(C27*6)+(D27*4)+(E27*3) -> 20 | G27: =(F27*8)/1.8245 -> 87.695259 | H27: 2 | J27: 1 | L27: =(H27*4)+(I27*6)+(J27*4)+(K27*3) -> 12 | M27: =(L27*8)/1.8245 -> 52.617155 | N27: 1 | O27: 1 | Q27: 1 | R27: =(N27*4)+(O27*6)+(P27*4)+(Q27*3) -> 13 | S27: =(R27*8)/1.8245 -> 57.001918 | T27: 1 | U27: 1 | X27: =(T27*4)+(U27*6)+(V27*4)+(W27*3) -> 10 | Y27: =(X27*8)/1.8245 -> 43.847629 | Z27: 2 | AA27: 1 | AD27: =(Z27*4)+(AA27*6)+(AB27*4)+(AC27*3) -> 14 | AE27: =(AD27*8)/1.8245 -> 61.386681 | AF27: =G27+M27+AE27+S27+Y27 -> 302.54864
A28: 45882 | C28: 1 | F28: =(B28*4)+(C28*6)+(D28*4)+(E28*3) -> 6 | G28: =(F28*8)/1.8245 -> 26.308578 | H28: 2 | J28: 1 | L28: =(H28*4)+(I28*6)+(J28*4)+(K28*3) -> 12 | M28: =(L28*8)/1.8245 -> 52.617155 | N28: 1 | O28: 1 | Q28: 1 | R28: =(N28*4)+(O28*6)+(P28*4)+(Q28*3) -> 13 | S28: =(R28*8)/1.8245 -> 57.001918 | T28: 2 | U28: 2 | W28: 1 | X28: =(T28*4)+(U28*6)+(V28*4)+(W28*3) -> 23 | Y28: =(X28*8)/1.8245 -> 100.84955 | Z28: 2 | AD28: =(Z28*4)+(AA28*6)+(AB28*4)+(AC28*3) -> 8 | AE28: =(AD28*8)/1.8245 -> 35.078104 | AF28: =G28+M28+AE28+S28+Y28 -> 271.8553
A29: 45883 | B29: 2 | C29: 3 | E29: 1 | F29: =(B29*4)+(C29*6)+(D29*4)+(E29*3) -> 29 | G29: =(F29*8)/1.8245 -> 127.15813 | H29: 1 | J29: 1 | L29: =(H29*4)+(I29*6)+(J29*4)+(K29*3) -> 8 | M29: =(L29*8)/1.8245 -> 35.078104 | N29: 2 | O29: 1 | Q29: 1 | R29: =(N29*4)+(O29*6)+(P29*4)+(Q29*3) -> 17 | S29: =(R29*8)/1.8245 -> 74.54097 | U29: 1 | X29: =(T29*4)+(U29*6)+(V29*4)+(W29*3) -> 6 | Y29: =(X29*8)/1.8245 -> 26.308578 | Z29: 6 | AB29: 1 | AD29: =(Z29*4)+(AA29*6)+(AB29*4)+(AC29*3) -> 28 | AE29: =(AD29*8)/1.8245 -> 122.77336 | AF29: =G29+M29+AE29+S29+Y29 -> 385.85914
A30: 45884 | B30: 1 | C30: 2 | E30: 1 | F30: =(B30*4)+(C30*6)+(D30*4)+(E30*3) -> 19 | G30: =(F30*8)/1.8245 -> 83.310496 | H30: 2 | L30: =(H30*4)+(I30*6)+(J30*4)+(K30*3) -> 8 | M30: =(L30*8)/1.8245 -> 35.078104 | N30: 2 | O30: 1 | R30: =(N30*4)+(O30*6)+(P30*4)+(Q30*3) -> 14 | S30: =(R30*8)/1.8245 -> 61.386681 | T30: 2 | X30: =(T30*4)+(U30*6)+(V30*4)+(W30*3) -> 8 | Y30: =(X30*8)/1.8245 -> 35.078104 | Z30: 1 | AA30: 1 | AD30: =(Z30*4)+(AA30*6)+(AB30*4)+(AC30*3) -> 10 | AE30: =(AD30*8)/1.8245 -> 43.847629 | AF30: =G30+M30+AE30+S30+Y30 -> 258.70101
