Workbook

Sheet Monitoring
A1: WO | B1: EXT | C1: DESCRIPTION | D1: LOCATION | E1: TOTAL PLANNED PROJECT COST | F1: TOTAL MANHOURS | G1: SUPV | H1: SUPV NAME | I1: VENDOR | J1: Date IR created | K1: Date IR given to QI | L1: QI | M1: PERSONNEL (CSB/NVP) | N1: YEAR FCOMP | O1: Date received from QI (Done Audit) | P1: DONE AUDIT? | Q1: Date created COI | R1: STATUS | S1: TASK COUNT | T1: DATE OF COC
A2: X23072784795 | B2: 'X23072784795', | C2: =IFERROR(VLOOKUP(A2,[1]C1!$E:$F,2,FALSE),IFERROR(VLOOKUP(A2,[2]C1!$E:$F,2,FALSE),VLOOKUP(A2,[3]C1!$E:$F,2,FALSE))) -> DISEGNO DI MILANO INC. DOING BUSINESS UNDER THE NA | D2: =IFERROR(VLOOKUP(A2,[3]C1!$E:$G,3,FALSE),IFERROR(VLOOKUP(A2,[2]C1!$E:$G,3,FALSE),VLOOKUP(A2,[1]C1!$E:$G,3,FALSE))) -> WEST SERVICE, CUPANG, MUNTINLUPA | E2: =IFERROR(VLOOKUP(A2,[4]C1!$E:$S,15,FALSE),IFERROR(VLOOKUP(A2,[5]C1!$E:$T,16,FALSE),VLOOKUP(A2,[6]C1!$E:$T,16,FALSE))) -> 178133.17 | F2: 70.78 | G2: =IFERROR(VLOOKUP(A2,[4]C1!$E:$N,10,FALSE),IFERROR(VLOOKUP(A2,[5]C1!$E:$N,10,FALSE),VLOOKUP(A2,[6]C1!$E:$N,10,FALSE))) -> RRG | H2: RONILO JR GANGE | I2: =IFERROR(VLOOKUP(A2,[4]C1!$E:$L,8,FALSE),IFERROR(VLOOKUP(A2,[5]C1!$E:$L,8,FALSE),VLOOKUP(A2,[6]C1!$E:$L,8,FALSE))) -> AVECO | L2: RAC | N2: =YEAR(IFERROR(VLOOKUP(A2,[4]C1!$E:$AA,23,FALSE),IFERROR(VLOOKUP(A2,[5]C1!$E:$AB,24,FALSE),VLOOKUP(A2,[6]C1!$E:$AB,23,FALSE)))) -> 2023 | O2: 45723 | P2: =IF(ISBLANK(O2),"NO","YES") -> YES | Q2: 45733 | R2: NO BACKJOB | S2: 2 | T2: =IFERROR(VLOOKUP(A2,[4]C1!$E:$BH,56,FALSE),IFERROR(VLOOKUP(A2,[5]C1!$E:$BI,57,FALSE),VLOOKUP(A2,[6]C1!$E:$BI,56,FALSE))) -> 45556
A3: X24062336064 | B3: 'X24062336064', | C3: =IFERROR(VLOOKUP(A3,[1]C1!$E:$F,2,FALSE),IFERROR(VLOOKUP(A3,[2]C1!$E:$F,2,FALSE),VLOOKUP(A3,[3]C1!$E:$F,2,FALSE))) -> DITO TELECOMMUNITY CORPORATION | D3: =IFERROR(VLOOKUP(A3,[3]C1!$E:$G,3,FALSE),IFERROR(VLOOKUP(A3,[2]C1!$E:$G,3,FALSE),VLOOKUP(A3,[1]C1!$E:$G,3,FALSE))) -> CERVANTES CPD, CERVANTES CPD, PARANAQUE | E3: =IFERROR(VLOOKUP(A3,[4]C1!$E:$S,15,FALSE),IFERROR(VLOOKUP(A3,[5]C1!$E:$T,16,FALSE),VLOOKUP(A3,[6]C1!$E:$T,16,FALSE))) -> 205000.15 | F3: 34.62 | G3: =IFERROR(VLOOKUP(A3,[4]C1!$E:$N,10,FALSE),IFERROR(VLOOKUP(A3,[5]C1!$E:$N,10,FALSE),VLOOKUP(A3,[6]C1!$E:$N,10,FALSE))) -> RRG | H3: RONILO JR GANGE | I3: =IFERROR(VLOOKUP(A3,[4]C1!$E:$L,8,FALSE),IFERROR(VLOOKUP(A3,[5]C1!$E:$L,8,FALSE),VLOOKUP(A3,[6]C1!$E:$L,8,FALSE))) -> ECOM | L3: RAC | N3: =YEAR(IFERROR(VLOOKUP(A3,[4]C1!$E:$AA,23,FALSE),IFERROR(VLOOKUP(A3,[5]C1!$E:$AB,24,FALSE),VLOOKUP(A3,[6]C1!$E:$AB,23,FALSE)))) -> 2024 | O3: 45723 | P3: =IF(ISBLANK(O3),"NO","YES") -> YES | Q3: 45733 | R3: WITH BACKJOB | S3: 2 | T3: =IFERROR(VLOOKUP(A3,[4]C1!$E:$BH,56,FALSE),IFERROR(VLOOKUP(A3,[5]C1!$E:$BI,57,FALSE),VLOOKUP(A3,[6]C1!$E:$BI,56,FALSE))) -> 45518
A4: X23114610946 | B4: 'X23114610946', | C4: =IFERROR(VLOOKUP(A4,[1]C1!$E:$F,2,FALSE),IFERROR(VLOOKUP(A4,[2]C1!$E:$F,2,FALSE),VLOOKUP(A4,[3]C1!$E:$F,2,FALSE))) -> SPENCER FOODS CORPORATION | D4: =IFERROR(VLOOKUP(A4,[3]C1!$E:$G,3,FALSE),IFERROR(VLOOKUP(A4,[2]C1!$E:$G,3,FALSE),VLOOKUP(A4,[1]C1!$E:$G,3,FALSE))) -> AGUIRRE, BF HOMES, PARANAQUE | E4: =IFERROR(VLOOKUP(A4,[4]C1!$E:$S,15,FALSE),IFERROR(VLOOKUP(A4,[5]C1!$E:$T,16,FALSE),VLOOKUP(A4,[6]C1!$E:$T,16,FALSE))) -> 48068.36 | F4: 21.57 | G4: =IFERROR(VLOOKUP(A4,[4]C1!$E:$N,10,FALSE),IFERROR(VLOOKUP(A4,[5]C1!$E:$N,10,FALSE),VLOOKUP(A4,[6]C1!$E:$N,10,FALSE))) -> JMM | H4: JENNETH MADRID | I4: =IFERROR(VLOOKUP(A4,[4]C1!$E:$L,8,FALSE),IFERROR(VLOOKUP(A4,[5]C1!$E:$L,8,FALSE),VLOOKUP(A4,[6]C1!$E:$L,8,FALSE))) -> POWERHOUSE | L4: RAC | N4: =YEAR(IFERROR(VLOOKUP(A4,[4]C1!$E:$AA,23,FALSE),IFERROR(VLOOKUP(A4,[5]C1!$E:$AB,24,FALSE),VLOOKUP(A4,[6]C1!$E:$AB,23,FALSE)))) -> 2024 | O4: 45723 | P4: =IF(ISBLANK(O4),"NO","YES") -> YES | Q4: 45733 | R4: NO BACKJOB | S4: 2 | T4: =IFERROR(VLOOKUP(A4,[4]C1!$E:$BH,56,FALSE),IFERROR(VLOOKUP(A4,[5]C1!$E:$BI,57,FALSE),VLOOKUP(A4,[6]C1!$E:$BI,56,FALSE))) -> 45653
A5: X24030858589 | B5: 'X24030858589', | C5: =IFERROR(VLOOKUP(A5,[1]C1!$E:$F,2,FALSE),IFERROR(VLOOKUP(A5,[2]C1!$E:$F,2,FALSE),VLOOKUP(A5,[3]C1!$E:$F,2,FALSE))) -> DEO MISSALYN SARIGUMBA SAVELLANO | D5: =IFERROR(VLOOKUP(A5,[3]C1!$E:$G,3,FALSE),IFERROR(VLOOKUP(A5,[2]C1!$E:$G,3,FALSE),VLOOKUP(A5,[1]C1!$E:$G,3,FALSE))) -> VON BRAUN, MOONWALK, PARANAQUE | E5: =IFERROR(VLOOKUP(A5,[4]C1!$E:$S,15,FALSE),IFERROR(VLOOKUP(A5,[5]C1!$E:$T,16,FALSE),VLOOKUP(A5,[6]C1!$E:$T,16,FALSE))) -> 408530.17 | F5: 110.52 | G5: =IFERROR(VLOOKUP(A5,[4]C1!$E:$N,10,FALSE),IFERROR(VLOOKUP(A5,[5]C1!$E:$N,10,FALSE),VLOOKUP(A5,[6]C1!$E:$N,10,FALSE))) -> JCF | H5: JUNILO MICHAEL FLORES | I5: =IFERROR(VLOOKUP(A5,[4]C1!$E:$L,8,FALSE),IFERROR(VLOOKUP(A5,[5]C1!$E:$L,8,FALSE),VLOOKUP(A5,[6]C1!$E:$L,8,FALSE))) -> CHALLENGER | L5: RAC | N5: =YEAR(IFERROR(VLOOKUP(A5,[4]C1!$E:$AA,23,FALSE),IFERROR(VLOOKUP(A5,[5]C1!$E:$AB,24,FALSE),VLOOKUP(A5,[6]C1!$E:$AB,23,FALSE)))) -> 2024 | O5: 45723 | P5: =IF(ISBLANK(O5),"NO","YES") -> YES | Q5: 45735 | R5: WITH BACKJOB | S5: 6 | T5: =IFERROR(VLOOKUP(A5,[4]C1!$E:$BH,56,FALSE),IFERROR(VLOOKUP(A5,[5]C1!$E:$BI,57,FALSE),VLOOKUP(A5,[6]C1!$E:$BI,56,FALSE))) -> 45518
A6: X23083404027 | B6: 'X23083404027', | C6: =IFERROR(VLOOKUP(A6,[1]C1!$E:$F,2,FALSE),IFERROR(VLOOKUP(A6,[2]C1!$E:$F,2,FALSE),VLOOKUP(A6,[3]C1!$E:$F,2,FALSE))) -> FIL-GARTE CONSTRUCTION AND DEVELOPMENT CORPORATION | D6: =IFERROR(VLOOKUP(A6,[3]C1!$E:$G,3,FALSE),IFERROR(VLOOKUP(A6,[2]C1!$E:$G,3,FALSE),VLOOKUP(A6,[1]C1!$E:$G,3,FALSE))) -> GEN. TIRONA, DULONG BAYAN, BACOOR | E6: =IFERROR(VLOOKUP(A6,[4]C1!$E:$S,15,FALSE),IFERROR(VLOOKUP(A6,[5]C1!$E:$T,16,FALSE),VLOOKUP(A6,[6]C1!$E:$T,16,FALSE))) -> 138793.76 | F6: 17.88 | G6: =IFERROR(VLOOKUP(A6,[4]C1!$E:$N,10,FALSE),IFERROR(VLOOKUP(A6,[5]C1!$E:$N,10,FALSE),VLOOKUP(A6,[6]C1!$E:$N,10,FALSE))) -> DCB | H6: DEAN CARL BORJAL | I6: =IFERROR(VLOOKUP(A6,[4]C1!$E:$L,8,FALSE),IFERROR(VLOOKUP(A6,[5]C1!$E:$L,8,FALSE),VLOOKUP(A6,[6]C1!$E:$L,8,FALSE))) -> POWERHOUSE | L6: CMR | N6: =YEAR(IFERROR(VLOOKUP(A6,[4]C1!$E:$AA,23,FALSE),IFERROR(VLOOKUP(A6,[5]C1!$E:$AB,24,FALSE),VLOOKUP(A6,[6]C1!$E:$AB,23,FALSE)))) -> 2024 | O6: 45723 | P6: =IF(ISBLANK(O6),"NO","YES") -> YES | Q6: 45735 | R6: NO BACKJOB | S6: 3 | T6: =IFERROR(VLOOKUP(A6,[4]C1!$E:$BH,56,FALSE),IFERROR(VLOOKUP(A6,[5]C1!$E:$BI,57,FALSE),VLOOKUP(A6,[6]C1!$E:$BI,56,FALSE))) -> 45406
A7: X24072928648 | B7: 'X24072928648', | C7: =IFERROR(VLOOKUP(A7,[1]C1!$E:$F,2,FALSE),IFERROR(VLOOKUP(A7,[2]C1!$E:$F,2,FALSE),VLOOKUP(A7,[3]C1!$E:$F,2,FALSE))) -> LOWELL L. YU | D7: =IFERROR(VLOOKUP(A7,[3]C1!$E:$G,3,FALSE),IFERROR(VLOOKUP(A7,[2]C1!$E:$G,3,FALSE),VLOOKUP(A7,[1]C1!$E:$G,3,FALSE))) -> NARRA, AYALA-ALABANG VILL, MUNTINLUPA | E7: =IFERROR(VLOOKUP(A7,[4]C1!$E:$S,15,FALSE),IFERROR(VLOOKUP(A7,[5]C1!$E:$T,16,FALSE),VLOOKUP(A7,[6]C1!$E:$T,16,FALSE))) -> 695642.64 | F7: 217.9 | G7: =IFERROR(VLOOKUP(A7,[4]C1!$E:$N,10,FALSE),IFERROR(VLOOKUP(A7,[5]C1!$E:$N,10,FALSE),VLOOKUP(A7,[6]C1!$E:$N,10,FALSE))) -> JSP | H7: JEMUEL PERALTA | I7: =IFERROR(VLOOKUP(A7,[4]C1!$E:$L,8,FALSE),IFERROR(VLOOKUP(A7,[5]C1!$E:$L,8,FALSE),VLOOKUP(A7,[6]C1!$E:$L,8,FALSE))) -> CHALLENGER | L7: RAC | N7: =YEAR(IFERROR(VLOOKUP(A7,[4]C1!$E:$AA,23,FALSE),IFERROR(VLOOKUP(A7,[5]C1!$E:$AB,24,FALSE),VLOOKUP(A7,[6]C1!$E:$AB,23,FALSE)))) -> 2024 | O7: 45733 | P7: =IF(ISBLANK(O7),"NO","YES") -> YES | Q7: 45737 | R7: WITH BACKJOB | S7: 9 | T7: =IFERROR(VLOOKUP(A7,[4]C1!$E:$BH,56,FALSE),IFERROR(VLOOKUP(A7,[5]C1!$E:$BI,57,FALSE),VLOOKUP(A7,[6]C1!$E:$BI,56,FALSE))) -> 45631
A8: X23072898930 | B8: 'X23072898930', | C8: =IFERROR(VLOOKUP(A8,[1]C1!$E:$F,2,FALSE),IFERROR(VLOOKUP(A8,[2]C1!$E:$F,2,FALSE),VLOOKUP(A8,[3]C1!$E:$F,2,FALSE))) -> MONALIZA B. CALUBAT | D8: =IFERROR(VLOOKUP(A8,[3]C1!$E:$G,3,FALSE),IFERROR(VLOOKUP(A8,[2]C1!$E:$G,3,FALSE),VLOOKUP(A8,[1]C1!$E:$G,3,FALSE))) -> BLOCK 2, CAMELLA SPRINGVILLE EXEC II, BACOOR | E8: =IFERROR(VLOOKUP(A8,[4]C1!$E:$S,15,FALSE),IFERROR(VLOOKUP(A8,[5]C1!$E:$T,16,FALSE),VLOOKUP(A8,[6]C1!$E:$T,16,FALSE))) -> 397499.52 | F8: 120.52 | G8: =IFERROR(VLOOKUP(A8,[4]C1!$E:$N,10,FALSE),IFERROR(VLOOKUP(A8,[5]C1!$E:$N,10,FALSE),VLOOKUP(A8,[6]C1!$E:$N,10,FALSE))) -> EAO | H8: RONILO JR GANGE | I8: =IFERROR(VLOOKUP(A8,[4]C1!$E:$L,8,FALSE),IFERROR(VLOOKUP(A8,[5]C1!$E:$L,8,FALSE),VLOOKUP(A8,[6]C1!$E:$L,8,FALSE))) -> AVECO | K8: 45736 | L8: AGD | M8: CSB | N8: =YEAR(IFERROR(VLOOKUP(A8,[4]C1!$E:$AA,23,FALSE),IFERROR(VLOOKUP(A8,[5]C1!$E:$AB,24,FALSE),VLOOKUP(A8,[6]C1!$E:$AB,23,FALSE)))) -> 2023 | O8: 45761 | P8: =IF(ISBLANK(O8),"NO","YES") -> YES | Q8: 45778 | R8: WITH BACKJOB | S8: 3 | T8: =IFERROR(VLOOKUP(A8,[4]C1!$E:$BH,56,FALSE),IFERROR(VLOOKUP(A8,[5]C1!$E:$BI,57,FALSE),VLOOKUP(A8,[6]C1!$E:$BI,56,FALSE))) -> 45497
A9: X21041366402 | B9: 'X21041366402', | C9: =IFERROR(VLOOKUP(A9,[1]C1!$E:$F,2,FALSE),IFERROR(VLOOKUP(A9,[2]C1!$E:$F,2,FALSE),VLOOKUP(A9,[3]C1!$E:$F,2,FALSE))) -> GLOBE TELECOM, INC. | D9: =IFERROR(VLOOKUP(A9,[3]C1!$E:$G,3,FALSE),IFERROR(VLOOKUP(A9,[2]C1!$E:$G,3,FALSE),VLOOKUP(A9,[1]C1!$E:$G,3,FALSE))) -> MALINIS CPD, MALINIS CPD, BACOOR | E9: =IFERROR(VLOOKUP(A9,[4]C1!$E:$S,15,FALSE),IFERROR(VLOOKUP(A9,[5]C1!$E:$T,16,FALSE),VLOOKUP(A9,[6]C1!$E:$T,16,FALSE))) -> 14049.52 | F9: 4.75 | G9: =IFERROR(VLOOKUP(A9,[4]C1!$E:$N,10,FALSE),IFERROR(VLOOKUP(A9,[5]C1!$E:$N,10,FALSE),VLOOKUP(A9,[6]C1!$E:$N,10,FALSE))) -> RRG | H9: RONILO JR GANGE | I9: =IFERROR(VLOOKUP(A9,[4]C1!$E:$L,8,FALSE),IFERROR(VLOOKUP(A9,[5]C1!$E:$L,8,FALSE),VLOOKUP(A9,[6]C1!$E:$L,8,FALSE))) -> AVECO | K9: 45736 | L9: AGD | M9: CSB | N9: =YEAR(IFERROR(VLOOKUP(A9,[4]C1!$E:$AA,23,FALSE),IFERROR(VLOOKUP(A9,[5]C1!$E:$AB,24,FALSE),VLOOKUP(A9,[6]C1!$E:$AB,23,FALSE)))) -> 2022 | P9: =IF(ISBLANK(O9),"NO","YES") -> NO | S9: 2 | T9: =IFERROR(VLOOKUP(A9,[4]C1!$E:$BH,56,FALSE),IFERROR(VLOOKUP(A9,[5]C1!$E:$BI,57,FALSE),VLOOKUP(A9,[6]C1!$E:$BI,56,FALSE))) -> 45455
A10: X22093803978 | B10: 'X22093803978', | C10: =IFERROR(VLOOKUP(A10,[1]C1!$E:$F,2,FALSE),IFERROR(VLOOKUP(A10,[2]C1!$E:$F,2,FALSE),VLOOKUP(A10,[3]C1!$E:$F,2,FALSE))) -> HOUSEHOLD DEVELOPMENT CORPORATION, | D10: =IFERROR(VLOOKUP(A10,[3]C1!$E:$G,3,FALSE),IFERROR(VLOOKUP(A10,[2]C1!$E:$G,3,FALSE),VLOOKUP(A10,[1]C1!$E:$G,3,FALSE))) -> BLOCK 3, VILLA LESSANDRA 6, BACOOR | E10: =IFERROR(VLOOKUP(A10,[4]C1!$E:$S,15,FALSE),IFERROR(VLOOKUP(A10,[5]C1!$E:$T,16,FALSE),VLOOKUP(A10,[6]C1!$E:$T,16,FALSE))) -> 23361.7 | F10: 17.05 | G10: =IFERROR(VLOOKUP(A10,[4]C1!$E:$N,10,FALSE),IFERROR(VLOOKUP(A10,[5]C1!$E:$N,10,FALSE),VLOOKUP(A10,[6]C1!$E:$N,10,FALSE))) -> RRG | H10: RONILO JR GANGE | I10: =IFERROR(VLOOKUP(A10,[4]C1!$E:$L,8,FALSE),IFERROR(VLOOKUP(A10,[5]C1!$E:$L,8,FALSE),VLOOKUP(A10,[6]C1!$E:$L,8,FALSE))) -> AVECO | K10: 45736 | L10: AGD | M10: CSB | N10: =YEAR(IFERROR(VLOOKUP(A10,[4]C1!$E:$AA,23,FALSE),IFERROR(VLOOKUP(A10,[5]C1!$E:$AB,24,FALSE),VLOOKUP(A10,[6]C1!$E:$AB,23,FALSE)))) -> 2022 | O10: 45881 | P10: =IF(ISBLANK(O10),"NO","YES") -> YES | Q10: 45887 | R10: NO BACKJOB | S10: 2 | T10: =IFERROR(VLOOKUP(A10,[4]C1!$E:$BH,56,FALSE),IFERROR(VLOOKUP(A10,[5]C1!$E:$BI,57,FALSE),VLOOKUP(A10,[6]C1!$E:$BI,56,FALSE))) -> 45081
A11: X22083673909 | B11: 'X22083673909', | C11: =IFERROR(VLOOKUP(A11,[1]C1!$E:$F,2,FALSE),IFERROR(VLOOKUP(A11,[2]C1!$E:$F,2,FALSE),VLOOKUP(A11,[3]C1!$E:$F,2,FALSE))) -> ALEJANDRO AQUINO | D11: =IFERROR(VLOOKUP(A11,[3]C1!$E:$G,3,FALSE),IFERROR(VLOOKUP(A11,[2]C1!$E:$G,3,FALSE),VLOOKUP(A11,[1]C1!$E:$G,3,FALSE))) -> BLOCK 13, GREEN VALLEY SUBD SECT A, BACOOR | E11: =IFERROR(VLOOKUP(A11,[4]C1!$E:$S,15,FALSE),IFERROR(VLOOKUP(A11,[5]C1!$E:$T,16,FALSE),VLOOKUP(A11,[6]C1!$E:$T,16,FALSE))) -> 285521.42 | F11: 74.25 | G11: =IFERROR(VLOOKUP(A11,[4]C1!$E:$N,10,FALSE),IFERROR(VLOOKUP(A11,[5]C1!$E:$N,10,FALSE),VLOOKUP(A11,[6]C1!$E:$N,10,FALSE))) -> EAO | H11: JEMUEL PERALTA | I11: =IFERROR(VLOOKUP(A11,[4]C1!$E:$L,8,FALSE),IFERROR(VLOOKUP(A11,[5]C1!$E:$L,8,FALSE),VLOOKUP(A11,[6]C1!$E:$L,8,FALSE))) -> CHALLENGER | K11: 45736 | L11: AGD | M11: CSB | N11: =YEAR(IFERROR(VLOOKUP(A11,[4]C1!$E:$AA,23,FALSE),IFERROR(VLOOKUP(A11,[5]C1!$E:$AB,24,FALSE),VLOOKUP(A11,[6]C1!$E:$AB,23,FALSE)))) -> 2023 | O11: 45743 | P11: =IF(ISBLANK(O11),"NO","YES") -> YES | Q11: 45855 | R11: WITH BACKJOB | S11: 4 | T11: =IFERROR(VLOOKUP(A11,[4]C1!$E:$BH,56,FALSE),IFERROR(VLOOKUP(A11,[5]C1!$E:$BI,57,FALSE),VLOOKUP(A11,[6]C1!$E:$BI,56,FALSE))) -> 45249
A12: X22125090828 | B12: 'X22125090828', | C12: =IFERROR(VLOOKUP(A12,[1]C1!$E:$F,2,FALSE),IFERROR(VLOOKUP(A12,[2]C1!$E:$F,2,FALSE),VLOOKUP(A12,[3]C1!$E:$F,2,FALSE))) -> DITO TELECOMMUNITY CORPORATION | D12: =IFERROR(VLOOKUP(A12,[3]C1!$E:$G,3,FALSE),IFERROR(VLOOKUP(A12,[2]C1!$E:$G,3,FALSE),VLOOKUP(A12,[1]C1!$E:$G,3,FALSE))) -> ANIBAN V, ANIBAN V, BACOOR | E12: =IFERROR(VLOOKUP(A12,[4]C1!$E:$S,15,FALSE),IFERROR(VLOOKUP(A12,[5]C1!$E:$T,16,FALSE),VLOOKUP(A12,[6]C1!$E:$T,16,FALSE))) -> 49092.14 | F12: 23.18 | G12: =IFERROR(VLOOKUP(A12,[4]C1!$E:$N,10,FALSE),IFERROR(VLOOKUP(A12,[5]C1!$E:$N,10,FALSE),VLOOKUP(A12,[6]C1!$E:$N,10,FALSE))) -> RRG | H12: RONILO JR GANGE | I12: =IFERROR(VLOOKUP(A12,[4]C1!$E:$L,8,FALSE),IFERROR(VLOOKUP(A12,[5]C1!$E:$L,8,FALSE),VLOOKUP(A12,[6]C1!$E:$L,8,FALSE))) -> AVECO | K12: 45736 | L12: AGD | M12: CSB | N12: =YEAR(IFERROR(VLOOKUP(A12,[4]C1!$E:$AA,23,FALSE),IFERROR(VLOOKUP(A12,[5]C1!$E:$AB,24,FALSE),VLOOKUP(A12,[6]C1!$E:$AB,23,FALSE)))) -> 2023 | O12: 45881 | P12: =IF(ISBLANK(O12),"NO","YES") -> YES | Q12: 45887 | R12: NO BACKJOB | S12: 4 | T12: =IFERROR(VLOOKUP(A12,[4]C1!$E:$BH,56,FALSE),IFERROR(VLOOKUP(A12,[5]C1!$E:$BI,57,FALSE),VLOOKUP(A12,[6]C1!$E:$BI,56,FALSE))) -> 45245
A13: X23051874609 | B13: 'X23051874609', | C13: =IFERROR(VLOOKUP(A13,[1]C1!$E:$F,2,FALSE),IFERROR(VLOOKUP(A13,[2]C1!$E:$F,2,FALSE),VLOOKUP(A13,[3]C1!$E:$F,2,FALSE))) -> STA. LUCIA REALTY & DEVELOPMENT, INC. | D13: =IFERROR(VLOOKUP(A13,[3]C1!$E:$G,3,FALSE),IFERROR(VLOOKUP(A13,[2]C1!$E:$G,3,FALSE),VLOOKUP(A13,[1]C1!$E:$G,3,FALSE))) -> HAZEL, VISTA VERDE SOUTH EXEC VILL 2, BACOOR | E13: =IFERROR(VLOOKUP(A13,[4]C1!$E:$S,15,FALSE),IFERROR(VLOOKUP(A13,[5]C1!$E:$T,16,FALSE),VLOOKUP(A13,[6]C1!$E:$T,16,FALSE))) -> 209139.71 | F13: 40.23 | G13: =IFERROR(VLOOKUP(A13,[4]C1!$E:$N,10,FALSE),IFERROR(VLOOKUP(A13,[5]C1!$E:$N,10,FALSE),VLOOKUP(A13,[6]C1!$E:$N,10,FALSE))) -> EAO | H13: ISAN CARLO LAZARO | I13: =IFERROR(VLOOKUP(A13,[4]C1!$E:$L,8,FALSE),IFERROR(VLOOKUP(A13,[5]C1!$E:$L,8,FALSE),VLOOKUP(A13,[6]C1!$E:$L,8,FALSE))) -> CHALLENGER | K13: 45736 | L13: AGD | M13: CSB | N13: =YEAR(IFERROR(VLOOKUP(A13,[4]C1!$E:$AA,23,FALSE),IFERROR(VLOOKUP(A13,[5]C1!$E:$AB,24,FALSE),VLOOKUP(A13,[6]C1!$E:$AB,23,FALSE)))) -> 2023 | O13: 45756 | P13: =IF(ISBLANK(O13),"NO","YES") -> YES | Q13: / | R13: NO BACKJOB | S13: 3 | T13: =IFERROR(VLOOKUP(A13,[4]C1!$E:$BH,56,FALSE),IFERROR(VLOOKUP(A13,[5]C1!$E:$BI,57,FALSE),VLOOKUP(A13,[6]C1!$E:$BI,56,FALSE))) -> 45130
A14: X22041707487 | B14: 'X22041707487', | C14: =IFERROR(VLOOKUP(A14,[1]C1!$E:$F,2,FALSE),IFERROR(VLOOKUP(A14,[2]C1!$E:$F,2,FALSE),VLOOKUP(A14,[3]C1!$E:$F,2,FALSE))) -> NOEMI BORROMEO DOMINGUEZ | D14: =IFERROR(VLOOKUP(A14,[3]C1!$E:$G,3,FALSE),IFERROR(VLOOKUP(A14,[2]C1!$E:$G,3,FALSE),VLOOKUP(A14,[1]C1!$E:$G,3,FALSE))) -> ALDRIN, MOONWALK, PARANAQUE | E14: =IFERROR(VLOOKUP(A14,[4]C1!$E:$S,15,FALSE),IFERROR(VLOOKUP(A14,[5]C1!$E:$T,16,FALSE),VLOOKUP(A14,[6]C1!$E:$T,16,FALSE))) -> 1913754.1 | F14: 1011.12 | G14: =IFERROR(VLOOKUP(A14,[4]C1!$E:$N,10,FALSE),IFERROR(VLOOKUP(A14,[5]C1!$E:$N,10,FALSE),VLOOKUP(A14,[6]C1!$E:$N,10,FALSE))) -> IJP | H14: IAN PATRICK PEREZ | I14: =IFERROR(VLOOKUP(A14,[4]C1!$E:$L,8,FALSE),IFERROR(VLOOKUP(A14,[5]C1!$E:$L,8,FALSE),VLOOKUP(A14,[6]C1!$E:$L,8,FALSE))) -> POWERHOUSE | K14: 45736 | L14: AGD | M14: CSB | N14: =YEAR(IFERROR(VLOOKUP(A14,[4]C1!$E:$AA,23,FALSE),IFERROR(VLOOKUP(A14,[5]C1!$E:$AB,24,FALSE),VLOOKUP(A14,[6]C1!$E:$AB,23,FALSE)))) -> 2022 | P14: =IF(ISBLANK(O14),"NO","YES") -> NO | S14: 19 | T14: =IFERROR(VLOOKUP(A14,[4]C1!$E:$BH,56,FALSE),IFERROR(VLOOKUP(A14,[5]C1!$E:$BI,57,FALSE),VLOOKUP(A14,[6]C1!$E:$BI,56,FALSE))) -> 45706
A15: X23083147226 | B15: 'X23083147226', | C15: =IFERROR(VLOOKUP(A15,[1]C1!$E:$F,2,FALSE),IFERROR(VLOOKUP(A15,[2]C1!$E:$F,2,FALSE),VLOOKUP(A15,[3]C1!$E:$F,2,FALSE))) -> CITY GOVERNMENT OF PARAÑAQUE | D15: =IFERROR(VLOOKUP(A15,[3]C1!$E:$G,3,FALSE),IFERROR(VLOOKUP(A15,[2]C1!$E:$G,3,FALSE),VLOOKUP(A15,[1]C1!$E:$G,3,FALSE))) -> STA. MONICA, DON GALO, PARANAQUE | E15: =IFERROR(VLOOKUP(A15,[4]C1!$E:$S,15,FALSE),IFERROR(VLOOKUP(A15,[5]C1!$E:$T,16,FALSE),VLOOKUP(A15,[6]C1!$E:$T,16,FALSE))) -> 333554.59 | F15: 80.32 | G15: =IFERROR(VLOOKUP(A15,[4]C1!$E:$N,10,FALSE),IFERROR(VLOOKUP(A15,[5]C1!$E:$N,10,FALSE),VLOOKUP(A15,[6]C1!$E:$N,10,FALSE))) -> RRG | H15: RONILO JR GANGE | I15: =IFERROR(VLOOKUP(A15,[4]C1!$E:$L,8,FALSE),IFERROR(VLOOKUP(A15,[5]C1!$E:$L,8,FALSE),VLOOKUP(A15,[6]C1!$E:$L,8,FALSE))) -> AVECO | K15: 45736 | L15: AGD | M15: CSB | N15: =YEAR(IFERROR(VLOOKUP(A15,[4]C1!$E:$AA,23,FALSE),IFERROR(VLOOKUP(A15,[5]C1!$E:$AB,24,FALSE),VLOOKUP(A15,[6]C1!$E:$AB,23,FALSE)))) -> 2023 | P15: =IF(ISBLANK(O15),"NO","YES") -> NO | S15: 4 | T15: =IFERROR(VLOOKUP(A15,[4]C1!$E:$BH,56,FALSE),IFERROR(VLOOKUP(A15,[5]C1!$E:$BI,57,FALSE),VLOOKUP(A15,[6]C1!$E:$BI,56,FALSE))) -> 45671
A16: X23093500518 | B16: 'X23093500518', | C16: =IFERROR(VLOOKUP(A16,[1]C1!$E:$F,2,FALSE),IFERROR(VLOOKUP(A16,[2]C1!$E:$F,2,FALSE),VLOOKUP(A16,[3]C1!$E:$F,2,FALSE))) -> JOYCE ANN ROMAN TUMANG | D16: =IFERROR(VLOOKUP(A16,[3]C1!$E:$G,3,FALSE),IFERROR(VLOOKUP(A16,[2]C1!$E:$G,3,FALSE),VLOOKUP(A16,[1]C1!$E:$G,3,FALSE))) -> CAPERNAUM, MULTINATIONAL VILL, PARANAQUE | E16: =IFERROR(VLOOKUP(A16,[4]C1!$E:$S,15,FALSE),IFERROR(VLOOKUP(A16,[5]C1!$E:$T,16,FALSE),VLOOKUP(A16,[6]C1!$E:$T,16,FALSE))) -> 473227.53 | F16: 135.73 | G16: =IFERROR(VLOOKUP(A16,[4]C1!$E:$N,10,FALSE),IFERROR(VLOOKUP(A16,[5]C1!$E:$N,10,FALSE),VLOOKUP(A16,[6]C1!$E:$N,10,FALSE))) -> EAO | H16: JEMUEL PERALTA | I16: =IFERROR(VLOOKUP(A16,[4]C1!$E:$L,8,FALSE),IFERROR(VLOOKUP(A16,[5]C1!$E:$L,8,FALSE),VLOOKUP(A16,[6]C1!$E:$L,8,FALSE))) -> VJC | K16: 45736 | L16: ECI | M16: CSB | N16: =YEAR(IFERROR(VLOOKUP(A16,[4]C1!$E:$AA,23,FALSE),IFERROR(VLOOKUP(A16,[5]C1!$E:$AB,24,FALSE),VLOOKUP(A16,[6]C1!$E:$AB,23,FALSE)))) -> 2023 | O16: 45769 | P16: =IF(ISBLANK(O16),"NO","YES") -> YES | Q16: 45847 | R16: WITH BACKJOB | S16: 5 | T16: =IFERROR(VLOOKUP(A16,[4]C1!$E:$BH,56,FALSE),IFERROR(VLOOKUP(A16,[5]C1!$E:$BI,57,FALSE),VLOOKUP(A16,[6]C1!$E:$BI,56,FALSE))) -> 45612
A17: X24093865089 | B17: 'X24093865089', | C17: =IFERROR(VLOOKUP(A17,[1]C1!$E:$F,2,FALSE),IFERROR(VLOOKUP(A17,[2]C1!$E:$F,2,FALSE),VLOOKUP(A17,[3]C1!$E:$F,2,FALSE))) -> JOVY BITANGCOL LOSERIAGA | D17: =IFERROR(VLOOKUP(A17,[3]C1!$E:$G,3,FALSE),IFERROR(VLOOKUP(A17,[2]C1!$E:$G,3,FALSE),VLOOKUP(A17,[1]C1!$E:$G,3,FALSE))) -> BLOCK 8, AFP OVAI PH 1, TAGUIG CITY | E17: =IFERROR(VLOOKUP(A17,[4]C1!$E:$S,15,FALSE),IFERROR(VLOOKUP(A17,[5]C1!$E:$T,16,FALSE),VLOOKUP(A17,[6]C1!$E:$T,15,FALSE))) -> 41516.72 | F17: 15.83 | G17: =IFERROR(VLOOKUP(A17,[4]C1!$E:$N,10,FALSE),IFERROR(VLOOKUP(A17,[5]C1!$E:$N,10,FALSE),VLOOKUP(A17,[6]C1!$E:$N,10,FALSE))) -> Jenneth Madrid | H17: JENNETH MADRID | I17: =IFERROR(VLOOKUP(A17,[4]C1!$E:$L,8,FALSE),IFERROR(VLOOKUP(A17,[5]C1!$E:$L,8,FALSE),VLOOKUP(A17,[6]C1!$E:$L,8,FALSE))) -> VJC | J17: 45736 | K17: 45839 | L17: RCL | N17: =YEAR(IFERROR(VLOOKUP(A17,[4]C1!$E:$AA,23,FALSE),IFERROR(VLOOKUP(A17,[5]C1!$E:$AB,24,FALSE),VLOOKUP(A17,[6]C1!$E:$AB,23,FALSE)))) -> 2025 | O17: 45848 | P17: =IF(ISBLANK(O17),"NO","YES") -> YES | Q17: 45880 | R17: NO BACKJOB | S17: 2 | T17: =IFERROR(VLOOKUP(A17,[4]C1!$E:$BH,56,FALSE),IFERROR(VLOOKUP(A17,[5]C1!$E:$BI,57,FALSE),VLOOKUP(A17,[6]C1!$E:$BI,56,FALSE))) -> 45723
A18: X24093492216 | B18: 'X24093492216', | C18: =IFERROR(VLOOKUP(A18,[1]C1!$E:$F,2,FALSE),IFERROR(VLOOKUP(A18,[2]C1!$E:$F,2,FALSE),VLOOKUP(A18,[3]C1!$E:$F,2,FALSE))) -> ALFAMART TRADING PHILIPPINES, INC. | D18: =IFERROR(VLOOKUP(A18,[3]C1!$E:$G,3,FALSE),IFERROR(VLOOKUP(A18,[2]C1!$E:$G,3,FALSE),VLOOKUP(A18,[1]C1!$E:$G,3,FALSE))) -> SUMMIT CIRCLE SUBD, SUMMIT CIRCLE SUBD, MUNTINLUPA | E18: =IFERROR(VLOOKUP(A18,[4]C1!$E:$S,15,FALSE),IFERROR(VLOOKUP(A18,[5]C1!$E:$T,16,FALSE),VLOOKUP(A18,[6]C1!$E:$T,15,FALSE))) -> 186146.6 | F18: 17.58 | G18: =IFERROR(VLOOKUP(A18,[4]C1!$E:$N,10,FALSE),IFERROR(VLOOKUP(A18,[5]C1!$E:$N,10,FALSE),VLOOKUP(A18,[6]C1!$E:$N,10,FALSE))) -> Isan Carlo Lazaro | H18: ISAN CARLO LAZARO | I18: =IFERROR(VLOOKUP(A18,[4]C1!$E:$L,8,FALSE),IFERROR(VLOOKUP(A18,[5]C1!$E:$L,8,FALSE),VLOOKUP(A18,[6]C1!$E:$L,8,FALSE))) -> CHALLENGER | J18: 45736 | K18: 45863 | L18: AGD | N18: =YEAR(IFERROR(VLOOKUP(A18,[4]C1!$E:$AA,23,FALSE),IFERROR(VLOOKUP(A18,[5]C1!$E:$AB,24,FALSE),VLOOKUP(A18,[6]C1!$E:$AB,23,FALSE)))) -> 2025 | O18: 45863 | P18: =IF(ISBLANK(O18),"NO","YES") -> YES | Q18: 45869 | R18: NO BACKJOB | S18: 3 | T18: =IFERROR(VLOOKUP(A18,[4]C1!$E:$BH,56,FALSE),IFERROR(VLOOKUP(A18,[5]C1!$E:$BI,57,FALSE),VLOOKUP(A18,[6]C1!$E:$BI,56,FALSE))) -> 45733
A19: X25010119305 | B19: 'X25010119305', | C19: =IFERROR(VLOOKUP(A19,[1]C1!$E:$F,2,FALSE),IFERROR(VLOOKUP(A19,[2]C1!$E:$F,2,FALSE),VLOOKUP(A19,[3]C1!$E:$F,2,FALSE))) -> VICENTE P PEREZ | D19: =IFERROR(VLOOKUP(A19,[3]C1!$E:$G,3,FALSE),IFERROR(VLOOKUP(A19,[2]C1!$E:$G,3,FALSE),VLOOKUP(A19,[1]C1!$E:$G,3,FALSE))) -> EL GRANDE, BF HOMES, PARANAQUE | E19: =IFERROR(VLOOKUP(A19,[4]C1!$E:$S,15,FALSE),IFERROR(VLOOKUP(A19,[5]C1!$E:$T,16,FALSE),VLOOKUP(A19,[6]C1!$E:$T,15,FALSE))) -> 241637.84 | F19: 45.67 | G19: =IFERROR(VLOOKUP(A19,[4]C1!$E:$N,10,FALSE),IFERROR(VLOOKUP(A19,[5]C1!$E:$N,10,FALSE),VLOOKUP(A19,[6]C1!$E:$N,10,FALSE))) -> Isan Carlo Lazaro | H19: ISAN CARLO LAZARO | I19: =IFERROR(VLOOKUP(A19,[4]C1!$E:$L,8,FALSE),IFERROR(VLOOKUP(A19,[5]C1!$E:$L,8,FALSE),VLOOKUP(A19,[6]C1!$E:$L,8,FALSE))) -> CHALLENGER | J19: 45736 | K19: 45737 | L19: AGD | M19: CSB | N19: =YEAR(IFERROR(VLOOKUP(A19,[4]C1!$E:$AA,23,FALSE),IFERROR(VLOOKUP(A19,[5]C1!$E:$AB,24,FALSE),VLOOKUP(A19,[6]C1!$E:$AB,23,FALSE)))) -> 2025 | O19: 45740 | P19: =IF(ISBLANK(O19),"NO","YES") -> YES | Q19: 45855 | R19: NO BACKJOB | S19: 3 | T19: =IFERROR(VLOOKUP(A19,[4]C1!$E:$BH,56,FALSE),IFERROR(VLOOKUP(A19,[5]C1!$E:$BI,57,FALSE),VLOOKUP(A19,[6]C1!$E:$BI,56,FALSE))) -> 45727
A20: X24093707345 | B20: 'X24093707345', | C20: =IFERROR(VLOOKUP(A20,[1]C1!$E:$F,2,FALSE),IFERROR(VLOOKUP(A20,[2]C1!$E:$F,2,FALSE),VLOOKUP(A20,[3]C1!$E:$F,2,FALSE))) -> CITY GOVERNMENT OF TAGUIG | D20: =IFERROR(VLOOKUP(A20,[3]C1!$E:$G,3,FALSE),IFERROR(VLOOKUP(A20,[2]C1!$E:$G,3,FALSE),VLOOKUP(A20,[1]C1!$E:$G,3,FALSE))) -> MAGSAYSAY, ZONE 6, TAGUIG CITY | E20: =IFERROR(VLOOKUP(A20,[4]C1!$E:$S,15,FALSE),IFERROR(VLOOKUP(A20,[5]C1!$E:$T,16,FALSE),VLOOKUP(A20,[6]C1!$E:$T,15,FALSE))) -> 715296.24 | F20: 114.4 | G20: =IFERROR(VLOOKUP(A20,[4]C1!$E:$N,10,FALSE),IFERROR(VLOOKUP(A20,[5]C1!$E:$N,10,FALSE),VLOOKUP(A20,[6]C1!$E:$N,10,FALSE))) -> Jenneth Madrid | H20: JENNETH MADRID | I20: =IFERROR(VLOOKUP(A20,[4]C1!$E:$L,8,FALSE),IFERROR(VLOOKUP(A20,[5]C1!$E:$L,8,FALSE),VLOOKUP(A20,[6]C1!$E:$L,8,FALSE))) -> VJC | J20: 45736 | K20: 45737 | L20: AGD | M20: CSB | N20: =YEAR(IFERROR(VLOOKUP(A20,[4]C1!$E:$AA,23,FALSE),IFERROR(VLOOKUP(A20,[5]C1!$E:$AB,24,FALSE),VLOOKUP(A20,[6]C1!$E:$AB,23,FALSE)))) -> 2025 | O20: 45744 | P20: =IF(ISBLANK(O20),"NO","YES") -> YES | Q20: 45749 | R20: WITH BACKJOB | S20: 3 | T20: =IFERROR(VLOOKUP(A20,[4]C1!$E:$BH,56,FALSE),IFERROR(VLOOKUP(A20,[5]C1!$E:$BI,57,FALSE),VLOOKUP(A20,[6]C1!$E:$BI,56,FALSE))) -> 45723
A21: X24114622443 | B21: 'X24114622443', | C21: =IFERROR(VLOOKUP(A21,[1]C1!$E:$F,2,FALSE),IFERROR(VLOOKUP(A21,[2]C1!$E:$F,2,FALSE),VLOOKUP(A21,[3]C1!$E:$F,2,FALSE))) -> NELSON BALIGUAT RODRIGUEZ | D21: =IFERROR(VLOOKUP(A21,[3]C1!$E:$G,3,FALSE),IFERROR(VLOOKUP(A21,[2]C1!$E:$G,3,FALSE),VLOOKUP(A21,[1]C1!$E:$G,3,FALSE))) -> ENLISTED PERSONNEL VIL 2, TAGUIG CITY | E21: =IFERROR(VLOOKUP(A21,[4]C1!$E:$S,15,FALSE),IFERROR(VLOOKUP(A21,[5]C1!$E:$T,16,FALSE),VLOOKUP(A21,[6]C1!$E:$T,15,FALSE))) -> 78921.54 | F21: 54.73 | G21: =IFERROR(VLOOKUP(A21,[4]C1!$E:$N,10,FALSE),IFERROR(VLOOKUP(A21,[5]C1!$E:$N,10,FALSE),VLOOKUP(A21,[6]C1!$E:$N,10,FALSE))) -> Jenneth Madrid | H21: JENNETH MADRID | I21: =IFERROR(VLOOKUP(A21,[4]C1!$E:$L,8,FALSE),IFERROR(VLOOKUP(A21,[5]C1!$E:$L,8,FALSE),VLOOKUP(A21,[6]C1!$E:$L,8,FALSE))) -> VJC | J21: 45736 | K21: 45839 | L21: RCL | N21: =YEAR(IFERROR(VLOOKUP(A21,[4]C1!$E:$AA,23,FALSE),IFERROR(VLOOKUP(A21,[5]C1!$E:$AB,24,FALSE),VLOOKUP(A21,[6]C1!$E:$AB,23,FALSE)))) -> 2025 | O21: 45848 | P21: =IF(ISBLANK(O21),"NO","YES") -> YES | Q21: 45881 | R21: WITH BACKJOB | S21: 4 | T21: =IFERROR(VLOOKUP(A21,[4]C1!$E:$BH,56,FALSE),IFERROR(VLOOKUP(A21,[5]C1!$E:$BI,57,FALSE),VLOOKUP(A21,[6]C1!$E:$BI,56,FALSE))) -> 45723
A22: X25010059547 | B22: 'X25010059547', | C22: =IFERROR(VLOOKUP(A22,[1]C1!$E:$F,2,FALSE),IFERROR(VLOOKUP(A22,[2]C1!$E:$F,2,FALSE),VLOOKUP(A22,[3]C1!$E:$F,2,FALSE))) -> ALFAMETRO MARKETING INC. (CORCUERRA - BANNER 4TH ESTATE) | D22: =IFERROR(VLOOKUP(A22,[3]C1!$E:$G,3,FALSE),IFERROR(VLOOKUP(A22,[2]C1!$E:$G,3,FALSE),VLOOKUP(A22,[1]C1!$E:$G,3,FALSE))) -> BANNER, 4TH ESTATE SUBD, PARANAQUE | E22: =IFERROR(VLOOKUP(A22,[4]C1!$E:$S,15,FALSE),IFERROR(VLOOKUP(A22,[5]C1!$E:$T,16,FALSE),VLOOKUP(A22,[6]C1!$E:$T,15,FALSE))) -> 202246.77 | F22: 27.28 | G22: =IFERROR(VLOOKUP(A22,[4]C1!$E:$N,10,FALSE),IFERROR(VLOOKUP(A22,[5]C1!$E:$N,10,FALSE),VLOOKUP(A22,[6]C1!$E:$N,10,FALSE))) -> Isan Carlo Lazaro | H22: ISAN CARLO LAZARO | I22: =IFERROR(VLOOKUP(A22,[4]C1!$E:$L,8,FALSE),IFERROR(VLOOKUP(A22,[5]C1!$E:$L,8,FALSE),VLOOKUP(A22,[6]C1!$E:$L,8,FALSE))) -> CHALLENGER | J22: 45736 | K22: 45737 | L22: AGD | M22: CSB | N22: =YEAR(IFERROR(VLOOKUP(A22,[4]C1!$E:$AA,23,FALSE),IFERROR(VLOOKUP(A22,[5]C1!$E:$AB,24,FALSE),VLOOKUP(A22,[6]C1!$E:$AB,23,FALSE)))) -> 2025 | O22: 45741 | P22: =IF(ISBLANK(O22),"NO","YES") -> YES | Q22: / | R22: NO BACKJOB | S22: 3 | T22: =IFERROR(VLOOKUP(A22,[4]C1!$E:$BH,56,FALSE),IFERROR(VLOOKUP(A22,[5]C1!$E:$BI,57,FALSE),VLOOKUP(A22,[6]C1!$E:$BI,56,FALSE))) -> 45729
A23: X23104201686 | B23: 'X23104201686', | C23: =IFERROR(VLOOKUP(A23,[1]C1!$E:$F,2,FALSE),IFERROR(VLOOKUP(A23,[2]C1!$E:$F,2,FALSE),VLOOKUP(A23,[3]C1!$E:$F,2,FALSE))) -> MINGHAI SU | D23: =IFERROR(VLOOKUP(A23,[3]C1!$E:$G,3,FALSE),IFERROR(VLOOKUP(A23,[2]C1!$E:$G,3,FALSE),VLOOKUP(A23,[1]C1!$E:$G,3,FALSE))) -> MATTHEW, MULTINATIONAL VILL, PARANAQUE | E23: =IFERROR(VLOOKUP(A23,[4]C1!$E:$S,15,FALSE),IFERROR(VLOOKUP(A23,[5]C1!$E:$T,16,FALSE),VLOOKUP(A23,[6]C1!$E:$T,15,FALSE))) -> 428089.39 | F23: 86.52 | G23: =IFERROR(VLOOKUP(A23,[4]C1!$E:$N,10,FALSE),IFERROR(VLOOKUP(A23,[5]C1!$E:$N,10,FALSE),VLOOKUP(A23,[6]C1!$E:$N,10,FALSE))) -> Isan Carlo Lazaro | H23: ISAN CARLO LAZARO | I23: =IFERROR(VLOOKUP(A23,[4]C1!$E:$L,8,FALSE),IFERROR(VLOOKUP(A23,[5]C1!$E:$L,8,FALSE),VLOOKUP(A23,[6]C1!$E:$L,8,FALSE))) -> CHALLENGER | J23: 45736 | K23: 45737 | L23: AGD | M23: CSB | N23: =YEAR(IFERROR(VLOOKUP(A23,[4]C1!$E:$AA,23,FALSE),IFERROR(VLOOKUP(A23,[5]C1!$E:$AB,24,FALSE),VLOOKUP(A23,[6]C1!$E:$AB,23,FALSE)))) -> 2025 | O23: 45741 | P23: =IF(ISBLANK(O23),"NO","YES") -> YES | Q23: 45817 | R23: WITH BACKJOB | S23: 3 | T23: =IFERROR(VLOOKUP(A23,[4]C1!$E:$BH,56,FALSE),IFERROR(VLOOKUP(A23,[5]C1!$E:$BI,57,FALSE),VLOOKUP(A23,[6]C1!$E:$BI,56,FALSE))) -> 45729
A24: X24104141244 | B24: 'X24104141244', | C24: =IFERROR(VLOOKUP(A24,[1]C1!$E:$F,2,FALSE),IFERROR(VLOOKUP(A24,[2]C1!$E:$F,2,FALSE),VLOOKUP(A24,[3]C1!$E:$F,2,FALSE))) -> SERVEQUEST INC. | D24: =IFERROR(VLOOKUP(A24,[3]C1!$E:$G,3,FALSE),IFERROR(VLOOKUP(A24,[2]C1!$E:$G,3,FALSE),VLOOKUP(A24,[1]C1!$E:$G,3,FALSE))) -> SUMMIT CIRCLE SUBD, SUMMIT CIRCLE SUBD, MUNTINLUPA | E24: =IFERROR(VLOOKUP(A24,[4]C1!$E:$S,15,FALSE),IFERROR(VLOOKUP(A24,[5]C1!$E:$T,16,FALSE),VLOOKUP(A24,[6]C1!$E:$T,15,FALSE))) -> 846988.2 | F24: 139.87 | G24: =IFERROR(VLOOKUP(A24,[4]C1!$E:$N,10,FALSE),IFERROR(VLOOKUP(A24,[5]C1!$E:$N,10,FALSE),VLOOKUP(A24,[6]C1!$E:$N,10,FALSE))) -> Isan Carlo Lazaro | H24: ISAN CARLO LAZARO | I24: =IFERROR(VLOOKUP(A24,[4]C1!$E:$L,8,FALSE),IFERROR(VLOOKUP(A24,[5]C1!$E:$L,8,FALSE),VLOOKUP(A24,[6]C1!$E:$L,8,FALSE))) -> CHALLENGER | K24: 45736 | L24: ECI | M24: CSB | N24: =YEAR(IFERROR(VLOOKUP(A24,[4]C1!$E:$AA,23,FALSE),IFERROR(VLOOKUP(A24,[5]C1!$E:$AB,24,FALSE),VLOOKUP(A24,[6]C1!$E:$AB,23,FALSE)))) -> 2025 | O24: 45750 | P24: =IF(ISBLANK(O24),"NO","YES") -> YES | Q24: 45770 | R24: NO BACKJOB | S24: 4 | T24: =IFERROR(VLOOKUP(A24,[4]C1!$E:$BH,56,FALSE),IFERROR(VLOOKUP(A24,[5]C1!$E:$BI,57,FALSE),VLOOKUP(A24,[6]C1!$E:$BI,56,FALSE))) -> 45709
A25: X23083142769 | B25: 'X23083142769', | C25: =IFERROR(VLOOKUP(A25,[1]C1!$E:$F,2,FALSE),IFERROR(VLOOKUP(A25,[2]C1!$E:$F,2,FALSE),VLOOKUP(A25,[3]C1!$E:$F,2,FALSE))) -> CHRISTOPHER SANTIAGO | D25: =IFERROR(VLOOKUP(A25,[3]C1!$E:$G,3,FALSE),IFERROR(VLOOKUP(A25,[2]C1!$E:$G,3,FALSE),VLOOKUP(A25,[1]C1!$E:$G,3,FALSE))) -> TANAUAN, AYALA-ALABANG VILL, MUNTINLUPA | E25: =IFERROR(VLOOKUP(A25,[4]C1!$E:$S,15,FALSE),IFERROR(VLOOKUP(A25,[5]C1!$E:$T,16,FALSE),VLOOKUP(A25,[6]C1!$E:$T,16,FALSE))) -> 69069.98 | F25: 115.77 | G25: =IFERROR(VLOOKUP(A25,[4]C1!$E:$N,10,FALSE),IFERROR(VLOOKUP(A25,[5]C1!$E:$N,10,FALSE),VLOOKUP(A25,[6]C1!$E:$N,10,FALSE))) -> EAO | H25: ISAN CARLO LAZARO | I25: =IFERROR(VLOOKUP(A25,[4]C1!$E:$L,8,FALSE),IFERROR(VLOOKUP(A25,[5]C1!$E:$L,8,FALSE),VLOOKUP(A25,[6]C1!$E:$L,8,FALSE))) -> CHALLENGER | K25: 45736 | L25: AGD | M25: CSB | N25: =YEAR(IFERROR(VLOOKUP(A25,[4]C1!$E:$AA,23,FALSE),IFERROR(VLOOKUP(A25,[5]C1!$E:$AB,24,FALSE),VLOOKUP(A25,[6]C1!$E:$AB,23,FALSE)))) -> 2023 | O25: 45777 | P25: =IF(ISBLANK(O25),"NO","YES") -> YES | Q25: 45855 | R25: NO BACKJOB | S25: 5 | T25: =IFERROR(VLOOKUP(A25,[4]C1!$E:$BH,56,FALSE),IFERROR(VLOOKUP(A25,[5]C1!$E:$BI,57,FALSE),VLOOKUP(A25,[6]C1!$E:$BI,56,FALSE))) -> 45379
A26: X22041849543 | B26: 'X22041849543', | C26: =IFERROR(VLOOKUP(A26,[1]C1!$E:$F,2,FALSE),IFERROR(VLOOKUP(A26,[2]C1!$E:$F,2,FALSE),VLOOKUP(A26,[3]C1!$E:$F,2,FALSE))) -> DITO TELECOMMUNITY CORPORATION | D26: =IFERROR(VLOOKUP(A26,[3]C1!$E:$G,3,FALSE),IFERROR(VLOOKUP(A26,[2]C1!$E:$G,3,FALSE),VLOOKUP(A26,[1]C1!$E:$G,3,FALSE))) -> COL. E. DE LEON, STO. NINO, PARANAQUE | E26: =IFERROR(VLOOKUP(A26,[4]C1!$E:$S,15,FALSE),IFERROR(VLOOKUP(A26,[5]C1!$E:$T,16,FALSE),VLOOKUP(A26,[6]C1!$E:$T,16,FALSE))) -> 347662.79 | F26: 76.82 | G26: =IFERROR(VLOOKUP(A26,[4]C1!$E:$N,10,FALSE),IFERROR(VLOOKUP(A26,[5]C1!$E:$N,10,FALSE),VLOOKUP(A26,[6]C1!$E:$N,10,FALSE))) -> RRG | H26: RONILO JR GANGE | I26: =IFERROR(VLOOKUP(A26,[4]C1!$E:$L,8,FALSE),IFERROR(VLOOKUP(A26,[5]C1!$E:$L,8,FALSE),VLOOKUP(A26,[6]C1!$E:$L,8,FALSE))) -> ECOM | K26: 45736 | L26: ECI | M26: CSB | N26: =YEAR(IFERROR(VLOOKUP(A26,[4]C1!$E:$AA,23,FALSE),IFERROR(VLOOKUP(A26,[5]C1!$E:$AB,24,FALSE),VLOOKUP(A26,[6]C1!$E:$AB,23,FALSE)))) -> 2023 | P26: =IF(ISBLANK(O26),"NO","YES") -> NO | S26: 4 | T26: =IFERROR(VLOOKUP(A26,[4]C1!$E:$BH,56,FALSE),IFERROR(VLOOKUP(A26,[5]C1!$E:$BI,57,FALSE),VLOOKUP(A26,[6]C1!$E:$BI,56,FALSE))) -> 45372
A27: X23062242918 | B27: 'X23062242918', | C27: =IFERROR(VLOOKUP(A27,[1]C1!$E:$F,2,FALSE),IFERROR(VLOOKUP(A27,[2]C1!$E:$F,2,FALSE),VLOOKUP(A27,[3]C1!$E:$F,2,FALSE))) -> GEORGIE VELASCO SAMONTE | D27: =IFERROR(VLOOKUP(A27,[3]C1!$E:$G,3,FALSE),IFERROR(VLOOKUP(A27,[2]C1!$E:$G,3,FALSE),VLOOKUP(A27,[1]C1!$E:$G,3,FALSE))) -> BLOCK 47 ST, GEORGETOWN HEIGHTS SUBD PH II, BACOOR | E27: =IFERROR(VLOOKUP(A27,[4]C1!$E:$S,15,FALSE),IFERROR(VLOOKUP(A27,[5]C1!$E:$T,16,FALSE),VLOOKUP(A27,[6]C1!$E:$T,16,FALSE))) -> 35997.05 | F27: 19.6 | G27: =IFERROR(VLOOKUP(A27,[4]C1!$E:$N,10,FALSE),IFERROR(VLOOKUP(A27,[5]C1!$E:$N,10,FALSE),VLOOKUP(A27,[6]C1!$E:$N,10,FALSE))) -> EAO | H27: RONILO JR GANGE | I27: =IFERROR(VLOOKUP(A27,[4]C1!$E:$L,8,FALSE),IFERROR(VLOOKUP(A27,[5]C1!$E:$L,8,FALSE),VLOOKUP(A27,[6]C1!$E:$L,8,FALSE))) -> AVECO | K27: 45736 | L27: AGD | M27: CSB | N27: =YEAR(IFERROR(VLOOKUP(A27,[4]C1!$E:$AA,23,FALSE),IFERROR(VLOOKUP(A27,[5]C1!$E:$AB,24,FALSE),VLOOKUP(A27,[6]C1!$E:$AB,23,FALSE)))) -> 2023 | O27: 45756 | P27: =IF(ISBLANK(O27),"NO","YES") -> YES | Q27: 45855 | R27: NO BACKJOB | S27: 4 | T27: =IFERROR(VLOOKUP(A27,[4]C1!$E:$BH,56,FALSE),IFERROR(VLOOKUP(A27,[5]C1!$E:$BI,57,FALSE),VLOOKUP(A27,[6]C1!$E:$BI,56,FALSE))) -> 45497
A28: R22553542 | B28: 'R22553542', | C28: =IFERROR(VLOOKUP(A28,[1]C1!$E:$F,2,FALSE),IFERROR(VLOOKUP(A28,[2]C1!$E:$F,2,FALSE),VLOOKUP(A28,[3]C1!$E:$F,2,FALSE))) -> BASCUGUIN BUENA MONTES, | D28: =IFERROR(VLOOKUP(A28,[3]C1!$E:$G,3,FALSE),IFERROR(VLOOKUP(A28,[2]C1!$E:$G,3,FALSE),VLOOKUP(A28,[1]C1!$E:$G,3,FALSE))) -> KALAYAAN VILL/BALAGBAG, KALAYAAN VILL/BALAGBAG, PASAY CITY | E28: =IFERROR(VLOOKUP(A28,[4]C1!$E:$S,15,FALSE),IFERROR(VLOOKUP(A28,[5]C1!$E:$T,16,FALSE),VLOOKUP(A28,[6]C1!$E:$T,16,FALSE))) -> 210433.39 | F28: 94.97 | G28: =IFERROR(VLOOKUP(A28,[4]C1!$E:$N,10,FALSE),IFERROR(VLOOKUP(A28,[5]C1!$E:$N,10,FALSE),VLOOKUP(A28,[6]C1!$E:$N,10,FALSE))) -> RRG | H28: RONILO JR GANGE | I28: =IFERROR(VLOOKUP(A28,[4]C1!$E:$L,8,FALSE),IFERROR(VLOOKUP(A28,[5]C1!$E:$L,8,FALSE),VLOOKUP(A28,[6]C1!$E:$L,8,FALSE))) -> ECOM | K28: 45736 | L28: ECI | M28: CSB | N28: =YEAR(IFERROR(VLOOKUP(A28,[4]C1!$E:$AA,23,FALSE),IFERROR(VLOOKUP(A28,[5]C1!$E:$AB,24,FALSE),VLOOKUP(A28,[6]C1!$E:$AB,23,FALSE)))) -> 2024 | P28: =IF(ISBLANK(O28),"NO","YES") -> NO | S28: 2 | T28: =IFERROR(VLOOKUP(A28,[4]C1!$E:$BH,56,FALSE),IFERROR(VLOOKUP(A28,[5]C1!$E:$BI,57,FALSE),VLOOKUP(A28,[6]C1!$E:$BI,56,FALSE))) -> 45372
A29: R23067764 | B29: 'R23067764', | C29: =IFERROR(VLOOKUP(A29,[1]C1!$E:$F,2,FALSE),IFERROR(VLOOKUP(A29,[2]C1!$E:$F,2,FALSE),VLOOKUP(A29,[3]C1!$E:$F,2,FALSE))) -> F & E DE CASTRO CORPORATION,, HMB | D29: =IFERROR(VLOOKUP(A29,[3]C1!$E:$G,3,FALSE),IFERROR(VLOOKUP(A29,[2]C1!$E:$G,3,FALSE),VLOOKUP(A29,[1]C1!$E:$G,3,FALSE))) -> BLOCK 19, GEORGETOWN HEIGHTS SUBD PH I, BACOOR | E29: =IFERROR(VLOOKUP(A29,[4]C1!$E:$S,15,FALSE),IFERROR(VLOOKUP(A29,[5]C1!$E:$T,16,FALSE),VLOOKUP(A29,[6]C1!$E:$T,16,FALSE))) -> 153228.84 | F29: 51.02 | G29: =IFERROR(VLOOKUP(A29,[4]C1!$E:$N,10,FALSE),IFERROR(VLOOKUP(A29,[5]C1!$E:$N,10,FALSE),VLOOKUP(A29,[6]C1!$E:$N,10,FALSE))) -> RRG | H29: RONILO JR GANGE | I29: =IFERROR(VLOOKUP(A29,[4]C1!$E:$L,8,FALSE),IFERROR(VLOOKUP(A29,[5]C1!$E:$L,8,FALSE),VLOOKUP(A29,[6]C1!$E:$L,8,FALSE))) -> ECOM | K29: 45736 | L29: AGD | M29: CSB | N29: =YEAR(IFERROR(VLOOKUP(A29,[4]C1!$E:$AA,23,FALSE),IFERROR(VLOOKUP(A29,[5]C1!$E:$AB,24,FALSE),VLOOKUP(A29,[6]C1!$E:$AB,23,FALSE)))) -> 2024 | O29: 45756 | P29: =IF(ISBLANK(O29),"NO","YES") -> YES | Q29: 45855 | R29: NO BACKJOB | S29: 2 | T29: =IFERROR(VLOOKUP(A29,[4]C1!$E:$BH,56,FALSE),IFERROR(VLOOKUP(A29,[5]C1!$E:$BI,57,FALSE),VLOOKUP(A29,[6]C1!$E:$BI,56,FALSE))) -> 45372
A30: R21257785 | B30: 'R21257785', | C30: =IFERROR(VLOOKUP(A30,[1]C1!$E:$F,2,FALSE),IFERROR(VLOOKUP(A30,[2]C1!$E:$F,2,FALSE),VLOOKUP(A30,[3]C1!$E:$F,2,FALSE))) -> GO JEREMY LESTER TEE TEN | D30: =IFERROR(VLOOKUP(A30,[3]C1!$E:$G,3,FALSE),IFERROR(VLOOKUP(A30,[2]C1!$E:$G,3,FALSE),VLOOKUP(A30,[1]C1!$E:$G,3,FALSE))) -> BAYANAN, BAYANAN, BACOOR | E30: =IFERROR(VLOOKUP(A30,[4]C1!$E:$S,15,FALSE),IFERROR(VLOOKUP(A30,[5]C1!$E:$T,16,FALSE),VLOOKUP(A30,[6]C1!$E:$T,16,FALSE))) -> 446398.79 | F30: 225.67 | G30: =IFERROR(VLOOKUP(A30,[4]C1!$E:$N,10,FALSE),IFERROR(VLOOKUP(A30,[5]C1!$E:$N,10,FALSE),VLOOKUP(A30,[6]C1!$E:$N,10,FALSE))) -> IJP | H30: IAN PATRICK PEREZ | I30: =IFERROR(VLOOKUP(A30,[4]C1!$E:$L,8,FALSE),IFERROR(VLOOKUP(A30,[5]C1!$E:$L,8,FALSE),VLOOKUP(A30,[6]C1!$E:$L,8,FALSE))) -> AVECO | K30: 45736 | L30: ECI | M30: CSB | N30: =YEAR(IFERROR(VLOOKUP(A30,[4]C1!$E:$AA,23,FALSE),IFERROR(VLOOKUP(A30,[5]C1!$E:$AB,24,FALSE),VLOOKUP(A30,[6]C1!$E:$AB,23,FALSE)))) -> 2022 | P30: =IF(ISBLANK(O30),"NO","YES") -> NO | S30: 6 | T30: =IFERROR(VLOOKUP(A30,[4]C1!$E:$BH,56,FALSE),IFERROR(VLOOKUP(A30,[5]C1!$E:$BI,57,FALSE),VLOOKUP(A30,[6]C1!$E:$BI,56,FALSE))) -> 45097
A31: X23072902617 | B31: 'X23072902617', | C31: =IFERROR(VLOOKUP(A31,[1]C1!$E:$F,2,FALSE),IFERROR(VLOOKUP(A31,[2]C1!$E:$F,2,FALSE),VLOOKUP(A31,[3]C1!$E:$F,2,FALSE))) -> LIGHT RAIL MANILA CORPORATION (REDEMPTORIST STATION) | D31: =IFERROR(VLOOKUP(A31,[3]C1!$E:$G,3,FALSE),IFERROR(VLOOKUP(A31,[2]C1!$E:$G,3,FALSE),VLOOKUP(A31,[1]C1!$E:$G,3,FALSE))) -> PRES. M. ROXAS, BACLARAN, PARANAQUE | E31: =IFERROR(VLOOKUP(A31,[4]C1!$E:$S,15,FALSE),IFERROR(VLOOKUP(A31,[5]C1!$E:$T,16,FALSE),VLOOKUP(A31,[6]C1!$E:$T,16,FALSE))) -> 539841.81 | F31: 300.3 | G31: =IFERROR(VLOOKUP(A31,[4]C1!$E:$N,10,FALSE),IFERROR(VLOOKUP(A31,[5]C1!$E:$N,10,FALSE),VLOOKUP(A31,[6]C1!$E:$N,10,FALSE))) -> IJP | H31: IAN PATRICK PEREZ | I31: =IFERROR(VLOOKUP(A31,[4]C1!$E:$L,8,FALSE),IFERROR(VLOOKUP(A31,[5]C1!$E:$L,8,FALSE),VLOOKUP(A31,[6]C1!$E:$L,8,FALSE))) -> CHALLENGER | K31: 45736 | L31: AGD | M31: CSB | N31: =YEAR(IFERROR(VLOOKUP(A31,[4]C1!$E:$AA,23,FALSE),IFERROR(VLOOKUP(A31,[5]C1!$E:$AB,24,FALSE),VLOOKUP(A31,[6]C1!$E:$AB,23,FALSE)))) -> 2023 | O31: 45769 | P31: =IF(ISBLANK(O31),"NO","YES") -> YES | R31: WITH BACKJOB | S31: 5 | T31: =IFERROR(VLOOKUP(A31,[4]C1!$E:$BH,56,FALSE),IFERROR(VLOOKUP(A31,[5]C1!$E:$BI,57,FALSE),VLOOKUP(A31,[6]C1!$E:$BI,56,FALSE))) -> 45379
A32: R22837793 | B32: 'R22837793', | C32: =IFERROR(VLOOKUP(A32,[1]C1!$E:$F,2,FALSE),IFERROR(VLOOKUP(A32,[2]C1!$E:$F,2,FALSE),VLOOKUP(A32,[3]C1!$E:$F,2,FALSE))) -> LUI, CHAD ALFRED SO, HMB | D32: =IFERROR(VLOOKUP(A32,[3]C1!$E:$G,3,FALSE),IFERROR(VLOOKUP(A32,[2]C1!$E:$G,3,FALSE),VLOOKUP(A32,[1]C1!$E:$G,3,FALSE))) -> BLK 6, PALM COAST MARINA, PARANAQUE | E32: =IFERROR(VLOOKUP(A32,[4]C1!$E:$S,15,FALSE),IFERROR(VLOOKUP(A32,[5]C1!$E:$T,16,FALSE),VLOOKUP(A32,[6]C1!$E:$T,16,FALSE))) -> 544752.43 | F32: 271.47 | G32: =IFERROR(VLOOKUP(A32,[4]C1!$E:$N,10,FALSE),IFERROR(VLOOKUP(A32,[5]C1!$E:$N,10,FALSE),VLOOKUP(A32,[6]C1!$E:$N,10,FALSE))) -> JSB | H32: JASPER BASTASA | I32: =IFERROR(VLOOKUP(A32,[4]C1!$E:$L,8,FALSE),IFERROR(VLOOKUP(A32,[5]C1!$E:$L,8,FALSE),VLOOKUP(A32,[6]C1!$E:$L,8,FALSE))) -> VJC | K32: 45736 | L32: ECI | M32: CSB | N32: =YEAR(IFERROR(VLOOKUP(A32,[4]C1!$E:$AA,23,FALSE),IFERROR(VLOOKUP(A32,[5]C1!$E:$AB,24,FALSE),VLOOKUP(A32,[6]C1!$E:$AB,23,FALSE)))) -> 2024 | P32: =IF(ISBLANK(O32),"NO","YES") -> NO | S32: 8 | T32: =IFERROR(VLOOKUP(A32,[4]C1!$E:$BH,56,FALSE),IFERROR(VLOOKUP(A32,[5]C1!$E:$BI,57,FALSE),VLOOKUP(A32,[6]C1!$E:$BI,56,FALSE))) -> 45584
A33: X24072668324 | B33: 'X24072668324', | C33: =IFERROR(VLOOKUP(A33,[1]C1!$E:$F,2,FALSE),IFERROR(VLOOKUP(A33,[2]C1!$E:$F,2,FALSE),VLOOKUP(A33,[3]C1!$E:$F,2,FALSE))) -> FODC-FIRST ORIENT DEVELOPMENT AND CONSTRUCTION COR | D33: =IFERROR(VLOOKUP(A33,[3]C1!$E:$G,3,FALSE),IFERROR(VLOOKUP(A33,[2]C1!$E:$G,3,FALSE),VLOOKUP(A33,[1]C1!$E:$G,3,FALSE))) -> PRES. M. ROXAS, TAMBO, PARANAQUE | E33: =IFERROR(VLOOKUP(A33,[4]C1!$E:$S,15,FALSE),IFERROR(VLOOKUP(A33,[5]C1!$E:$T,16,FALSE),VLOOKUP(A33,[6]C1!$E:$T,16,FALSE))) -> 35822.77 | F33: 52.63 | G33: =IFERROR(VLOOKUP(A33,[4]C1!$E:$N,10,FALSE),IFERROR(VLOOKUP(A33,[5]C1!$E:$N,10,FALSE),VLOOKUP(A33,[6]C1!$E:$N,10,FALSE))) -> JSB | H33: JASPER BASTASA | I33: =IFERROR(VLOOKUP(A33,[4]C1!$E:$L,8,FALSE),IFERROR(VLOOKUP(A33,[5]C1!$E:$L,8,FALSE),VLOOKUP(A33,[6]C1!$E:$L,8,FALSE))) -> VJC | K33: 45736 | L33: AGD | M33: CSB | N33: =YEAR(IFERROR(VLOOKUP(A33,[4]C1!$E:$AA,23,FALSE),IFERROR(VLOOKUP(A33,[5]C1!$E:$AB,24,FALSE),VLOOKUP(A33,[6]C1!$E:$AB,23,FALSE)))) -> 2024 | O33: 45769 | P33: =IF(ISBLANK(O33),"NO","YES") -> YES | Q33: 45847 | R33: NO BACKJOB | S33: 2 | T33: =IFERROR(VLOOKUP(A33,[4]C1!$E:$BH,56,FALSE),IFERROR(VLOOKUP(A33,[5]C1!$E:$BI,57,FALSE),VLOOKUP(A33,[6]C1!$E:$BI,56,FALSE))) -> 45556
A34: X21115170333 | B34: 'X21115170333', | C34: =IFERROR(VLOOKUP(A34,[1]C1!$E:$F,2,FALSE),IFERROR(VLOOKUP(A34,[2]C1!$E:$F,2,FALSE),VLOOKUP(A34,[3]C1!$E:$F,2,FALSE))) -> JOSE AGUSTO GUSTILO QUIMPO | D34: =IFERROR(VLOOKUP(A34,[3]C1!$E:$G,3,FALSE),IFERROR(VLOOKUP(A34,[2]C1!$E:$G,3,FALSE),VLOOKUP(A34,[1]C1!$E:$G,3,FALSE))) -> ST. JOSEPH, SAN JOSE SUBD, MUNTINLUPA | E34: =IFERROR(VLOOKUP(A34,[4]C1!$E:$S,15,FALSE),IFERROR(VLOOKUP(A34,[5]C1!$E:$T,16,FALSE),VLOOKUP(A34,[6]C1!$E:$T,16,FALSE))) -> 535717.03 | F34: 238.85 | G34: =IFERROR(VLOOKUP(A34,[4]C1!$E:$N,10,FALSE),IFERROR(VLOOKUP(A34,[5]C1!$E:$N,10,FALSE),VLOOKUP(A34,[6]C1!$E:$N,10,FALSE))) -> FMS | H34: FRANCIS MARC SANTOS | I34: =IFERROR(VLOOKUP(A34,[4]C1!$E:$L,8,FALSE),IFERROR(VLOOKUP(A34,[5]C1!$E:$L,8,FALSE),VLOOKUP(A34,[6]C1!$E:$L,8,FALSE))) -> POWERHOUSE | K34: 45736 | L34: ECI | M34: CSB | N34: =YEAR(IFERROR(VLOOKUP(A34,[4]C1!$E:$AA,23,FALSE),IFERROR(VLOOKUP(A34,[5]C1!$E:$AB,24,FALSE),VLOOKUP(A34,[6]C1!$E:$AB,23,FALSE)))) -> 2022 | O34: 45750 | P34: =IF(ISBLANK(O34),"NO","YES") -> YES | Q34: 45840 | R34: WITH BACKJOB | S34: 8 | T34: =IFERROR(VLOOKUP(A34,[4]C1!$E:$BH,56,FALSE),IFERROR(VLOOKUP(A34,[5]C1!$E:$BI,57,FALSE),VLOOKUP(A34,[6]C1!$E:$BI,56,FALSE))) -> 45476
A35: X24072541358 | B35: 'X24072541358', | C35: =IFERROR(VLOOKUP(A35,[1]C1!$E:$F,2,FALSE),IFERROR(VLOOKUP(A35,[2]C1!$E:$F,2,FALSE),VLOOKUP(A35,[3]C1!$E:$F,2,FALSE))) -> WILHOME DEVELOPMENT INC. | D35: =IFERROR(VLOOKUP(A35,[3]C1!$E:$G,3,FALSE),IFERROR(VLOOKUP(A35,[2]C1!$E:$G,3,FALSE),VLOOKUP(A35,[1]C1!$E:$G,3,FALSE))) -> MOLINO ROAD, MOLINO III, BACOOR | E35: =IFERROR(VLOOKUP(A35,[4]C1!$E:$S,15,FALSE),IFERROR(VLOOKUP(A35,[5]C1!$E:$T,16,FALSE),VLOOKUP(A35,[6]C1!$E:$T,15,FALSE))) -> 833293.59 | F35: 144.6 | G35: =IFERROR(VLOOKUP(A35,[4]C1!$E:$N,10,FALSE),IFERROR(VLOOKUP(A35,[5]C1!$E:$N,10,FALSE),VLOOKUP(A35,[6]C1!$E:$N,10,FALSE))) -> Jenneth Madrid | I35: =IFERROR(VLOOKUP(A35,[4]C1!$E:$L,8,FALSE),IFERROR(VLOOKUP(A35,[5]C1!$E:$L,8,FALSE),VLOOKUP(A35,[6]C1!$E:$L,8,FALSE))) -> POWERHOUSE | L35: AGD | N35: =YEAR(IFERROR(VLOOKUP(A35,[4]C1!$E:$AA,23,FALSE),IFERROR(VLOOKUP(A35,[5]C1!$E:$AB,24,FALSE),VLOOKUP(A35,[6]C1!$E:$AB,23,FALSE)))) -> 2025 | O35: 45776 | P35: =IF(ISBLANK(O35),"NO","YES") -> YES | Q35: 45792 | R35: NO BACKJOB | S35: 3 | T35: =IFERROR(VLOOKUP(A35,[4]C1!$E:$BH,56,FALSE),IFERROR(VLOOKUP(A35,[5]C1!$E:$BI,57,FALSE),VLOOKUP(A35,[6]C1!$E:$BI,56,FALSE))) -> 45706
A36: X24051934516 | B36: 'X24051934516', | C36: =IFERROR(VLOOKUP(A36,[1]C1!$E:$F,2,FALSE),IFERROR(VLOOKUP(A36,[2]C1!$E:$F,2,FALSE),VLOOKUP(A36,[3]C1!$E:$F,2,FALSE))) -> EPICUREAN PARTNERS EXCHANGE INC. | D36: =IFERROR(VLOOKUP(A36,[3]C1!$E:$G,3,FALSE),IFERROR(VLOOKUP(A36,[2]C1!$E:$G,3,FALSE),VLOOKUP(A36,[1]C1!$E:$G,3,FALSE))) -> NATIONAL, TUNASAN, MUNTINLUPA | E36: =IFERROR(VLOOKUP(A36,[4]C1!$E:$S,15,FALSE),IFERROR(VLOOKUP(A36,[5]C1!$E:$T,16,FALSE),VLOOKUP(A36,[6]C1!$E:$T,16,FALSE))) -> 828221.87 | F36: 146.17 | G36: =IFERROR(VLOOKUP(A36,[4]C1!$E:$N,10,FALSE),IFERROR(VLOOKUP(A36,[5]C1!$E:$N,10,FALSE),VLOOKUP(A36,[6]C1!$E:$N,10,FALSE))) -> JSP | H36: JEMUEL PERALTA | I36: =IFERROR(VLOOKUP(A36,[4]C1!$E:$L,8,FALSE),IFERROR(VLOOKUP(A36,[5]C1!$E:$L,8,FALSE),VLOOKUP(A36,[6]C1!$E:$L,8,FALSE))) -> CHALLENGER | K36: 45736 | L36: RAC | M36: NVP | N36: =YEAR(IFERROR(VLOOKUP(A36,[4]C1!$E:$AA,23,FALSE),IFERROR(VLOOKUP(A36,[5]C1!$E:$AB,24,FALSE),VLOOKUP(A36,[6]C1!$E:$AB,23,FALSE)))) -> 2024 | O36: 45743 | P36: =IF(ISBLANK(O36),"NO","YES") -> YES | Q36: 45755 | R36: WITH BACKJOB | S36: 3 | T36: =IFERROR(VLOOKUP(A36,[4]C1!$E:$BH,56,FALSE),IFERROR(VLOOKUP(A36,[5]C1!$E:$BI,57,FALSE),VLOOKUP(A36,[6]C1!$E:$BI,56,FALSE))) -> 45665
A37: X24041088653 | B37: 'X24041088653', | C37: =IFERROR(VLOOKUP(A37,[1]C1!$E:$F,2,FALSE),IFERROR(VLOOKUP(A37,[2]C1!$E:$F,2,FALSE),VLOOKUP(A37,[3]C1!$E:$F,2,FALSE))) -> GABRIEL AGUILA REYES | D37: =IFERROR(VLOOKUP(A37,[3]C1!$E:$G,3,FALSE),IFERROR(VLOOKUP(A37,[2]C1!$E:$G,3,FALSE),VLOOKUP(A37,[1]C1!$E:$G,3,FALSE))) -> BLOCK 10, BRAZILIA HEIGHTS, MUNTINLUPA | E37: =IFERROR(VLOOKUP(A37,[4]C1!$E:$S,15,FALSE),IFERROR(VLOOKUP(A37,[5]C1!$E:$T,16,FALSE),VLOOKUP(A37,[6]C1!$E:$T,16,FALSE))) -> 1365333.4 | F37: 493.75 | G37: =IFERROR(VLOOKUP(A37,[4]C1!$E:$N,10,FALSE),IFERROR(VLOOKUP(A37,[5]C1!$E:$N,10,FALSE),VLOOKUP(A37,[6]C1!$E:$N,10,FALSE))) -> JSP | H37: JEMUEL PERALTA | I37: =IFERROR(VLOOKUP(A37,[4]C1!$E:$L,8,FALSE),IFERROR(VLOOKUP(A37,[5]C1!$E:$L,8,FALSE),VLOOKUP(A37,[6]C1!$E:$L,8,FALSE))) -> CHALLENGER | K37: 45736 | L37: RAC | M37: NVP | N37: =YEAR(IFERROR(VLOOKUP(A37,[4]C1!$E:$AA,23,FALSE),IFERROR(VLOOKUP(A37,[5]C1!$E:$AB,24,FALSE),VLOOKUP(A37,[6]C1!$E:$AB,23,FALSE)))) -> 2024 | O37: 45775 | P37: =IF(ISBLANK(O37),"NO","YES") -> YES | Q37: 45791 | R37: WITH BACKJOB | S37: 18 | T37: =IFERROR(VLOOKUP(A37,[4]C1!$E:$BH,56,FALSE),IFERROR(VLOOKUP(A37,[5]C1!$E:$BI,57,FALSE),VLOOKUP(A37,[6]C1!$E:$BI,56,FALSE))) -> 45706
A38: X23093726087 | B38: 'X23093726087', | C38: =IFERROR(VLOOKUP(A38,[1]C1!$E:$F,2,FALSE),IFERROR(VLOOKUP(A38,[2]C1!$E:$F,2,FALSE),VLOOKUP(A38,[3]C1!$E:$F,2,FALSE))) -> CITY GOV'T OF LAS PIÑAS | D38: =IFERROR(VLOOKUP(A38,[3]C1!$E:$G,3,FALSE),IFERROR(VLOOKUP(A38,[2]C1!$E:$G,3,FALSE),VLOOKUP(A38,[1]C1!$E:$G,3,FALSE))) -> C5 EXTENSION, PULANGLUPA I, LAS PINAS CITY | E38: =IFERROR(VLOOKUP(A38,[4]C1!$E:$S,15,FALSE),IFERROR(VLOOKUP(A38,[5]C1!$E:$T,16,FALSE),VLOOKUP(A38,[6]C1!$E:$T,16,FALSE))) -> 2921763.9 | F38: 1039.42 | G38: =IFERROR(VLOOKUP(A38,[4]C1!$E:$N,10,FALSE),IFERROR(VLOOKUP(A38,[5]C1!$E:$N,10,FALSE),VLOOKUP(A38,[6]C1!$E:$N,10,FALSE))) -> JSP | H38: JEMUEL PERALTA | I38: =IFERROR(VLOOKUP(A38,[4]C1!$E:$L,8,FALSE),IFERROR(VLOOKUP(A38,[5]C1!$E:$L,8,FALSE),VLOOKUP(A38,[6]C1!$E:$L,8,FALSE))) -> CHALLENGER | K38: 45736 | L38: RAC | M38: NVP | N38: =YEAR(IFERROR(VLOOKUP(A38,[4]C1!$E:$AA,23,FALSE),IFERROR(VLOOKUP(A38,[5]C1!$E:$AB,24,FALSE),VLOOKUP(A38,[6]C1!$E:$AB,23,FALSE)))) -> 2024 | O38: 45742 | P38: =IF(ISBLANK(O38),"NO","YES") -> YES | Q38: 45771 | R38: WITH BACKJOB | S38: 26 | T38: =IFERROR(VLOOKUP(A38,[4]C1!$E:$BH,56,FALSE),IFERROR(VLOOKUP(A38,[5]C1!$E:$BI,57,FALSE),VLOOKUP(A38,[6]C1!$E:$BI,56,FALSE))) -> 45706
A39: X23124803010 | B39: 'X23124803010', | C39: =IFERROR(VLOOKUP(A39,[1]C1!$E:$F,2,FALSE),IFERROR(VLOOKUP(A39,[2]C1!$E:$F,2,FALSE),VLOOKUP(A39,[3]C1!$E:$F,2,FALSE))) -> MUBG REALTY CORP. | D39: =IFERROR(VLOOKUP(A39,[3]C1!$E:$G,3,FALSE),IFERROR(VLOOKUP(A39,[2]C1!$E:$G,3,FALSE),VLOOKUP(A39,[1]C1!$E:$G,3,FALSE))) -> QUIRINO, BACLARAN, PARANAQUE | E39: =IFERROR(VLOOKUP(A39,[4]C1!$E:$S,15,FALSE),IFERROR(VLOOKUP(A39,[5]C1!$E:$T,16,FALSE),VLOOKUP(A39,[6]C1!$E:$T,16,FALSE))) -> 639194.32 | F39: 79.55 | G39: =IFERROR(VLOOKUP(A39,[4]C1!$E:$N,10,FALSE),IFERROR(VLOOKUP(A39,[5]C1!$E:$N,10,FALSE),VLOOKUP(A39,[6]C1!$E:$N,10,FALSE))) -> JSP | H39: JEMUEL PERALTA | I39: =IFERROR(VLOOKUP(A39,[4]C1!$E:$L,8,FALSE),IFERROR(VLOOKUP(A39,[5]C1!$E:$L,8,FALSE),VLOOKUP(A39,[6]C1!$E:$L,8,FALSE))) -> CHALLENGER | J39: 45736 | K39: 45736 | L39: RAC | M39: NVP | N39: =YEAR(IFERROR(VLOOKUP(A39,[4]C1!$E:$AA,23,FALSE),IFERROR(VLOOKUP(A39,[5]C1!$E:$AB,24,FALSE),VLOOKUP(A39,[6]C1!$E:$AB,23,FALSE)))) -> 2024 | O39: 45792 | P39: =IF(ISBLANK(O39),"NO","YES") -> YES | Q39: 45817 | R39: NO BACKJOB | S39: 3 | T39: =IFERROR(VLOOKUP(A39,[4]C1!$E:$BH,56,FALSE),IFERROR(VLOOKUP(A39,[5]C1!$E:$BI,57,FALSE),VLOOKUP(A39,[6]C1!$E:$BI,56,FALSE))) -> 45733
A40: X24114405667 | B40: 'X24114405667', | C40: =IFERROR(VLOOKUP(A40,[1]C1!$E:$F,2,FALSE),IFERROR(VLOOKUP(A40,[2]C1!$E:$F,2,FALSE),VLOOKUP(A40,[3]C1!$E:$F,2,FALSE))) -> GREENKRAFT CORPORATION | D40: =IFERROR(VLOOKUP(A40,[3]C1!$E:$G,3,FALSE),IFERROR(VLOOKUP(A40,[2]C1!$E:$G,3,FALSE),VLOOKUP(A40,[1]C1!$E:$G,3,FALSE))) -> CHAMPACA, UNITED PQUE 4 SUBD, PARANAQUE | E40: =IFERROR(VLOOKUP(A40,[4]C1!$E:$S,15,FALSE),IFERROR(VLOOKUP(A40,[5]C1!$E:$T,16,FALSE),VLOOKUP(A40,[6]C1!$E:$T,16,FALSE))) -> 640840.51 | F40: 76.52 | G40: =IFERROR(VLOOKUP(A40,[4]C1!$E:$N,10,FALSE),IFERROR(VLOOKUP(A40,[5]C1!$E:$N,10,FALSE),VLOOKUP(A40,[6]C1!$E:$N,10,FALSE))) -> JSP | H40: JEMUEL PERALTA | I40: =IFERROR(VLOOKUP(A40,[4]C1!$E:$L,8,FALSE),IFERROR(VLOOKUP(A40,[5]C1!$E:$L,8,FALSE),VLOOKUP(A40,[6]C1!$E:$L,8,FALSE))) -> CHALLENGER | J40: 45736 | K40: 45736 | L40: RAC | M40: NVP | N40: =YEAR(IFERROR(VLOOKUP(A40,[4]C1!$E:$AA,23,FALSE),IFERROR(VLOOKUP(A40,[5]C1!$E:$AB,24,FALSE),VLOOKUP(A40,[6]C1!$E:$AB,23,FALSE)))) -> 2024 | O40: 45768 | P40: =IF(ISBLANK(O40),"NO","YES") -> YES | Q40: 45791 | R40: WITH BACKJOB | S40: 4 | T40: =IFERROR(VLOOKUP(A40,[4]C1!$E:$BH,56,FALSE),IFERROR(VLOOKUP(A40,[5]C1!$E:$BI,57,FALSE),VLOOKUP(A40,[6]C1!$E:$BI,56,FALSE))) -> 45727
...

Sheet Sheet11
A1: RAC
A2: CMR
A3: AGD
A4: ECI
A5: RPR
A6: RM
A7: NCB
A8: GTO

Sheet SUMMARY
A2: DONE AUDIT | B2: TOTAL | E2: 2022 | H2: 2023 | K2: 2024 | N2: 2025
B3: WO COUNT | C3: WO COST | D3: TOTAL MANHOURS | E3: WO COUNT | F3: WO COST | G3: TOTAL MANHOURS | H3: WO COUNT | I3: WO COST | J3: TOTAL MANHOURS | K3: WO COUNT | L3: WO COST | M3: TOTAL MANHOURS | N3: WO COUNT | O3: WO COST | P3: TOTAL MANHOURS
A4: QI | B4: =SUM(B5:B11) -> 121 | C4: =SUM(C5:C11) -> 56312164 | D4: =SUM(D5:D11) -> 26938.99 | E4: =SUM(E5:E11) -> 1 | F4: =SUM(F5:F11) -> 535717.03 | G4: =SUM(G5:G11) -> 238.85 | H4: =SUM(H5:H11) -> 17 | I4: =SUM(I5:I11) -> 6827766 | ... P4: =SUM(P5:P11) -> 1924.18
A5: AGD | B5: =SUM(E5,H5,K5,N5) -> 34 | C5: =SUM(F5,I5,L5,O5) -> 12156643 | D5: =SUM(G5,J5,M5,P5) -> 4822.98 | H5: 5 | I5: 1206324.5 | J5: 418.4 | K5: 17 | L5: 6226447.1 | M5: 3200.98 | N5: 12 | O5: 4723871.8 | P5: 1203.6
A6: CMR | B6: =SUM(E6,H6,K6,N6) -> 4 | C6: =SUM(F6,I6,L6,O6) -> 3146456 | D6: =SUM(G6,J6,M6,P6) -> 1134.7 | K6: 4 | L6: 3146456 | M6: 1134.7
A7: ECI | B7: =SUM(E7,H7,K7,N7) -> 29 | C7: =SUM(F7,I7,L7,O7) -> 10869285 | D7: =SUM(G7,J7,M7,P7) -> 8829.96 | E7: 1 | F7: 535717.03 | G7: 238.85 | H7: 2 | I7: 890709.71 | J7: 271.32 | K7: 21 | L7: 7606553.1 | M7: 7688.03 | N7: 5 | O7: 1836304.7 | P7: 631.76
A8: RAC | B8: =SUM(E8,H8,K8,N8) -> 34 | C8: =SUM(F8,I8,L8,O8) -> 20343280 | D8: =SUM(G8,J8,M8,P8) -> 6024.02 | H8: 4 | I8: 1188123.2 | J8: 587.23 | K8: 30 | L8: 19155157 | M8: 5436.79
A9: RPR | B9: =SUM(E9,H9,K9,N9) -> 6 | C9: =SUM(F9,I9,L9,O9) -> 3146574.5 | D9: =SUM(G9,J9,M9,P9) -> 1439.83 | H9: 5 | I9: 3002766.8 | J9: 1420.91 | N9: 1 | O9: 143807.71 | P9: 18.92
A10: NCB | B10: =SUM(E10,H10,K10,N10) -> 2 | C10: =SUM(F10,I10,L10,O10) -> 664963.59 | D10: =SUM(G10,J10,M10,P10) -> 129.33 | K10: 2 | L10: 664963.59 | M10: 129.33
A11: ECI/AGD | B11: =SUM(E11,H11,K11,N11) -> 12 | C11: =SUM(F11,I11,L11,O11) -> 5984961.6 | D11: =SUM(G11,J11,M11,P11) -> 4558.17 | H11: 1 | I11: 539841.81 | J11: 300.3 | K11: 10 | L11: 4979432.1 | M11: 4187.97 | N11: 1 | O11: 465687.7 | P11: 69.9
A17: DONE AUDIT | B17: TOTAL | E17: 2022 | H17: 2023 | K17: 2024 | N17: 2025
B18: WO COUNT | C18: WO COST | D18: TOTAL MANHOURS | E18: WO COUNT | F18: WO COST | G18: TOTAL MANHOURS | H18: WO COUNT | I18: WO COST | J18: TOTAL MANHOURS | K18: WO COUNT | L18: WO COST | M18: TOTAL MANHOURS | N18: WO COUNT | O18: WO COST | P18: TOTAL MANHOURS
A19: VENDOR | B19: =SUM(B20:B25) -> 121 | C19: =SUM(C20:C25) -> 56312164 | D19: =SUM(D20:D25) -> 26938.99 | E19: =SUM(E20:E25) -> 1 | F19: =SUM(F20:F25) -> 535717.03 | G19: =SUM(G20:G25) -> 238.85 | H19: =SUM(H20:H25) -> 17 | I19: =SUM(I20:I25) -> 6827766 | ... P19: =SUM(P20:P25) -> 1924.18
A20: AVECO | B20: =SUM(E20,H20,K20,N20) -> 12 | C20: =SUM(F20,I20,L20,O20) -> 4928911 | D20: =SUM(G20,J20,M20,P20) -> 1789.3 | H20: 6 | I20: 2057287.3 | J20: 892.59 | K20: 6 | L20: 2871623.7 | M20: 896.71
A21: CHALLENGER | B21: =SUM(E21,H21,K21,N21) -> 46 | C21: =SUM(F21,I21,L21,O21) -> 27571285 | D21: =SUM(G21,J21,M21,P21) -> 8466.19 | H21: 10 | I21: 4525384.9 | J21: 2037.94 | K21: 26 | L21: 19645288 | M21: 5672.81 | N21: 10 | O21: 3400612 | P21: 755.44
A22: ECOM | B22: =SUM(E22,H22,K22,N22) -> 18 | C22: =SUM(F22,I22,L22,O22) -> 7646009.3 | D22: =SUM(G22,J22,M22,P22) -> 2181.58 | K22: 17 | L22: 7180321.6 | M22: 2111.68 | N22: 1 | O22: 465687.7 | P22: 69.9
A23: POWERHOUSE | B23: =SUM(E23,H23,K23,N23) -> 14 | C23: =SUM(F23,I23,L23,O23) -> 4713274.8 | D23: =SUM(G23,J23,M23,P23) -> 1224.63 | E23: 1 | F23: 535717.03 | G23: 238.85 | H23: 1 | I23: 245093.83 | J23: 67.63 | K23: 11 | L23: 3099170.4 | M23: 773.55 | N23: 1 | O23: 833293.59 | P23: 144.6
A24: VJC | B24: =SUM(E24,H24,K24,N24) -> 30 | C24: =SUM(F24,I24,L24,O24) -> 11308876 | D24: =SUM(G24,J24,M24,P24) -> 13258.37 | K24: 24 | L24: 8982605.1 | M24: 12323.05 | N24: 6 | O24: 2326270.9 | P24: 935.32
A25: MAINTENANCE | B25: =SUM(E25,H25,K25,N25) -> 1 | C25: =SUM(F25,I25,L25,O25) -> 143807.71 | D25: =SUM(G25,J25,M25,P25) -> 18.92 | N25: 1 | O25: 143807.71 | P25: 18.92
A44: ONGOING AUDIT | B44: TOTAL | E44: 2022 | H44: 2023 | K44: 2024 | N44: 2025
B45: WO COUNT | C45: WO COST | D45: TOTAL MANHOURS | E45: WO COUNT | F45: WO COST | G45: TOTAL MANHOURS | H45: WO COUNT | I45: WO COST | J45: TOTAL MANHOURS | K45: WO COUNT | L45: WO COST | M45: TOTAL MANHOURS | N45: WO COUNT | O45: WO COST | P45: TOTAL MANHOURS
A46: QI | B46: =SUM(B47:B55) -> 69 | C46: =SUM(C47:C55) -> 45074557 | D46: =SUM(D47:D55) -> 28003.47 | E46: =SUM(E47:E55) -> 1 | F46: =SUM(F47:F55) -> 446398.79 | G46: =SUM(G47:G55) -> 225.67 | H46: =SUM(H47:H55) -> 22 | I46: =SUM(I47:I55) -> 18972677 | ... P46: =SUM(P47:P55) -> 772.43
A47: AGD | B47: =SUM(E47,H47,K47,N47) -> 18 | C47: =SUM(F47,I47,L47,O47) -> 10461768 | D47: =SUM(G47,J47,M47,P47) -> 7414.23 | H47: 8 | I47: 4668625.7 | J47: 1569 | K47: 8 | L47: 4747655.8 | M47: 5528.68 | N47: 2 | O47: 1045487 | P47: 316.55
A48: ECI | B48: =SUM(E48,H48,K48,N48) -> 25 | C48: =SUM(F48,I48,L48,O48) -> 8278643.6 | D48: =SUM(G48,J48,M48,P48) -> 9729.63 | E48: 1 | F48: 446398.79 | G48: 225.67 | H48: 4 | I48: 918306.95 | J48: 189.19 | K48: 20 | L48: 6913937.9 | M48: 9314.77
A49: RAC | B49: =SUM(E49,H49,K49,N49) -> 14 | C49: =SUM(F49,I49,L49,O49) -> 7077527 | D49: =SUM(G49,J49,M49,P49) -> 1820.16 | H49: 3 | I49: 1094540.2 | J49: 281.36 | K49: 10 | L49: 4418772.5 | M49: 1153.48 | N49: 1 | O49: 1564214.3 | P49: 385.32
A50: C/O SIR IAN | B50: =SUM(E50,H50,K50,N50) -> 2 | C50: =SUM(F50,I50,L50,O50) -> 2653941 | D50: =SUM(G50,J50,M50,P50) -> 1422.93 | H50: 2 | I50: 2653941 | J50: 1422.93
A51: C/O JGR | B51: =SUM(E51,H51,K51,N51) -> 3 | C51: =SUM(F51,I51,L51,O51) -> 2018395.3 | D51: =SUM(G51,J51,M51,P51) -> 699.95 | H51: 1 | I51: 253538.45 | J51: 80.47 | K51: 2 | L51: 1764856.8 | M51: 619.48
A52: C/O SIR JIM | B52: =SUM(E52,H52,K52,N52) -> 2 | C52: =SUM(F52,I52,L52,O52) -> 3402203 | D52: =SUM(G52,J52,M52,P52) -> 1087.99 | H52: 2 | I52: 3402203 | J52: 1087.99
A53: C/O C2 | B53: =SUM(E53,H53,K53,N53) -> 4 | C53: =SUM(F53,I53,L53,O53) -> 10708851 | D53: =SUM(G53,J53,M53,P53) -> 5692.85 | H53: 1 | I53: 5508294.5 | J53: 2860.77 | K53: 1 | L53: 5080118.2 | M53: 2761.52 | N53: 2 | O53: 120438.26 | P53: 70.56
A54: C/O C2 | B54: =SUM(E54,H54,K54,N54) -> 1 | C54: =SUM(F54,I54,L54,O54) -> 473227.53 | D54: =SUM(G54,J54,M54,P54) -> 135.73 | H54: 1 | I54: 473227.53 | J54: 135.73
A59: 1ST WEEK OF MAY ACCOMPLISHMENT (MAY 5 - 9, 2025)
A61: DONE AUDIT | B61: TOTAL | E61: 2024 | H61: 2025
B62: WO COUNT | C62: WO COST | D62: TOTAL MANHOURS | E62: WO COUNT | F62: WO COST | G62: TOTAL MANHOURS | H62: WO COUNT | I62: WO COST | J62: TOTAL MANHOURS
A63: QI | B63: =SUM(B64:B66) -> 4 | C63: =SUM(C64:C66) -> 2755826.8 | D63: =SUM(D64:D66) -> 809 | E63: =SUM(E64:E66) -> 3 | F63: =SUM(F64:F66) -> 2612019 | G63: =SUM(G64:G66) -> 790.08 | H63: =SUM(H64:H66) -> 1 | I63: =SUM(I64:I66) -> 143807.71 | J63: =SUM(J64:J66) -> 18.92
A64: AGD | B64: =SUM(E64,H64) -> 2 | C64: =SUM(F64,I64) -> 962921.27 | D64: =SUM(G64,J64) -> 237.35 | E64: 2 | F64: 962921.27 | G64: 237.35
A65: RAC | B65: =SUM(E65,H65) -> 1 | C65: =SUM(F65,I65) -> 1649097.8 | D65: =SUM(G65,J65) -> 552.73 | E65: 1 | F65: 1649097.8 | G65: 552.73
A66: RPR | B66: =SUM(E66,H66) -> 1 | C66: =SUM(F66,I66) -> 143807.71 | D66: =SUM(G66,J66) -> 18.92 | H66: 1 | I66: 143807.71 | J66: 18.92
A72: QI ACCOMPLISHMENT FOR THE MONTH OF FEBRUARY 2025
A74: DONE AUDIT | B74: TOTAL | E74: 2024
B75: WO COUNT | C75: WO COST | D75: TOTAL MANHOURS | E75: WO COUNT | F75: WO COST | G75: TOTAL MANHOURS
...

Sheet WEEKLY ACCOMPLISHMENT
A1: CONSTRUCTION 1 QI WEEKLY ACCOMPLISHMENT (JULY 28 - AUGUST 4, 2025)
A3: DONE AUDIT | B3: TOTAL | F3: 2022 | J3: 2023 | N3: 2024 | R3: 2025
B4: TASK COUNT | C4: WO COUNT | D4: MANHOURS | E4: WO COST | F4: TASK COUNT | G4: WO COUNT | H4: MANHOURS | I4: WO COST | J4: TASK COUNT | K4: WO COUNT | L4: MANHOURS | M4: WO COST | N4: TASK COUNT | O4: WO COUNT | P4: MANHOURS | Q4: WO COST | R4: TASK COUNT | S4: WO COUNT | T4: MANHOURS | U4: WO COST
A5: QI | B5: =SUM(B6:B10) -> 50 | C5: =SUM(C6:C10) -> 16 | D5: =SUM(D6:D10) -> 2114.88 | E5: =SUM(E6:E10) -> 6872084 | F5: =SUM(F6:F10) -> 9 | G5: =SUM(G6:G10) -> 1 | H5: =SUM(H6:H10) -> 209.1 | I5: =SUM(I6:I10) -> 666826.75 | ... U5: =SUM(U6:U10) -> 1455040.6
A6: AGD | B6: =SUM(F6,J6,N6,R6) -> 19 | C6: =SUM(G6,K6,O6,S6) -> 6 | D6: =SUM(H6,L6,P6,T6) -> 294.49 | E6: =SUM(I6,M6,Q6,U6) -> 1733902.9 | F6: =IF(ISBLANK(VLOOKUP(A6,'WEEKLY ACCOMPLISHMENT PIVOT'!A:B,2,FALSE)),"",VLOOKUP(A6,'WEEKLY ACCOMPLISHMENT PIVOT'!A:B,2,FALSE)) | G6: =IF(ISBLANK(VLOOKUP(A6,'WEEKLY ACCOMPLISHMENT PIVOT'!A:C,3,FALSE)),"",VLOOKUP(A6,'WEEKLY ACCOMPLISHMENT PIVOT'!A:C,3,FALSE)) | H6: =IF(ISBLANK(VLOOKUP(A6,'WEEKLY ACCOMPLISHMENT PIVOT'!A:E,5,FALSE)),"",VLOOKUP(A6,'WEEKLY ACCOMPLISHMENT PIVOT'!A:E,5,FALSE)) | I6: =IF(ISBLANK(VLOOKUP(A6,'WEEKLY ACCOMPLISHMENT PIVOT'!A:D,4,FALSE)),"",VLOOKUP(A6,'WEEKLY ACCOMPLISHMENT PIVOT'!A:D,4,FALSE)) | J6: =IF(ISBLANK(VLOOKUP(A6,'WEEKLY ACCOMPLISHMENT PIVOT'!A:F,6,FALSE)),"",VLOOKUP(A6,'WEEKLY ACCOMPLISHMENT PIVOT'!A:F,6,FALSE)) | K6: =IF(ISBLANK(VLOOKUP(A6,'WEEKLY ACCOMPLISHMENT PIVOT'!A:G,7,FALSE)),"",VLOOKUP(A6,'WEEKLY ACCOMPLISHMENT PIVOT'!A:G,7,FALSE)) | L6: =IF(ISBLANK(VLOOKUP(A6,'WEEKLY ACCOMPLISHMENT PIVOT'!A:I,9,FALSE)),"",VLOOKUP(A6,'WEEKLY ACCOMPLISHMENT PIVOT'!A:I,9,FALSE)) | M6: =IF(ISBLANK(VLOOKUP(A6,'WEEKLY ACCOMPLISHMENT PIVOT'!A:H,8,FALSE)),"",VLOOKUP(A6,'WEEKLY ACCOMPLISHMENT PIVOT'!A:H,8,FALSE)) | N6: =IF(ISBLANK(VLOOKUP(A6,'WEEKLY ACCOMPLISHMENT PIVOT'!A:J,10,FALSE)),"",VLOOKUP(A6,'WEEKLY ACCOMPLISHMENT PIVOT'!A:J,10,FALSE)) -> 6 | O6: =IF(ISBLANK(VLOOKUP(A6,'WEEKLY ACCOMPLISHMENT PIVOT'!A:K,11,FALSE)),"",VLOOKUP(A6,'WEEKLY ACCOMPLISHMENT PIVOT'!A:K,11,FALSE)) -> 2 | P6: =IF(ISBLANK(VLOOKUP(A6,'WEEKLY ACCOMPLISHMENT PIVOT'!A:M,13,FALSE)),"",VLOOKUP(A6,'WEEKLY ACCOMPLISHMENT PIVOT'!A:M,13,FALSE)) -> 57.67 | Q6: =IF(ISBLANK(VLOOKUP(A6,'WEEKLY ACCOMPLISHMENT PIVOT'!A:L,12,FALSE)),"",VLOOKUP(A6,'WEEKLY ACCOMPLISHMENT PIVOT'!A:L,12,FALSE)) -> 352606.49 | R6: =IF(ISBLANK(VLOOKUP(A6,'WEEKLY ACCOMPLISHMENT PIVOT'!A:N,14,FALSE)),"",VLOOKUP(A6,'WEEKLY ACCOMPLISHMENT PIVOT'!A:N,14,FALSE)) -> 13 | S6: =IF(ISBLANK(VLOOKUP(A6,'WEEKLY ACCOMPLISHMENT PIVOT'!A:O,15,FALSE)),"",VLOOKUP(A6,'WEEKLY ACCOMPLISHMENT PIVOT'!A:O,15,FALSE)) -> 4 | T6: =IF(ISBLANK(VLOOKUP(A6,'WEEKLY ACCOMPLISHMENT PIVOT'!A:Q,17,FALSE)),"",VLOOKUP(A6,'WEEKLY ACCOMPLISHMENT PIVOT'!A:Q,17,FALSE)) -> 236.82 | U6: =IF(ISBLANK(VLOOKUP(A6,'WEEKLY ACCOMPLISHMENT PIVOT'!A:P,16,FALSE)),"",VLOOKUP(A6,'WEEKLY ACCOMPLISHMENT PIVOT'!A:P,16,FALSE)) -> 1381296.4
