Workbook
Name at: 'C1'!#REF!

Sheet Sheet3
A1: SUPERVISOR | B1: IGL | F1: SUPERVISOR | G1: IGL
A3: Count of WO NO | B3: Column Labels | G3: Column Labels
A4: Row Labels | B4: CHALLENGER | C4: Grand Total | G4: CHALLENGER | I4: Total TOTAL ESTIMATED COST (SERVICE ITEMS) | J4: Total BILLED/PARTIALLY BILLED COST
A5: AUDITED | B5: 8 | C5: 8 | F5: Row Labels | G5: TOTAL ESTIMATED COST (SERVICE ITEMS) | H5: BILLED/PARTIALLY BILLED COST
A6: FOR AUDIT | B6: 42 | C6: 42 | F6: AUDITED | G6: 309761.23 | H6: 79479.1 | I6: 309761.23 | J6: 79479.1
A7: NO COC | B7: 18 | C7: 18 | F7: FOR AUDIT | G7: 4834813.4 | H7: 368944.03 | I7: 4834813.4 | J7: 368944.03
A8: PAID | B8: 1 | C8: 1 | F8: NO COC | G8: 1976088.5 | I8: 1976088.5
A9: Transferred to DCB (point person for OLDT) | B9: 5 | C9: 5 | F9: PAID | G9: 80751.9 | H9: 84452.5 | I9: 80751.9 | J9: 84452.5
A10: SCHED/ INPRG | B10: 39 | C10: 39 | F10: Transferred to DCB (point person for OLDT) | G10: 169350.32 | I10: 169350.32
A11: Grand Total | B11: 113 | C11: 113 | F11: SCHED/ INPRG | G11: 3937935.2 | I11: 3937935.2
F12: Grand Total | G12: 11308700 | H12: 532875.63 | I12: 11308700 | J12: 532875.63
F14: Row Labels | G14: Sum of TOTAL ESTIMATED COST (SERVICES) | H14: Sum of BILLED / PARTIALLY BILLED COST | I14: Sum of TOTAL ESTIMATED COST (SERVICES) | J14: Sum of BILLED / PARTIALLY BILLED COST
F15: AUDITED | G15: 309761.23 | H15: 79479.1 | K15: 309761.23 | L15: 79479.1
F16: FOR AUDIT | G16: 4366131.1 | H16: 368944.03 | K16: 4366131.1 | L16: 368944.03
F17: NO COC | G17: 1784857.6 | K17: 1784857.6
F18: ON GOING MATERIAL RETURN | G18: 80751.9 | H18: 35552.91 | K18: 80751.9 | L18: 35552.91
F19: SCHED/ INPRG | G19: 4597848.4 | I19: 44676.99 | K19: 4642525.4
F20: Grand Total | G20: 11139350 | H20: 483976.04 | I20: 44676.99 | K20: 11184027 | L20: 483976.04

Sheet SUPV
A1: ME185130 | B1: JEMUEL PERALTA
A2: ME168168 | B2: CRIS EMMANUEL GUEVARRA | CV2: EXT
A3: ME168443 | B3: DEAN CARL BORJAL
A4: ME194579 | B4: IAN PATRICK PEREZ
A5: ME188111 | B5: JUSTINE RAMOS
A6: ME166067 | B6: ISAN CARLO LAZARO | CV6: P2006000921',
A7: ME173899 | B7: JUNILO MICHAEL FLORES
A8: ME189046 | B8: REYZON MATIENZO
A9: ME177199 | B9: MARC JOSEPH FERRER
A10: ME155242 | B10: RONILO JR GANGE
A11: =VLOOKUP(#REF!,'[1]List of Work Orders'!$A:$I,9,FALSE) -> #REF!

Sheet Justifications
A1: Applicant facility not ready
A2: Applicant holds execution
A3: Conjuct work order not released / completed
A4: ECQ (Site inaccessible)
A5: Energized on site but insufficient contract amount / No PO (System error)
A6: Energized on site but with back job
A7: Group quarantine (Manpower)
A8: MEP (Meralco Electrification Project)
A9: Materials unavailability
A10: No pole stake
A11: Road access problem
A12: Special LGU permits
... A21: With system error issue but completed at site
A23: Value | B23: Scope | C23: Start and End Dates | D23: Required Attachment (inclusive of Start and End dates) | E23: Required Remarks (inclusive of Start and End dates
A24: Applicant holds execution | B24: customer-related | C24: Start Date: WMTRL Date | D24: Communication with CRS/Customer | E24: Notes on customer-related concern/s
C25: End Date: Date of resolution with CRS/Customer | E25: Reason/s of applicant holding execution
A26: Third party concern (Applicant-related compliance) | B26: delay caused by parties other than the applicant (eg. LGU, HOA - halts execution due to lack of applicant compliance) | C26: Start Date: Date from CRS/Design/PROW coordination | D26: Communication with CRS/Design/PROW | E26: Notes on third party-related concern/s
C27: End Date: Date of concern resolution | E27: Reason/s of delay casued by third party
A28: Third party concern (Other than the applicant) | B28: delay caused by parties other than the applicant (eg. Neighbor, LGU, HOA - halts execution or requests transfer of pole location/guying, etc.) | C28: Start Date: Date from CRS/Design/PROW coordination | D28: Communication with CRS/Design/PROW | E28: Notes on third party-related concern/s
C29: End Date: Date of concern resolution | E29: Reason/s of delay casued by third party
A30: With ROW problem | B30: expired or unavailable ROW/permit | C30: Start Date: Date from CRS/Design/PROW coordination | D30: Communication with CRS/Design/PROW | E30: Notes on ROW-related concern/s
C31: End Date: Date of concern resolution | E31: Reason/s of ROW problem
A32: Special LGU permits | B32: Permits not common to other LGUs - Contractor’s Tax (Antipolo LGU), Baliwag LGU, ASEANA, BESC Permit Acquisition (BGC) | C32: Start Date: Start date of permit acquisition processing | D32: Communication with concerned party | E32: Notes on permit-related concern/s
C33: End Date: Permit acquisition | E33: Reason/s of permit/s problem
A34: No pole stake | B34: applicable only to subdivision developments; not applicable if proof of pole stake is available in EAM | C34: Start Date: WMTRL Date | D34: Communication with concerned party | E34: Notes on pole stake-related concern/s
C35: End Date: Date of concern resolution
A36: Conjuct work order not released/completed | B36: conjuct work order number not released or not yet completed | C36: Start Date: Date of coordination with CRS/Design | D36: Communication with CRS/Design | E36: Notes on conjuct WO details
C37: End Date: Date of concern resolution | E37: Reason/s of conjuct WO delay in completion
A38: With minor design modifications | B38: Minor design modifications (no change in design scheme / no additional station/task) | C38: Start Date: Date of coordination with Design | D38: Communication with Design | E38: Notes on design modification details
C39: End Date: Date of concern resolution | E39: Reason/s of design modification
A40: With major design modifications | B40: Major design modifications (with changes in design scheme / with additional station/task) | C40: Start Date: Date of coordination with Design | D40: Communication with Design | E40: Notes on design modification details
C41: End Date: Date released to construction after WO reversion | E41: Reason/s of design modification
A42: With pole / drainage /digging / manhole / pole attachment issue | B42: Location problem not related to ROW problem and/or Thrird party concern | C42: Start Date: Date from Design/PROW coordination | D42: Communication with Design/PROW | E42: Notes on issues with pole / drainage / digging / manhole / pole attachment
C43: End Date: Date of concern resolution
A44: Energized on site but with back job | B44: actual energization date must be indicated in the WO specs | C44: Start Date: Date energized | D44: Communication with vendor | E44: Notes on back job details
C45: End Date: Date of completion of back job/WO FCOMP/Date of concern resolution | D45: WO details/milestones | E45: Reason/s of back job
A46: Energized on site but insufficient contract amount / No PO (System error) | B46: actual energization date must be indicated in the WO specs | C46: Start Date: Date energized | D46: Communication with PCT/NCOM | E46: Notes on contract insufficiency
C47: End Date: Date of completion of budget amendment/WO FCOMP/Date of concern resolution | D47: WO details/milestones
A48: Materials unavailability | B48: item code and desciption must be indicated in justification | C48: Start Date: Date material unavailability | D48: Communication with Stores/MMO | E48: Notes on materials unavailability
C49: End Date: Date of stock availability | E49: List of unavailable items
...

Sheet UG-SLEM
D1: PROJECTS | E1: F | K1: F | L1: 45293 | X1: PERFORMANCE | AC1: RED(Above 50Days) | AH1: NEW KPI (Starting October 2021) | AL1: COMPUTATION: FOR FCOMP | AQ1: FOR COMP | AT1: (-5) | AU1: 0.75 aspiration | BB1: 0.75 aspiration | BC1: REMARKS | BE1: CERTIFICATE OF COMPLETION | BI1: FIELD AUDIT | BK1: RE-WORK | BO1: MATERIAL BALANCING | BQ1: TRANSMITTAL TO METER | BS1: FOR OLDT DETAILS
A2: Date Received Jacket from P&S | B2: Date Received Awarding of Wo | C2: VIP | D2: WO INITIATOR | E2: WO NO | F2: DESCRIPTION | G2: LOCATION | H2: MUNICIPALITY | I2: AREA OF RESPONSIBILITY | J2: VENDOR REMARKS (free text) | K2: C1 REMARKS (with or without issue) | L2: ASSIGNED | M2: STATUS | N2: SUPERVISOR | O2: C1 CONTRACTOR MANHOUR | P2: TOTAL MANHOURS | Q2: APPLIED LOAD | R2: TYPE | S2: TOTAL PLANNED PROJECT COST | T2: TOTAL ESTIMATED COST (SERVICES) | U2: BILLED / PARTIALLY BILLED COST | V2: % BILLED | W2: DATE WMTRL | X2: DATE SCHED | Y2: DATE RECEIVED BY VC | Z2: ACTUAL DATE COMPLETED ON SITE | AA2: DATE FCOMP | AB2: DATE COMP | AC2: # of days WMTRL TO FCOMP APT Without Exclusion (SPT) | AD2: # of days SCHED TO FCOMP | AE2: # of days COMP | AF2: (0.75) DATE NEEDED FOR WMTRL TO FCOMP | AG2: (0.95) DATE NEEDED FOR FCOMP | AH2: (50 DAYS) DATE NEEDED FOR WMTRL TO FCOMP | AI2: COMPUTED INDEX (WMTRL TO FCOMP) CCTI Without Exclusion | AJ2: COMPUTED INDEX (COMP) | AK2: SPT(M) | AL2: SPT(L) | AM2: 0.75 DURATION (DAYS) | AN2: 0.95 DURATION (DAYS) | AO2: TARGET DAYS | AP2: SPT(M) for comp | AQ2: DURATION (DAYS)COMP | AR2: TARGET DAYS (COMP) | AS2: DATE NEEDED TO COMP | AT2: TARGET DATE TO COMP | AU2: REASON (FOR EXCLUSION) | AV2: FOR CCTI EXCLUSION (Y/N) | AW2: ENCODED IN EAM (Y/N) | AX2: VALIDATED BY DCSAM (Y/N) | AY2: For APT Exclusion (Y/N) | AZ2: START DATE | BA2: DURATION FOR EXCLUSION | BB2: END DATE (FOR EXCLUSION) | BC2: REMARKS / FOLLOW UP BY | BD2: REMARKS 2 | BE2: DATE NEEDED TO SUBMIT COC | BF2: AGEING SUBMISSION OF COC | BG2: DATE COMPLETED (FROM COC) | BH2: ACTUAL RECEIVED COC | BI2: DATE AUDIT | BJ2: BY: | BK2: W/ BACK JOB | BL2: BACKJOB TAGGED IN EAM? RE-WORK | BM2: DATE RECEIVED BY CONTRACTOR | BN2: DATE CORRECTED | BO2: DATE MATERIAL BALANCING | BP2: BY | BQ2: Y/N | BR2: EMAILED TO METER | BS2: DT CORRECTION METHOD | BT2: TLN | BU2: WITH POLE REPL? | BV2: ACTUAL FIELD STATUS | BW2: REMARKS3 | BX2: ABF PRINTED BY (FOR AUDIT) | BY2: DATE PRINTED OF POLE TAG FABRICATION FORM | BZ2: POLE / TLN TAGS | CA2: Days for Exclusion based on emails to concerned office/PCTs (Due to customer only - APT) | CB2: APT with Exclusion | CC2: Days for Exclusion based on emails to concerned office/PCTs (All reason - CCTI) | CD2: Duration for CCTI with exclusion | CE2: CCTI With Exclusion | CF2: Meralco/Customer Reason | CG2: Issue Remarks | CH2: CURRENT CCTI
A3: 45238 | B3: 45236 | D3: CBG | E3: X23083339380 | F3: TANG KUNQUAN | G3: QUIRINO, TAMBO, PARANAQUE | H3: PARAÑAQUE CITY | I3: PARAÑAQUE | J3: UG WO; with issue on pole location | K3: UG | L3: ECOM | M3: COMP | N3: UG | O3: 139.3524 | P3: 659.83 | Q3: 1062 | R3: NEW | S3: 4081533.1 | T3: 132841.45 | U3: 94987.61 | V3: =U3/T3 -> 0.71504497 | W3: 45233.619 | X3: 45233.619 | Y3: 45236.366 | AA3: 45328.546 | AB3: 45581.419 | AC3: =AA3-W3 -> 94.926389 | AD3: =AA3-X3 -> 94.926389 | AE3: =AB3-AA3 -> 252.87361 | AF3: =W3+AO3 -> 45248.267 | AG3: =W3+AN3 -> 45255.972 | AH3: =W3+50 -> 45283.619 | AI3: =(0.3)*(AC3/AK3)+(0.7)*(AC3/AL3) -> 4.0343715 | AJ3: =AE3/AP3 -> 4.597702 | AK3: =IF(P3<51,20,(IF(P3<101,23,(IF(P3<201,26,IF(P3<301,28,IF(P3<401,30,(IF(P3<501,32,(IF(P3<1001,40,50))))))))))) -> 40 | AL3: =IF(Q3<51,36,(IF(Q3<101,34,(IF(Q3<201,32,IF(Q3<301,30,IF(Q3<401,28,(IF(Q3<501,26,(IF(Q3<1001,23,20))))))))))) -> 20 | AM3: =(0.75)/((0.3/AK3)+(0.7/AL3)) -> 17.647059 | AN3: =(0.95)/((0.3/AK3)+(0.7/AL3)) -> 22.352941 | AO3: =AM3-3 -> 14.647059 | AP3: =IF(P3<51,40,(IF(P3<101,42,(IF(P3<201,44,IF(P3<301,46,IF(P3<401,48,(IF(P3<501,50,(IF(P3<1001,55,60))))))))))) -> 55 | AQ3: =0.8*AP3 -> 44 | AR3: =AQ3-5 -> 39 | AS3: =AA3+AQ3 -> 45372.546 | AT3: =AS3-5 -> 45367.546 | BC3: PAID | BF3: 3 | BG3: 45327 | BH3: 45372 | BI3: 45548 | BJ3: ECI | BK3: N | BQ3: Y | BX3: PDZC | BY3: 45238 | BZ3: C5-0512, 116398, C5-8057, 518496, C5-8058 | CB3: =AC3-CA3 -> 94.926389 | CD3: =AC3-CC3 -> 94.926389 | CE3: =(0.3)*(CD3/AK3)+(0.7)*(CD3/AL3) -> 4.0343715 | CH3: =(0.3)*((NOW()-W3)/AK3)+(0.7)*((NOW()-W3)/AL3) -> 28.122134 | CI3: =IF(AB3="","PENDING COMP",(AB3-AA3)/AP3) -> 4.597702 | CK3: =IF(R3="NEW","REV","NON-REV") -> REV
A4: 45310 | D4: CBG | E4: X23083306750 | F4: VITACARE UNIMED HOSPITAL AND MEDICAL CENTER CORP. | G4: DAANG-HARI RD., MOLINO IV, BACOOR | H4: BACOOR CITY | I4: DASMA | K4: UG | L4: POWERHOUSE | M4: TECO | N4: UG | O4: 72.5251 | P4: 585.55 | Q4: 1700 | R4: NEW | S4: 3336508.3 | T4: 36496.41 | V4: =U4/T4 -> 0 | W4: 45295.606 | X4: 45295.606 | Y4: 45296.903 | AA4: 45314.547 | AB4: 45723.674 | AC4: =AA4-W4 -> 18.941667 | AD4: =AA4-X4 -> 18.941667 | AE4: =AB4-AA4 -> 409.12639 | AF4: =W4+AO4 -> 45310.253 | AG4: =W4+AN4 -> 45317.958 | AH4: =W4+50 -> 45345.606 | AI4: =(0.3)*(AC4/AK4)+(0.7)*(AC4/AL4) -> 0.80502083 | AJ4: =AE4/AP4 -> 7.4386616 | AK4: =IF(P4<51,20,(IF(P4<101,23,(IF(P4<201,26,IF(P4<301,28,IF(P4<401,30,(IF(P4<501,32,(IF(P4<1001,40,50))))))))))) -> 40 | AL4: =IF(Q4<51,36,(IF(Q4<101,34,(IF(Q4<201,32,IF(Q4<301,30,IF(Q4<401,28,(IF(Q4<501,26,(IF(Q4<1001,23,20))))))))))) -> 20 | AM4: =(0.75)/((0.3/AK4)+(0.7/AL4)) -> 17.647059 | AN4: =(0.95)/((0.3/AK4)+(0.7/AL4)) -> 22.352941 | AO4: =AM4-3 -> 14.647059 | AP4: =IF(P4<51,40,(IF(P4<101,42,(IF(P4<201,44,IF(P4<301,46,IF(P4<401,48,(IF(P4<501,50,(IF(P4<1001,55,60))))))))))) -> 55 | AQ4: =0.8*AP4 -> 44 | AR4: =AQ4-5 -> 39 | AS4: =AA4+AQ4 -> 45358.547 | AT4: =AS4-5 -> 45353.547 | BC4: NO COC | BF4: 3 | BQ4: Y | BY4: 45315 | BZ4: CR8-5430, CR8-8016, CR8-8016, 182943 | CB4: =AC4-CA4 -> 18.941667 | CD4: =AC4-CC4 -> 18.941667 | CE4: =(0.3)*(CD4/AK4)+(0.7)*(CD4/AL4) -> 0.80502083 | CH4: =(0.3)*((NOW()-W4)/AK4)+(0.7)*((NOW()-W4)/AL4) -> 25.487724 | CI4: =IF(AB4="","PENDING COMP",(AB4-AA4)/AP4) -> 7.4386616 | CK4: =IF(R4="NEW","REV","NON-REV") -> REV
A5: 45350 | B5: 45356 | D5: CBG | E5: X23062134423 | F5: SM DEVELOPMENT CORPORATION, | G5: TOWER C, BLOOM RESIDENCES, PARANAQUE | H5: PARAÑAQUE CITY | I5: PARANAQUE | J5: Conjunct with UG, target itayo poste March 6 | L5: AVECO | M5: COMP | N5: UG | O5: 115.33 | P5: 507.57 | Q5: 1563.3 | R5: NEW | S5: 3001400.5 | T5: 89877.04 | V5: =U5/T5 -> 0 | W5: 45310.658 | X5: 45314.61 | Y5: 45351 | AA5: 45401.602 | AB5: 45694 | AC5: =AA5-W5 -> 90.944444 | AD5: =AA5-X5 -> 86.991667 | AE5: =AB5-AA5 -> 292.39792 | AF5: =W5+AO5 -> 45325.526 | AG5: =W5+AN5 -> 45333.291 | AH5: =W5+50 -> 45360.658 | AI5: =(0.3)*(AC5/AK5)+(0.7)*(AC5/AL5) -> 3.8172334 | AJ5: =AE5/AP5 -> 6.6454072 | AK5: =IF(O5<51,20,(IF(O5<101,23,(IF(O5<201,26,IF(O5<301,28,IF(O5<401,30,(IF(O5<501,32,(IF(O5<1001,40,50))))))))))) -> 26 | AL5: =IF(P5<51,36,(IF(P5<101,34,(IF(P5<201,32,IF(P5<301,30,IF(P5<401,28,(IF(P5<501,26,(IF(P5<1001,23,20))))))))))) -> 23 | AM5: =(0.75)/((0.3/AK5)+(0.7/AL5)) -> 17.868526 | AN5: =(0.95)/((0.3/AK5)+(0.7/AL5)) -> 22.633466 | AO5: =AM5-3 -> 14.868526 | AP5: =IF(O5<51,40,(IF(O5<101,42,(IF(O5<201,44,IF(O5<301,46,IF(O5<401,48,(IF(O5<501,50,(IF(O5<1001,55,60))))))))))) -> 44 | AQ5: =0.8*AP5 -> 35.2 | AR5: =AQ5-5 -> 30.2 | AS5: =AA5+AQ5 -> 45436.802 | AT5: =AS5-5 -> 45431.802 | BC5: ON GOING MAT RETURN | BD5: FULLY BILLED | BE5: =AA5+3 -> 45404.602 | BF5: =IF(ISBLANK(AA5),0,IF(ISBLANK(BH5),($L$1-BE5),(BH5-BE5))) -> 198.39792 | BG5: 45394 | BH5: 45603 | BI5: 45638 | BJ5: ECI | BK5: N | BQ5: Y | CB5: =AC5-CA5 -> 90.944444 | CD5: =AC5-CC5 -> 90.944444 | CE5: =(0.3)*(CD5/AK5)+(0.7)*(CD5/AL5) -> 3.8172334 | CH5: =(0.3)*((NOW()-W5)/AK5)+(0.7)*((NOW()-W5)/AL5) -> 24.540038 | CI5: =IF(AB5="","PENDING COMP",(AB5-AA5)/AP5) -> 6.6454072 | CK5: =IF(R5="NEW","REV","NON-REV") -> REV
A6: 45383 | B6: 45376 | D6: CBG | E6: X24010270067 | F6: PHINMA PROPERTY HOLDINGS CORPORATION | G6: CHROMIUM, METROTOWNE, LAS PINAS CITY | H6: LAS PIÑAS CITY | I6: PARAÑAQUE | J6: UG supervisor | K6: W/O ISSUE | L6: POWERHOUSE | M6: FCOMP | N6: UG | O6: 45.3098 | P6: 375.5 | Q6: 1965.8 | R6: NEW | S6: 3158370.5 | T6: 46889.1 | V6: =U6/T6 -> 0 | W6: 45370.465 | X6: 45383.364 | Y6: 45373 | AA6: 45398.693 | AC6: =AA6-W6 -> 28.228472 | AD6: =AA6-X6 -> 15.329167 | AE6: =AB6-AA6 -> -45398.693 | AF6: =W6+AO6 -> 45386.215 | AG6: =W6+AN6 -> 45394.215 | AH6: =W6+50 -> 45420.465 | AI6: =(0.3)*(AC6/AK6)+(0.7)*(AC6/AL6) -> 1.1291389 | AJ6: =AE6/AP6 -> -1134.9673 | AK6: =IF(O6<51,20,(IF(O6<101,23,(IF(O6<201,26,IF(O6<301,28,IF(O6<401,30,(IF(O6<501,32,(IF(O6<1001,40,50))))))))))) -> 20 | AL6: =IF(P6<51,36,(IF(P6<101,34,(IF(P6<201,32,IF(P6<301,30,IF(P6<401,28,(IF(P6<501,26,(IF(P6<1001,23,20))))))))))) -> 28 | AM6: =(0.75)/((0.3/AK6)+(0.7/AL6)) -> 18.75 | AN6: =(0.95)/((0.3/AK6)+(0.7/AL6)) -> 23.75 | AO6: =AM6-3 -> 15.75 | AP6: =IF(O6<51,40,(IF(O6<101,42,(IF(O6<201,44,IF(O6<301,46,IF(O6<401,48,(IF(O6<501,50,(IF(O6<1001,55,60))))))))))) -> 40 | AQ6: =0.8*AP6 -> 32 | AR6: =AQ6-5 -> 27 | AS6: =AA6+AQ6 -> 45430.693 | AT6: =AS6-5 -> 45425.693 | BC6: NO COC | BE6: =AA6+3 -> 45401.693 | BF6: =IF(ISBLANK(AA6),0,IF(ISBLANK(BH6),($L$1-BE6),(BH6-BE6))) -> -108.69306 | BQ6: Y | BY6: 45384 | BZ6: CU8-1255, 520351, CU8-8053 | CB6: =AC6-CA6 -> 28.228472 | CD6: =AC6-CC6 -> 28.228472 | CE6: =(0.3)*(CD6/AK6)+(0.7)*(CD6/AL6) -> 1.1291389 | CH6: =(0.3)*((NOW()-W6)/AK6)+(0.7)*((NOW()-W6)/AL6) -> 20.994085 | CI6: =IF(AB6="","PENDING COMP",(AB6-AA6)/AP6) -> PENDING COMP | CK6: =IF(R6="NEW","REV","NON-REV") -> REV
E7: X24041165129 | F7: LIGHT RAIL MANILA CORPORATION | G7: NINOY AQUINO, STO. NINO, PARANAQUE | H7: PARANAQUE CITY | I7: PARAÑAQUE | L7: SLEM | M7: FCOMP | N7: SLEM | P7: 136.13 | R7: NEW | V7: =U7/T7 -> #DIV/0! | W7: 45408 | AA7: 45800 | AE7: =AB7-AA7 -> -45800 | AF7: =W7+AO7 -> 45429.207 | AG7: =W7+AN7 -> 45438.662 | AH7: =W7+50 -> 45458 | AI7: =(0.3)*(AC7/AK7)+(0.7)*(AC7/AL7) -> 0 | AJ7: =AE7/AP7 -> -1040.9091 | AK7: =IF(P7<51,20,(IF(P7<101,23,(IF(P7<201,26,IF(P7<301,28,IF(P7<401,30,(IF(P7<501,32,(IF(P7<1001,40,50))))))))))) -> 26 | AL7: =IF(Q7<51,36,(IF(Q7<101,34,(IF(Q7<201,32,IF(Q7<301,30,IF(Q7<401,28,(IF(Q7<501,26,(IF(Q7<1001,23,20))))))))))) -> 36 | AM7: =(0.75)/((0.3/AK7)+(0.7/AL7)) -> 24.206897 | AN7: =(0.95)/((0.3/AK7)+(0.7/AL7)) -> 30.662069 | AO7: =AM7-3 -> 21.206897 | AP7: =IF(P7<51,40,(IF(P7<101,42,(IF(P7<201,44,IF(P7<301,46,IF(P7<401,48,(IF(P7<501,50,(IF(P7<1001,55,60))))))))))) -> 44 | AQ7: =0.8*AP7 -> 35.2 | AR7: =AQ7-5 -> 30.2 | AS7: =AA7+AQ7 -> 45835.2 | AT7: =AS7-5 -> 45830.2 | BF7: =IF(ISBLANK(AA7),0,IF(ISBLANK(BH7),($L$1-BE7),(BH7-BE7))) -> 45293 | CB7: =AC7-CA7 -> 0 | CD7: =AC7-CC7 -> 0 | CE7: =(0.3)*(CD7/AK7)+(0.7)*(CD7/AL7) -> 0 | CH7: =(0.3)*((NOW()-W7)/AK7)+(0.7)*((NOW()-W7)/AL7) -> 15.098488 | CI7: =IF(AB7="","PENDING COMP",(AB7-AA7)/AP7) -> PENDING COMP | CK7: =IF(R7="NEW","REV","NON-REV") -> REV
E8: X24041165310 | F8: LIGHT RAIL MANILA CORPORATION | G8: NINOY AQUINO, STO. NINO, PARANAQUE | H8: PARANAQUE CITY | I8: PARAÑAQUE | L8: SLEM | M8: FCOMP | N8: SLEM | P8: 136.13 | R8: NEW | V8: =U8/T8 -> #DIV/0! | W8: 45408 | AA8: 45811 | AE8: =AB8-AA8 -> -45811 | AF8: =W8+AO8 -> 45429.207 | AG8: =W8+AN8 -> 45438.662 | AH8: =W8+50 -> 45458 | AI8: =(0.3)*(AC8/AK8)+(0.7)*(AC8/AL8) -> 0 | AJ8: =AE8/AP8 -> -1041.1591 | AK8: =IF(P8<51,20,(IF(P8<101,23,(IF(P8<201,26,IF(P8<301,28,IF(P8<401,30,(IF(P8<501,32,(IF(P8<1001,40,50))))))))))) -> 26 | AL8: =IF(Q8<51,36,(IF(Q8<101,34,(IF(Q8<201,32,IF(Q8<301,30,IF(Q8<401,28,(IF(Q8<501,26,(IF(Q8<1001,23,20))))))))))) -> 36 | AM8: =(0.75)/((0.3/AK8)+(0.7/AL8)) -> 24.206897 | AN8: =(0.95)/((0.3/AK8)+(0.7/AL8)) -> 30.662069 | AO8: =AM8-3 -> 21.206897 | AP8: =IF(P8<51,40,(IF(P8<101,42,(IF(P8<201,44,IF(P8<301,46,IF(P8<401,48,(IF(P8<501,50,(IF(P8<1001,55,60))))))))))) -> 44 | AQ8: =0.8*AP8 -> 35.2 | AR8: =AQ8-5 -> 30.2 | AS8: =AA8+AQ8 -> 45846.2 | AT8: =AS8-5 -> 45841.2 | BF8: =IF(ISBLANK(AA8),0,IF(ISBLANK(BH8),($L$1-BE8),(BH8-BE8))) -> 45293 | CB8: =AC8-CA8 -> 0 | CD8: =AC8-CC8 -> 0 | CE8: =(0.3)*(CD8/AK8)+(0.7)*(CD8/AL8) -> 0 | CH8: =(0.3)*((NOW()-W8)/AK8)+(0.7)*((NOW()-W8)/AL8) -> 15.098488 | CI8: =IF(AB8="","PENDING COMP",(AB8-AA8)/AP8) -> PENDING COMP | CK8: =IF(R8="NEW","REV","NON-REV") -> REV
E9: X24041432658 | F9: LIGHT RAIL MANILA CORPORATION | G9: NINOY AQUINO, STO. NINO, PARANAQUE | H9: PARANAQUE CITY | I9: PARAÑAQUE | L9: SLEM | M9: FCOMP | N9: SLEM | P9: 136.13 | R9: NEW | V9: =U9/T9 -> #DIV/0! | W9: 45420 | AA9: 45716 | AC9: =AA9-W9 -> 296 | AD9: =AA9-X9 -> 45716 | AE9: =AB9-AA9 -> -45716 | AF9: =W9+AO9 -> 45441.207 | AG9: =W9+AN9 -> 45450.662 | AH9: =W9+50 -> 45470 | AI9: =(0.3)*(AC9/AK9)+(0.7)*(AC9/AL9) -> 9.1709402 | AJ9: =AE9/AP9 -> -1039 | AK9: =IF(P9<51,20,(IF(P9<101,23,(IF(P9<201,26,IF(P9<301,28,IF(P9<401,30,(IF(P9<501,32,(IF(P9<1001,40,50))))))))))) -> 26 | AL9: =IF(Q9<51,36,(IF(Q9<101,34,(IF(Q9<201,32,IF(Q9<301,30,IF(Q9<401,28,(IF(Q9<501,26,(IF(Q9<1001,23,20))))))))))) -> 36 | AM9: =(0.75)/((0.3/AK9)+(0.7/AL9)) -> 24.206897 | AN9: =(0.95)/((0.3/AK9)+(0.7/AL9)) -> 30.662069 | AO9: =AM9-3 -> 21.206897 | AP9: =IF(P9<51,40,(IF(P9<101,42,(IF(P9<201,44,IF(P9<301,46,IF(P9<401,48,(IF(P9<501,50,(IF(P9<1001,55,60))))))))))) -> 44 | AQ9: =0.8*AP9 -> 35.2 | AR9: =AQ9-5 -> 30.2 | AS9: =AA9+AQ9 -> 45751.2 | AT9: =AS9-5 -> 45746.2 | BF9: =IF(ISBLANK(AA9),0,IF(ISBLANK(BH9),($L$1-BE9),(BH9-BE9))) -> 45293 | CB9: =AC9-CA9 -> 296 | CD9: =AC9-CC9 -> 296 | CE9: =(0.3)*(CD9/AK9)+(0.7)*(CD9/AL9) -> 9.1709402 | CH9: =(0.3)*((NOW()-W9)/AK9)+(0.7)*((NOW()-W9)/AL9) -> 14.726693 | CI9: =IF(AB9="","PENDING COMP",(AB9-AA9)/AP9) -> PENDING COMP | CK9: =IF(R9="NEW","REV","NON-REV") -> REV
A10: 45427 | B10: 45427 | D10: CBG | E10: X24020489831 | F10: SM DEVELOPMENT CORPORATION, | G10: DR. A SANTOS, SAN DIONISIO, PARANAQUE | H10: PARAÑAQUE CITY | I10: PARAÑAQUE | L10: ECOM | M10: FCOMP | N10: UG | O10: 108.1986 | P10: 443.47 | Q10: 1021 | R10: NEW | S10: 3240513.1 | T10: 55638.73 | V10: =U10/T10 -> 0 | W10: 45422.635 | X10: 45425.781 | Y10: 45427 | AA10: 45483.344 | AC10: =AA10-W10 -> 60.709028 | AD10: =AA10-X10 -> 57.563889 | AE10: =AB10-AA10 -> -45483.344 | AF10: =W10+AO10 -> 45436.537 | AG10: =W10+AN10 -> 45444.044 | AH10: =W10+50 -> 45472.635 | AI10: =(0.3)*(AC10/AK10)+(0.7)*(AC10/AL10) -> 2.6939631 | AJ10: =AE10/AP10 -> -909.66689 | AK10: =IF(P10<51,20,(IF(P10<101,23,(IF(P10<201,26,IF(P10<301,28,IF(P10<401,30,(IF(P10<501,32,(IF(P10<1001,40,50))))))))))) -> 32 | AL10: =IF(Q10<51,36,(IF(Q10<101,34,(IF(Q10<201,32,IF(Q10<301,30,IF(Q10<401,28,(IF(Q10<501,26,(IF(Q10<1001,23,20))))))))))) -> 20 | AM10: =(0.75)/((0.3/AK10)+(0.7/AL10)) -> 16.901408 | AN10: =(0.95)/((0.3/AK10)+(0.7/AL10)) -> 21.408451 | AO10: =AM10-3 -> 13.901408 | AP10: =IF(P10<51,40,(IF(P10<101,42,(IF(P10<201,44,IF(P10<301,46,IF(P10<401,48,(IF(P10<501,50,(IF(P10<1001,55,60))))))))))) -> 50 | AQ10: =0.8*AP10 -> 40 | AR10: =AQ10-5 -> 35 | AS10: =AA10+AQ10 -> 45523.344 | AT10: =AS10-5 -> 45518.344 | BC10: ON GOING MAT RETURN | BE10: =AA10+3 -> 45486.344 | BF10: =IF(ISBLANK(AA10),0,IF(ISBLANK(BH10),($L$1-BE10),(BH10-BE10))) -> 6.6555556 | BG10: 45476 | BH10: 45493 | BI10: 45572 | BJ10: ECI | BK10: N | BQ10: Y | BY10: 45428 | BZ10: CZ8-8066, 520527 | CB10: =AC10-CA10 -> 60.709028 | CD10: =AC10-CC10 -> 60.709028 | CE10: =(0.3)*(CD10/AK10)+(0.7)*(CD10/AL10) -> 2.6939631 | CH10: =(0.3)*((NOW()-W10)/AK10)+(0.7)*((NOW()-W10)/AL10) -> 20.975232 | CI10: =IF(AB10="","PENDING COMP",(AB10-AA10)/AP10) -> PENDING COMP | CK10: =IF(R10="NEW","REV","NON-REV") -> REV
A11: 45440 | B11: 45441 | D11: BIZ | E11: X24030698480 | F11: BRILLO DEL ESTE DEVELOPMENT CORP. | G11: ADMIN-COMMERCIAL, EASTGLORY CENTER, PARANAQUE | H11: PARAÑAQUE CITY | I11: PARAÑAQUE | K11: W/O ISSUE | L11: VJC | M11: FCOMP | N11: UG | O11: 37.49 | P11: 600.42 | Q11: 6237 | R11: NEW | S11: 4328746.1 | T11: 30189.83 | U11: 14379.55 | V11: =U11/T11 -> 0.47630444 | W11: 45425.682 | X11: 45427.739 | Y11: 45440 | AA11: 45488.594 | AC11: =AA11-W11 -> 62.911806 | AD11: =AA11-X11 -> 60.854861 | AE11: =AB11-AA11 -> -45488.594 | AF11: =W11+AO11 -> 45440.329 | AG11: =W11+AN11 -> 45448.035 | AH11: =W11+50 -> 45475.682 | AI11: =(0.3)*(AC11/AK11)+(0.7)*(AC11/AL11) -> 2.6737517 | AJ11: =AE11/AP11 -> -827.06534 | AK11: =IF(P11<51,20,(IF(P11<101,23,(IF(P11<201,26,IF(P11<301,28,IF(P11<401,30,(IF(P11<501,32,(IF(P11<1001,40,50))))))))))) -> 40 | AL11: =IF(Q11<51,36,(IF(Q11<101,34,(IF(Q11<201,32,IF(Q11<301,30,IF(Q11<401,28,(IF(Q11<501,26,(IF(Q11<1001,23,20))))))))))) -> 20 | AM11: =(0.75)/((0.3/AK11)+(0.7/AL11)) -> 17.647059 | AN11: =(0.95)/((0.3/AK11)+(0.7/AL11)) -> 22.352941 | AO11: =AM11-3 -> 14.647059 | AP11: =IF(P11<51,40,(IF(P11<101,42,(IF(P11<201,44,IF(P11<301,46,IF(P11<401,48,(IF(P11<501,50,(IF(P11<1001,55,60))))))))))) -> 55 | AQ11: =0.8*AP11 -> 44 | AR11: =AQ11-5 -> 39 | AS11: =AA11+AQ11 -> 45532.594 | AT11: =AS11-5 -> 45527.594 | BC11: NO COC | BD11: PARTIALLY BILLED - 7/25/24 JSB | BE11: =AA11+3 -> 45491.594 | BF11: =IF(ISBLANK(AA11),0,IF(ISBLANK(BH11),($L$1-BE11),(BH11-BE11))) -> -198.59375 | BQ11: Y | BY11: 45440 | BZ11: C5-0154, C5-8080, 520856 | CB11: =AC11-CA11 -> 62.911806 | CD11: =AC11-CC11 -> 62.911806 | CE11: =(0.3)*(CD11/AK11)+(0.7)*(CD11/AL11) -> 2.6737517 | CH11: =(0.3)*((NOW()-W11)/AK11)+(0.7)*((NOW()-W11)/AL11) -> 19.959477 | CI11: =IF(AB11="","PENDING COMP",(AB11-AA11)/AP11) -> PENDING COMP | CK11: =IF(R11="NEW","REV","NON-REV") -> REV
A12: 45457 | B12: 45461 | D12: CBG | E12: X24010113590 | F12: LAS PINAS GENERAL HOSPITAL AND SATELLITE TRAUMA CE | G12: QUIRINO, PULANGLUPA I, LAS PINAS CITY | H12: LAS PIÑAS CITY | I12: PARAÑAQUE | K12: W/O ISSUE | L12: AVECO | M12: FCOMP | N12: UG | O12: 76.7333 | P12: 563.4 | Q12: 1434 | R12: NEW | S12: 3729821 | T12: 61791.45 | V12: =U12/T12 -> 0 | W12: 45443.547 | X12: 45457.689 | Y12: 45454 | AA12: 45481.297 | AC12: =AA12-W12 -> 37.75 | AD12: =AA12-X12 -> 23.607639 | AE12: =AB12-AA12 -> -45481.297 | AF12: =W12+AO12 -> 45458.194 | AG12: =W12+AN12 -> 45465.899 | AH12: =W12+50 -> 45493.547 | AI12: =(0.3)*(AC12/AK12)+(0.7)*(AC12/AL12) -> 1.604375 | AJ12: =AE12/AP12 -> -826.93266 | AK12: =IF(P12<51,20,(IF(P12<101,23,(IF(P12<201,26,IF(P12<301,28,IF(P12<401,30,(IF(P12<501,32,(IF(P12<1001,40,50))))))))))) -> 40 | AL12: =IF(Q12<51,36,(IF(Q12<101,34,(IF(Q12<201,32,IF(Q12<301,30,IF(Q12<401,28,(IF(Q12<501,26,(IF(Q12<1001,23,20))))))))))) -> 20 | AM12: =(0.75)/((0.3/AK12)+(0.7/AL12)) -> 17.647059 | AN12: =(0.95)/((0.3/AK12)+(0.7/AL12)) -> 22.352941 | AO12: =AM12-3 -> 14.647059 | AP12: =IF(P12<51,40,(IF(P12<101,42,(IF(P12<201,44,IF(P12<301,46,IF(P12<401,48,(IF(P12<501,50,(IF(P12<1001,55,60))))))))))) -> 55 | AQ12: =0.8*AP12 -> 44 | AR12: =AQ12-5 -> 39 | AS12: =AA12+AQ12 -> 45525.297 | AT12: =AS12-5 -> 45520.297 | BC12: NO COC | BE12: =AA12+3 -> 45484.297 | BF12: =IF(ISBLANK(AA12),0,IF(ISBLANK(BH12),($L$1-BE12),(BH12-BE12))) -> -191.29653 | BQ12: Y | BY12: 45460 | BZ12: CY7-8072, CY7-8073, 519311, CY7-8073 | CB12: =AC12-CA12 -> 37.75 | CD12: =AC12-CC12 -> 37.75 | CE12: =(0.3)*(CD12/AK12)+(0.7)*(CD12/AL12) -> 1.604375 | CH12: =(0.3)*((NOW()-W12)/AK12)+(0.7)*((NOW()-W12)/AL12) -> 19.200233 | CI12: =IF(AB12="","PENDING COMP",(AB12-AA12)/AP12) -> PENDING COMP | CK12: =IF(R12="NEW","REV","NON-REV") -> REV
A13: 45517 | B13: 45512 | D13: BIZ | E13: X23114429217 | F13: GOLDSERVE HOLDING COMPANY INC. | G13: MIA, TAMBO, PARANAQUE | H13: PARAÑAQUE CITY | I13: PARAÑAQUE | J13: pole location issue | K13: W/ ISSUE | L13: VJC | M13: FCOMP | N13: UG | O13: 62.1094 | P13: 224.02 | Q13: 44 | R13: NEW | S13: 636513.87 | T13: 49637.68 | U13: 41296.18 | V13: =U13/T13 -> 0.83195226 | W13: 45512.711 | X13: 45517.305 | Y13: 45520 | AA13: 45723 | AC13: =AA13-W13 -> 210.28889 | AD13: =AA13-X13 -> 205.69514 | AE13: =AB13-AA13 -> -45723 | AF13: =W13+AO13 -> 45534.58 | AG13: =W13+AN13 -> 45544.211 | AH13: =W13+50 -> 45562.711 | AI13: =(0.3)*(AC13/AK13)+(0.7)*(AC13/AL13) -> 6.3420459 | AJ13: =AE13/AP13 -> -993.97826 | AK13: =IF(P13<51,20,(IF(P13<101,23,(IF(P13<201,26,IF(P13<301,28,IF(P13<401,30,(IF(P13<501,32,(IF(P13<1001,40,50))))))))))) -> 28 | AL13: =IF(Q13<51,36,(IF(Q13<101,34,(IF(Q13<201,32,IF(Q13<301,30,IF(Q13<401,28,(IF(Q13<501,26,(IF(Q13<1001,23,20))))))))))) -> 36 | AM13: =(0.75)/((0.3/AK13)+(0.7/AL13)) -> 24.868421 | AN13: =(0.95)/((0.3/AK13)+(0.7/AL13)) -> 31.5 | AO13: =AM13-3 -> 21.868421 | AP13: =IF(P13<51,40,(IF(P13<101,42,(IF(P13<201,44,IF(P13<301,46,IF(P13<401,48,(IF(P13<501,50,(IF(P13<1001,55,60))))))))))) -> 46 | AQ13: =0.8*AP13 -> 36.8 | AR13: =AQ13-5 -> 31.8 | AS13: =AA13+AQ13 -> 45759.8 | AT13: =AS13-5 -> 45754.8 | BC13: FOR AUDIT | BD13: PARTIALLY BILLED - 7/25/24 JSB, PARTIAL 5/21/2025 | BE13: =AA13+15 -> 45738 | BF13: =IF(ISBLANK(AA13),0,IF(ISBLANK(BH13),($L$1-BE13),(BH13-BE13))) -> 30 | BG13: 45723 | BH13: 45768 | BQ13: Y | BY13: 45518 | BZ13: B5-8037, B5-0084, B5-8038, B5-5094, B5-00971 | CB13: =AC13-CA13 -> 210.28889 | CD13: =AC13-CC13 -> 210.28889 | CE13: =(0.3)*(CD13/AK13)+(0.7)*(CD13/AL13) -> 6.3420459 | CH13: =(0.3)*((NOW()-W13)/AK13)+(0.7)*((NOW()-W13)/AL13) -> 11.538899 | CI13: =IF(AB13="","PENDING COMP",(AB13-AA13)/AP13) -> PENDING COMP | CK13: =IF(R13="NEW","REV","NON-REV") -> REV
D14: CBG | E14: X24062079073 | F14: THE LANDMARK MANILA BAY CORPORATION | G14: ASEANA, ASEANA BUSINESS PARK, PARANAQUE | H14: PARAÑAQUE CITY | I14: PARAÑAQUE | L14: VJC | M14: FCOMP | N14: UG | O14: 147.944 | P14: 563.37 | Q14: 5950 | R14: NEW | S14: 5216314.4 | T14: 140962.37 | V14: =U14/T14 -> 0 | W14: 45569.434 | X14: 45569.555 | AA14: 45581.676 | AE14: =AB14-AA14 -> -45581.676 | AF14: =W14+AO14 -> 45584.081 | AG14: =W14+AN14 -> 45591.787 | AH14: =W14+50 -> 45619.434 | AI14: =(0.3)*(AC14/AK14)+(0.7)*(AC14/AL14) -> 0 | AJ14: =AE14/AP14 -> -828.75775 | AK14: =IF(P14<51,20,(IF(P14<101,23,(IF(P14<201,26,IF(P14<301,28,IF(P14<401,30,(IF(P14<501,32,(IF(P14<1001,40,50))))))))))) -> 40 | AL14: =IF(Q14<51,36,(IF(Q14<101,34,(IF(Q14<201,32,IF(Q14<301,30,IF(Q14<401,28,(IF(Q14<501,26,(IF(Q14<1001,23,20))))))))))) -> 20 | AM14: =(0.75)/((0.3/AK14)+(0.7/AL14)) -> 17.647059 | AN14: =(0.95)/((0.3/AK14)+(0.7/AL14)) -> 22.352941 | AO14: =AM14-3 -> 14.647059 | AP14: =IF(P14<51,40,(IF(P14<101,42,(IF(P14<201,44,IF(P14<301,46,IF(P14<401,48,(IF(P14<501,50,(IF(P14<1001,55,60))))))))))) -> 55 | AQ14: =0.8*AP14 -> 44 | AR14: =AQ14-5 -> 39 | AS14: =AA14+AQ14 -> 45625.676 | AT14: =AS14-5 -> 45620.676 | BC14: NO COC | CB14: =AC14-CA14 -> 0 | CD14: =AC14-CC14 -> 0 | CE14: =(0.3)*(CD14/AK14)+(0.7)*(CD14/AL14) -> 0 | CH14: =(0.3)*((NOW()-W14)/AK14)+(0.7)*((NOW()-W14)/AL14) -> 13.850014 | CI14: =IF(AB14="","PENDING COMP",(AB14-AA14)/AP14) -> PENDING COMP | CK14: =IF(R14="NEW","REV","NON-REV") -> REV
A15: 45694 | D15: BIZ | E15: X24051566102 | F15: ONE PREMIER AND TWO PREMIER CONDOMINIUM CORP. | G15: TWO PREMIER, ALABANG PREMIER, LAS PINAS CITY | H15: LAS PIÑAS CITY | I15: PARAÑAQUE | L15: UG | M15: TECO | N15: UG | P15: 299 | Q15: 3791 | R15: NEW | S15: 3214681.5 | V15: =U15/T15 -> #DIV/0! | W15: 45618 | X15: 45623 | AA15: 45672 | AB15: 45817.263 | AC15: =AA15-W15 -> 54 | AD15: =AA15-X15 -> 49 | AE15: =AB15-AA15 -> 145.26319 | AF15: =W15+AO15 -> 45631.406 | AG15: =W15+AN15 -> 45638.781 | AH15: =W15+50 -> 45668 | AI15: =(0.3)*(AC15/AK15)+(0.7)*(AC15/AL15) -> 2.4685714 | AJ15: =AE15/AP15 -> 3.1578955 | AK15: =IF(P15<51,20,(IF(P15<101,23,(IF(P15<201,26,IF(P15<301,28,IF(P15<401,30,(IF(P15<501,32,(IF(P15<1001,40,50))))))))))) -> 28 | AL15: =IF(Q15<51,36,(IF(Q15<101,34,(IF(Q15<201,32,IF(Q15<301,30,IF(Q15<401,28,(IF(Q15<501,26,(IF(Q15<1001,23,20))))))))))) -> 20 | AM15: =(0.75)/((0.3/AK15)+(0.7/AL15)) -> 16.40625 | AN15: =(0.95)/((0.3/AK15)+(0.7/AL15)) -> 20.78125 | AO15: =AM15-3 -> 13.40625 | AP15: =IF(P15<51,40,(IF(P15<101,42,(IF(P15<201,44,IF(P15<301,46,IF(P15<401,48,(IF(P15<501,50,(IF(P15<1001,55,60))))))))))) -> 46 | AQ15: =0.8*AP15 -> 36.8 | AR15: =AQ15-5 -> 31.8 | AS15: =AA15+AQ15 -> 45708.8 | AT15: =AS15-5 -> 45703.8 | BC15: PAID | BY15: N/A | CB15: =AC15-CA15 -> 54 | CD15: =AC15-CC15 -> 54 | CE15: =(0.3)*(CD15/AK15)+(0.7)*(CD15/AL15) -> 2.4685714 | CH15: =(0.3)*((NOW()-W15)/AK15)+(0.7)*((NOW()-W15)/AL15) -> 12.677335 | CI15: =IF(AB15="","PENDING COMP",(AB15-AA15)/AP15) -> 3.1578955 | CK15: =IF(R15="NEW","REV","NON-REV") -> REV
B16: 45679 | C16: Y | D16: CBG | E16: X24114365991 | F16: IFACE INC. | G16: STA. ANA, SUN VALLEY SUBD, PARANAQUE | H16: PARANAQUE CITY | I16: STA. ROSA | L16: AVECO | M16: FCOMP | N16: RRG | O16: 31.96 | P16: 366.82 | Q16: 994 | R16: NEW | S16: 3141766.4 | T16: 32632.89 | V16: =U16/T16 -> 0 | W16: 45673.69 | X16: 45677.626 | Y16: 45678 | Z16: 45751 | AA16: 45751 | AE16: =AB16-AA16 -> -45751 | AF16: =W16+AO16 -> 45689.239 | AG16: =W16+AN16 -> 45697.185 | AH16: =W16+50 -> 45723.69 | AI16: =(0.3)*(AC16/AK16)+(0.7)*(AC16/AL16) -> 0 | AJ16: =AE16/AP16 -> -953.14583 | AK16: =IF(P16<51,20,(IF(P16<101,23,(IF(P16<201,26,IF(P16<301,28,IF(P16<401,30,(IF(P16<501,32,(IF(P16<1001,40,50))))))))))) -> 30 | AL16: =IF(Q16<51,36,(IF(Q16<101,34,(IF(Q16<201,32,IF(Q16<301,30,IF(Q16<401,28,(IF(Q16<501,26,(IF(Q16<1001,23,20))))))))))) -> 23 | AM16: =(0.75)/((0.3/AK16)+(0.7/AL16)) -> 18.548387 | AN16: =(0.95)/((0.3/AK16)+(0.7/AL16)) -> 23.494624 | AO16: =AM16-3 -> 15.548387 | AP16: =IF(P16<51,40,(IF(P16<101,42,(IF(P16<201,44,IF(P16<301,46,IF(P16<401,48,(IF(P16<501,50,(IF(P16<1001,55,60))))))))))) -> 48 | AQ16: =0.8*AP16 -> 38.4 | AR16: =AQ16-5 -> 33.4 | AS16: =AA16+AQ16 -> 45789.4 | AT16: =AS16-5 -> 45784.4 | BC16: FOR AUDIT | BF16: =IF(ISBLANK(AA16),0,IF(ISBLANK(BH16),($L$1-BE16),(BH16-BE16))) -> 45861 | BG16: 45751 | BH16: 45861 | BY16: 45861 | BZ16: DZ1-8046 | CB16: =AC16-CA16 -> 0 | CD16: =AC16-CC16 -> 0 | CE16: =(0.3)*(CD16/AK16)+(0.7)*(CD16/AL16) -> 0 | CH16: =(0.3)*((NOW()-W16)/AK16)+(0.7)*((NOW()-W16)/AL16) -> 8.9614165 | CI16: =IF(AB16="","PENDING COMP",(AB16-AA16)/AP16) -> PENDING COMP | CK16: =IF(R16="NEW","REV","NON-REV") -> REV
A17: 45691 | D17: BIZ | E17: X25010064382 | F17: ACACIA REALTY CORP. | G17: FINANCE AVE, MADRIGAL BUSINESS PARK, MUNTINLUPA | H17: MUNTINLUPA CITY | I17: PARAÑAQUE | L17: UG | M17: FCOMP | N17: UG | P17: 32.2 | R17: TERMINATION | S17: 102570.5 | V17: =U17/T17 -> #DIV/0! | W17: 45682.541 | X17: 45688.604 | AA17: 45827 | AE17: =AB17-AA17 -> -45827 | AF17: =W17+AO17 -> 45701.315 | AG17: =W17+AN17 -> 45710.122 | AH17: =W17+50 -> 45732.541 | AI17: =(0.3)*(AC17/AK17)+(0.7)*(AC17/AL17) -> 0 | AJ17: =AE17/AP17 -> -1145.675 | AK17: =IF(P17<51,20,(IF(P17<101,23,(IF(P17<201,26,IF(P17<301,28,IF(P17<401,30,(IF(P17<501,32,(IF(P17<1001,40,50))))))))))) -> 20 | AL17: =IF(Q17<51,36,(IF(Q17<101,34,(IF(Q17<201,32,IF(Q17<301,30,IF(Q17<401,28,(IF(Q17<501,26,(IF(Q17<1001,23,20))))))))))) -> 36 | AM17: =(0.75)/((0.3/AK17)+(0.7/AL17)) -> 21.774194 | AN17: =(0.95)/((0.3/AK17)+(0.7/AL17)) -> 27.580645 | AO17: =AM17-3 -> 18.774194 | AP17: =IF(P17<51,40,(IF(P17<101,42,(IF(P17<201,44,IF(P17<301,46,IF(P17<401,48,(IF(P17<501,50,(IF(P17<1001,55,60))))))))))) -> 40 | AQ17: =0.8*AP17 -> 32 | AR17: =AQ17-5 -> 27 | AS17: =AA17+AQ17 -> 45859 | AT17: =AS17-5 -> 45854 | BF17: =IF(ISBLANK(AA17),0,IF(ISBLANK(BH17),($L$1-BE17),(BH17-BE17))) -> 45293 | BY17: N/A | CB17: =AC17-CA17 -> 0 | CD17: =AC17-CC17 -> 0 | CE17: =(0.3)*(CD17/AK17)+(0.7)*(CD17/AL17) -> 0 | CH17: =(0.3)*((NOW()-W17)/AK17)+(0.7)*((NOW()-W17)/AL17) -> 7.328942 | CI17: =IF(AB17="","PENDING COMP",(AB17-AA17)/AP17) -> PENDING COMP | CK17: =IF(R17="NEW","REV","NON-REV") -> NON-REV
A18: 45691 | D18: HMB | E18: X24124836711 | F18: C-E CONSTRUCTION CORPORATION | G18: PARKWAY, FILINVEST CORPORATE CITY, MUNTINLUPA | H18: MUNTINLUPA CITY | I18: PARAÑAQUE | L18: UG | M18: FCOMP | N18: UG | P18: 556.32 | Q18: 535 | R18: NEW | S18: 3359185 | V18: =U18/T18 -> #DIV/0! | W18: 45685.717 | X18: 45691.546 | AA18: 45730 | AC18: =AA18-W18 -> 44.282639 | AD18: =AA18-X18 -> 38.454167 | AE18: =AB18-AA18 -> -45730 | AF18: =W18+AO18 -> 45702.488 | AG18: =W18+AN18 -> 45710.76 | AH18: =W18+50 -> 45735.717 | AI18: =(0.3)*(AC18/AK18)+(0.7)*(AC18/AL18) -> 1.6798523 | AJ18: =AE18/AP18 -> -831.45455 | AK18: =IF(P18<51,20,(IF(P18<101,23,(IF(P18<201,26,IF(P18<301,28,IF(P18<401,30,(IF(P18<501,32,(IF(P18<1001,40,50))))))))))) -> 40 | AL18: =IF(Q18<51,36,(IF(Q18<101,34,(IF(Q18<201,32,IF(Q18<301,30,IF(Q18<401,28,(IF(Q18<501,26,(IF(Q18<1001,23,20))))))))))) -> 23 | AM18: =(0.75)/((0.3/AK18)+(0.7/AL18)) -> 19.770774 | AN18: =(0.95)/((0.3/AK18)+(0.7/AL18)) -> 25.04298 | AO18: =AM18-3 -> 16.770774 | AP18: =IF(P18<51,40,(IF(P18<101,42,(IF(P18<201,44,IF(P18<301,46,IF(P18<401,48,(IF(P18<501,50,(IF(P18<1001,55,60))))))))))) -> 55 | AQ18: =0.8*AP18 -> 44 | AR18: =AQ18-5 -> 39 | AS18: =AA18+AQ18 -> 45774 | AT18: =AS18-5 -> 45769 | BC18: NO COC | BY18: N/A | CB18: =AC18-CA18 -> 44.282639 | CD18: =AC18-CC18 -> 44.282639 | CE18: =(0.3)*(CD18/AK18)+(0.7)*(CD18/AL18) -> 1.6798523 | CH18: =(0.3)*((NOW()-W18)/AK18)+(0.7)*((NOW()-W18)/AL18) -> 7.9511056 | CI18: =IF(AB18="","PENDING COMP",(AB18-AA18)/AP18) -> PENDING COMP | CK18: =IF(R18="NEW","REV","NON-REV") -> REV
A19: 45721 | D19: CBG | E19: R23935710 | F19: CAVITEX INFRASTRUCTURE CORP., CBG | G19: C5 EXTENSION, MOONWALK, PARANAQUE | H19: PARANAQUE CITY | I19: PARAÑAQUE | L19: UG | M19: FCOMP | N19: UG | P19: 182.95 | R19: RELOC | S19: 462215.14 | V19: =U19/T19 -> #DIV/0! | W19: 45707.365 | X19: 45713.533 | Y19: 45709 | AA19: 45758 | AE19: =AB19-AA19 -> -45758 | AF19: =W19+AO19 -> 45728.572 | AG19: =W19+AN19 -> 45738.027 | AH19: =W19+50 -> 45757.365 | AI19: =(0.3)*(AC19/AK19)+(0.7)*(AC19/AL19) -> 0 | AJ19: =AE19/AP19 -> -1039.9545 | AK19: =IF(P19<51,20,(IF(P19<101,23,(IF(P19<201,26,IF(P19<301,28,IF(P19<401,30,(IF(P19<501,32,(IF(P19<1001,40,50))))))))))) -> 26 | AL19: =IF(Q19<51,36,(IF(Q19<101,34,(IF(Q19<201,32,IF(Q19<301,30,IF(Q19<401,28,(IF(Q19<501,26,(IF(Q19<1001,23,20))))))))))) -> 36 | AM19: =(0.75)/((0.3/AK19)+(0.7/AL19)) -> 24.206897 | AN19: =(0.95)/((0.3/AK19)+(0.7/AL19)) -> 30.662069 | AO19: =AM19-3 -> 21.206897 | AP19: =IF(P19<51,40,(IF(P19<101,42,(IF(P19<201,44,IF(P19<301,46,IF(P19<401,48,(IF(P19<501,50,(IF(P19<1001,55,60))))))))))) -> 44 | AQ19: =0.8*AP19 -> 35.2 | AR19: =AQ19-5 -> 30.2 | AS19: =AA19+AQ19 -> 45793.2 | AT19: =AS19-5 -> 45788.2 | BF19: =IF(ISBLANK(AA19),0,IF(ISBLANK(BH19),($L$1-BE19),(BH19-BE19))) -> 45293 | BY19: N/A | CB19: =AC19-CA19 -> 0 | CD19: =AC19-CC19 -> 0 | CE19: =(0.3)*(CD19/AK19)+(0.7)*(CD19/AL19) -> 0 | CH19: =(0.3)*((NOW()-W19)/AK19)+(0.7)*((NOW()-W19)/AL19) -> 5.8232815 | CI19: =IF(AB19="","PENDING COMP",(AB19-AA19)/AP19) -> PENDING COMP | CK19: =IF(R19="NEW","REV","NON-REV") -> NON-REV | CL19: =IF(CJ19="","",IF(CJ19<91,"0-3 MONTHS",(IF(CJ19<181,"4-6 MONTHS",(IF(CJ19<271,"7-9 MONTHS",IF(CJ19>270,"10 MONTHS AND ABOVE",)))))))
E20: R21138022 | F20: CAVITEX INFRASTRUCTURE CORP. | G20: STREET, MULTINATIONAL VILL, MULTINATIONAL VILL, PARANAQUE | H20: PARAÑAQUE CITY | I20: PARAÑAQUE | L20: UG | M20: SCHED | N20: UG | P20: 178.48 | R20: RELOC | V20: =U20/T20 -> #DIV/0! | W20: 44811 | X20: 44813 | AC20: =AA20-W20 -> -44811 | AD20: =AA20-X20 -> -44813 | AE20: =AB20-AA20 -> 0 | AF20: =W20+AO20 -> 44832.207 | AG20: =W20+AN20 -> 44841.662 | AH20: =W20+50 -> 44861 | AI20: =(0.3)*(AC20/AK20)+(0.7)*(AC20/AL20) -> -1388.375 | AJ20: =AE20/AP20 -> 0 | AK20: =IF(P20<51,20,(IF(P20<101,23,(IF(P20<201,26,IF(P20<301,28,IF(P20<401,30,(IF(P20<501,32,(IF(P20<1001,40,50))))))))))) -> 26 | AL20: =IF(Q20<51,36,(IF(Q20<101,34,(IF(Q20<201,32,IF(Q20<301,30,IF(Q20<401,28,(IF(Q20<501,26,(IF(Q20<1001,23,20))))))))))) -> 36 | AM20: =(0.75)/((0.3/AK20)+(0.7/AL20)) -> 24.206897 | AN20: =(0.95)/((0.3/AK20)+(0.7/AL20)) -> 30.662069 | AO20: =AM20-3 -> 21.206897 | AP20: =IF(P20<51,40,(IF(P20<101,42,(IF(P20<201,44,IF(P20<301,46,IF(P20<401,48,(IF(P20<501,50,(IF(P20<1001,55,60))))))))))) -> 44 | AQ20: =0.8*AP20 -> 35.2 | AR20: =AQ20-5 -> 30.2 | AS20: =AA20+AQ20 -> 35.2 | AT20: =AS20-5 -> 30.2 | BF20: =IF(ISBLANK(AA20),0,IF(ISBLANK(BH20),($L$1-BE20),(BH20-BE20))) -> 0 | CB20: =AC20-CA20 -> -44811 | CD20: =AC20-CC20 -> -44811 | CE20: =(0.3)*(CD20/AK20)+(0.7)*(CD20/AL20) -> -1388.375 | CH20: =(0.3)*((NOW()-W20)/AK20)+(0.7)*((NOW()-W20)/AL20) -> 33.595283 | CI20: =IF(AB20="","PENDING COMP",(AB20-AA20)/AP20) -> PENDING COMP | CK20: =IF(R20="NEW","REV","NON-REV") -> NON-REV
E21: R22006061 | F21: PCA RELOC, Overhead Facilities, N, Y, N, DEPARTMENT OF TRANSPORTATION,, CBG | G21: STREET, EAST SERVICE, SN MARTIN DE PORRES, PARANAQUE | H21: PARANAQUE CITY | I21: PARAÑAQUE | L21: SLEM | M21: SCHED | N21: SLEM | P21: 120.75 | R21: RELOC | V21: =U21/T21 -> #DIV/0! | W21: 45057 | X21: 45065 | AC21: =AA21-W21 -> -45057 | AD21: =AA21-X21 -> -45065 | AE21: =AB21-AA21 -> 0 | AF21: =W21+AO21 -> 45078.207 | AG21: =W21+AN21 -> 45087.662 | AH21: =W21+50 -> 45107 | AI21: =(0.3)*(AC21/AK21)+(0.7)*(AC21/AL21) -> -1395.9968 | AJ21: =AE21/AP21 -> 0 | AK21: =IF(P21<51,20,(IF(P21<101,23,(IF(P21<201,26,IF(P21<301,28,IF(P21<401,30,(IF(P21<501,32,(IF(P21<1001,40,50))))))))))) -> 26 | AL21: =IF(Q21<51,36,(IF(Q21<101,34,(IF(Q21<201,32,IF(Q21<301,30,IF(Q21<401,28,(IF(Q21<501,26,(IF(Q21<1001,23,20))))))))))) -> 36 | AM21: =(0.75)/((0.3/AK21)+(0.7/AL21)) -> 24.206897 | AN21: =(0.95)/((0.3/AK21)+(0.7/AL21)) -> 30.662069 | AO21: =AM21-3 -> 21.206897 | AP21: =IF(P21<51,40,(IF(P21<101,42,(IF(P21<201,44,IF(P21<301,46,IF(P21<401,48,(IF(P21<501,50,(IF(P21<1001,55,60))))))))))) -> 44 | AQ21: =0.8*AP21 -> 35.2 | AR21: =AQ21-5 -> 30.2 | AS21: =AA21+AQ21 -> 35.2 | AT21: =AS21-5 -> 30.2 | CB21: =AC21-CA21 -> -45057 | CD21: =AC21-CC21 -> -45057 | CE21: =(0.3)*(CD21/AK21)+(0.7)*(CD21/AL21) -> -1395.9968 | CH21: =(0.3)*((NOW()-W21)/AK21)+(0.7)*((NOW()-W21)/AL21) -> 25.973488 | CI21: =IF(AB21="","PENDING COMP",(AB21-AA21)/AP21) -> PENDING COMP | CK21: =IF(R21="NEW","REV","NON-REV") -> NON-REV
A22: N/A | B22: N/A | D22: CBG | E22: X24041158243 | F22: PHINMA PROPERTY HOLDINGS CORPORATION | G22: ALUMINUM, METROTOWNE, LAS PINAS CITY | H22: LAS PIÑAS CITY | I22: PARAÑAQUE | L22: UG | M22: SCHED | N22: Jayson Ramores | O22: 174.81 | P22: 174.81 | Q22: 1965 | R22: NEW | S22: 2772246.8 | V22: =U22/T22 -> #DIV/0! | W22: 45828.432 | X22: 45834.644 | Y22: N/A | AC22: =AA22-W22 -> -45828.432 | AD22: =AA22-X22 -> -45834.644 | AE22: =AB22-AA22 -> 0 | AF22: =W22+AO22 -> 45841.548 | AG22: =W22+AN22 -> 45848.846 | AH22: =W22+50 -> 45878.432 | AI22: =(0.3)*(AC22/AK22)+(0.7)*(AC22/AL22) -> -2132.7847 | AJ22: =AE22/AP22 -> 0 | AK22: =IF(P22<51,20,(IF(P22<101,23,(IF(P22<201,26,IF(P22<301,28,IF(P22<401,30,(IF(P22<501,32,(IF(P22<1001,40,50))))))))))) -> 26 | AL22: =IF(Q22<51,36,(IF(Q22<101,34,(IF(Q22<201,32,IF(Q22<301,30,IF(Q22<401,28,(IF(Q22<501,26,(IF(Q22<1001,23,20))))))))))) -> 20 | AM22: =(0.75)/((0.3/AK22)+(0.7/AL22)) -> 16.115702 | AN22: =(0.95)/((0.3/AK22)+(0.7/AL22)) -> 20.413223 | AO22: =AM22-3 -> 13.115702 | AP22: 60 | AQ22: =0.95*AP22 -> 57 | AR22: =AQ22-5 -> 52 | AS22: =AA22+AP22 -> 60 | AT22: =IFERROR(TODAY()-AA22,"") -> 45895 | BE22: =AA22+15 -> 15 | BF22: =IF(ISBLANK(AA22),0,IF(ISBLANK(BH22),(BE22-'C1'!$L$1),(BH22-BE22))) -> 0 | CA22: =IF(AY22="Y",BA22,"0") -> 0 | CB22: =AC22-CA22 -> -45828.432 | CC22: =BA22 -> 0 | CD22: =AC22-BA22 -> -45828.432 | CE22: =(0.3)*(CD22/AK22)+(0.7)*(CD22/AL22) -> -2132.7847 | CH22: =(0.3)*(('C1'!$CF$1-W22)/AK22)+(0.7)*(('C1'!$CF$1-W22)/AL22) -> 1.8879555 | CI22: =CH22-CG22 -> 1.8879555 | CJ22: =CF22/AP22 -> 0 | CK22: =IF(AA22>0,"",'C1'!$CK$1-W22) -> 27.567639 | CL22: =IF(R22="NEW","REV","NON-REV") -> REV | CM22: =IF(CK22="","",IF(CK22<91,"0-3 MONTHS",(IF(CK22<181,"4-6 MONTHS",(IF(CK22<271,"7-9 MONTHS",IF(CK22>270,"10 MONTHS AND ABOVE",))))))) -> 0-3 MONTHS

Sheet C1
D1: PROJECTS | G1: 0 | K1: F | L1: R | X1: PERFORMANCE | AC1: RED(Above 50Days) | AH1: NEW KPI (Starting October 2021) | AL1: COMPUTATION: FOR FCOMP | AQ1: FOR COMP | AT1: (-5) | AU1: 0.75 aspiration | BB1: 0.75 aspiration | BC1: REMARKS | BE1: CERTIFICATE OF COMPLETION | BI1: FIELD AUDIT | BK1: RE-WORK | BO1: MATERIAL BALANCING | BQ1: TRANSMITTAL TO METER | BS1: FOR OLDT DETAILS | CF1: 45869 | CG1: MANUAL | CK1: 45856
A2: Date Received Jacket from P&S | B2: Date Received Awarding of Wo | C2: VIP | D2: WO INITIATOR | E2: WO NO | F2: DESCRIPTION | G2: LOCATION | H2: MUNICIPALITY | I2: AREA OF RESPONSIBILITY | J2: VENDOR REMARKS (free text) | K2: C1 REMARKS (with or without issue) | L2: ASSIGNED | M2: STATUS | N2: SUPERVISOR | O2: C1 CONTRACTOR MANHOUR | P2: TOTAL MANHOURS | Q2: APPLIED LOAD | R2: TYPE | S2: TOTAL PLANNED PROJECT COST | T2: TOTAL ESTIMATED COST (SERVICES) | U2: BILLED / PARTIALLY BILLED COST | V2: % BILLED | W2: DATE WMTRL | X2: DATE SCHED | Y2: DATE RECEIVED BY VC | Z2: ACTUAL DATE COMPLETED ON SITE | AA2: DATE FCOMP | AB2: DATE COMP | AC2: # of days WMTRL TO FCOMP APT Without Exclusion (SPT) | AD2: # of days SCHED TO FCOMP | AE2: # of days COMP | AF2: (0.75) DATE NEEDED FOR WMTRL TO FCOMP | AG2: (0.95) DATE NEEDED FOR FCOMP | AH2: (50 DAYS) DATE NEEDED FOR WMTRL TO FCOMP | AI2: COMPUTED INDEX (WMTRL TO FCOMP) CCTI Without Exclusion | AJ2: COMPUTED INDEX (COMP) | AK2: SPT(M) | AL2: SPT(L) | AM2: 0.75 DURATION (DAYS) | AN2: 0.95 DURATION (DAYS) | AO2: TARGET DAYS | AP2: SPT(M) for comp | AQ2: DURATION (DAYS)COMP | AR2: TARGET DAYS (COMP) | AS2: DATE NEEDED TO COMP | AT2: AGEING DAYS SINCE FCOMP | AU2: REASON (FOR EXCLUSION) | AV2: FOR CCTI EXCLUSION (Y/N) | AW2: ENCODED IN EAM (Y/N) | AX2: VALIDATED BY DCSAM (Y/N) | AY2: For APT Exclusion (Y/N) | AZ2: START DATE | BA2: DURATION FOR EXCLUSION | BB2: END DATE (FOR EXCLUSION) | BC2: REMARKS / FOLLOW UP BY | BD2: REMARKS 2 | BE2: DATE NEEDED TO SUBMIT COC | BF2: AGEING SUBMISSION OF COC | BG2: DATE COMPLETED (FROM COC) | BH2: ACTUAL RECEIVED COC | BI2: DATE AUDIT | BJ2: BY: | BK2: W/ BACK JOB | BL2: BACKJOB TAGGED IN EAM? RE-WORK | BM2: DATE RECEIVED BY CONTRACTOR | BN2: DATE CORRECTED | BO2: DATE MATERIAL BALANCING | BP2: BY | BQ2: Y/N | BR2: EMAILED TO METER | BS2: DT CORRECTION METHOD | BT2: TLN | BU2: WITH POLE REPL? | BV2: ACTUAL FIELD STATUS | BW2: REMARKS3 | BX2: ABF PRINTED BY (FOR AUDIT) | BY2: DATE PRINTED OF POLE TAG FABRICATION FORM | BZ2: POLE / TLN TAGS | CA2: Days for Exclusion based on emails to concerned office/PCTs (Due to customer only - APT) | CB2: APT with Exclusion | CC2: Days for Exclusion based on emails to concerned office/PCTs (All reason - CCTI) | CD2: Duration for CCTI with exclusion | CE2: CCTI With Exclusion | CF2: E2E for PRDI | CG2: CURRENT CCTI (with exclusion) | CH2: CURRENT CCTI | CI2: FINAL CCTI (LESS THAN FCOMP) | CJ2: PRDI | CK2: Days Ageing (as of cell CJ1) | CL2: REV/NON-REV | CM2: AGE BRACKET | CN2: NTC DATE CREATED | CO2: AMOUNT | CP2: NTC | CQ2: DATE RECEIVED BY CONTRACTOR | CR2: DATE COMPLETED NTC | CS2: RUNNING DAYS | CT2: NOV & DEBIT MEMO DATE CREATED | CU2: AMOUNT | CV2: DATE RECEIVED BY CONTRACTOR | CW2: EXT | CX2: UPDATED SUPV | CY2: SUPV NAME | CZ2: STATUS 4/4/25 | DA2: DIFF (in days) FROM WMTRL TO SCHED - 2025 WOs only | DC2: filter | DS2: SUPERVISOR FULL NAME
A3: 44000 | B3: N/A | D3: MN | E3: P2004004805 | F3: MAINT - 44WU_TLN 051257 LOADSPLIT & Inst Addl 25/50/50KVA on CY8-1276/CY8-1275/CY8-1273 | G3: DIAMOND, BERNABE PH 3 SUBD SAN DIONISIO PARAÑAQUE CITY | H3: PARAÑAQUE CITY | I3: PARAÑAQUE | J3: not feasible; for survey team C1 | K3: W/ ISSUE | L3: OPS | M3: SCHED | N3: Dean Carl Borjal | O3: 139.2078 | P3: #N/A | Q3: 0 | R3: OLDT | S3: 560984.1 | T3: 109904.21 | V3: =U3/T3 -> 0 | W3: 43987.697 | X3: 43990.368 | Y3: 43997 | AC3: =AA3-W3 -> -43987.697 | AD3: =AA3-X3 -> -43990.368 | AE3: =AB3-AA3 -> 0 | AF3: =W3+AO3 -> #N/A | AG3: =W3+AN3 -> #N/A | AH3: =W3+50 -> 44037.697 | AI3: =(0.3)*(AC3/AK3)+(0.7)*(AC3/AL3) -> #N/A | AJ3: =AE3/AP3 -> 0 | AK3: =IF(P3<51,20,(IF(P3<101,23,(IF(P3<201,26,IF(P3<301,28,IF(P3<401,30,(IF(P3<501,32,(IF(P3<1001,40,50))))))))))) -> #N/A | AL3: =IF(Q3<51,36,(IF(Q3<101,34,(IF(Q3<201,32,IF(Q3<301,30,IF(Q3<401,28,(IF(Q3<501,26,(IF(Q3<1001,23,20))))))))))) -> 36 | AM3: =(0.75)/((0.3/AK3)+(0.7/AL3)) -> #N/A | AN3: =(0.95)/((0.3/AK3)+(0.7/AL3)) -> #N/A | AO3: =AM3-3 -> #N/A | AP3: 60 | AQ3: =0.95*AP3 -> 57 | AR3: =AQ3-5 -> 52 | AS3: =AA3+AP3 -> 60 | AT3: =IFERROR(TODAY()-AA3,"") -> 45895 | BE3: =AA3+15 -> 15 | BF3: =IF(ISBLANK(AA3),0,IF(ISBLANK(BH3),(BE3-$L$1),(BH3-BE3))) -> 0 | BQ3: N | BS3: Load-splitting | BT3: TLN 051257 | BU3: Y | BV3: With concern | BW3: Transferred from Alvin to Jimmy | CA3: =IF(AY3="Y",BA3,"0") -> 0 | CB3: =AC3-CA3 -> -43987.697 | CC3: =BA3 -> 0 | CD3: =AC3-BA3 -> -43987.697 | CE3: =(0.3)*(CD3/AK3)+(0.7)*(CD3/AL3) -> #N/A | CF3: =IF(AA3="","0",$CF$1-AA3) -> 0 | CH3: =(0.3)*(($CF$1-W3)/AK3)+(0.7)*(($CF$1-W3)/AL3) -> #N/A | CI3: =CH3-CG3 -> #N/A | CJ3: =CF3/AP3 -> 0 | CK3: =IF(AA3>0,"",$CK$1-W3) -> 1868.3028 | CL3: =IF(R3="NEW","REV","NON-REV") -> NON-REV | CM3: =IF(CK3="","",IF(CK3<91,"0-3 MONTHS",(IF(CK3<181,"4-6 MONTHS",(IF(CK3<271,"7-9 MONTHS",IF(CK3>270,"10 MONTHS AND ABOVE",))))))) -> 10 MONTHS AND ABOVE | CP3: =IF(CQ3,"NTC ISSUED","FOR ISSUANCE") -> FOR ISSUANCE | CS3: =IF(AND(CQ3=0,CR3=0), "0",IF(CR3,(CR3-CQ3),TODAY()-CQ3)) -> 0 | CW3: 'P2004004805', | CX3: =VLOOKUP(E3,'[1]List of Work Orders'!$A:$I,9,FALSE) -> ME168443 | DC3: =VLOOKUP(E3,'[2]List of Work Orders'!$A:$F,6,FALSE) -> SCHED | DS3: DCB
A4: 44025 | B4: N/A | D4: MN | E4: P2006000420 | F4: MAINT 45WG TLN 037283; Split Loading Inst Addl 50KVA & 75KVA on A8-0440&ALB1-3102 | G4: BLOCK 32 PUROK 4 UPPER BICUTAN TAGUIG CITY | H4: TAGUIG CITY | I4: PARAÑAQUE | J4: Sept 2023, ayaw magpahukay, for survey wityh design/For survey of C1 Team | K4: W/ ISSUE | L4: VJC | M4: CAN | N4: Jenneth Madrid | O4: 90.9766 | P4: #N/A | Q4: 0 | R4: OLDT | S4: 442337.68 | T4: 91388.65 | V4: =U4/T4 -> 0 | W4: 44022.592 | X4: 44025.524 | Y4: 44025 | AA4: CAN | AC4: =AA4-W4 -> #VALUE! | AD4: =AA4-X4 -> #VALUE! | AE4: =AB4-AA4 -> #VALUE! | AF4: =W4+AO4 -> #N/A | AG4: =W4+AN4 -> #N/A | AH4: =W4+50 -> 44072.592 | AI4: =(0.3)*(AC4/AK4)+(0.7)*(AC4/AL4) -> #VALUE! | AJ4: =AE4/AP4 -> #VALUE! | AK4: =IF(P4<51,20,(IF(P4<101,23,(IF(P4<201,26,IF(P4<301,28,IF(P4<401,30,(IF(P4<501,32,(IF(P4<1001,40,50))))))))))) -> #N/A | AL4: =IF(Q4<51,36,(IF(Q4<101,34,(IF(Q4<201,32,IF(Q4<301,30,IF(Q4<401,28,(IF(Q4<501,26,(IF(Q4<1001,23,20))))))))))) -> 36 | AM4: =(0.75)/((0.3/AK4)+(0.7/AL4)) -> #N/A | AN4: =(0.95)/((0.3/AK4)+(0.7/AL4)) -> #N/A | AO4: =AM4-3 -> #N/A | AP4: 60 | AQ4: =0.95*AP4 -> 57 | AR4: =AQ4-5 -> 52 | AS4: =AA4+AP4 -> #VALUE! | AT4: =IFERROR(TODAY()-AA4,"") | BE4: =AA4+15 -> #VALUE! | BF4: =IF(ISBLANK(AA4),0,IF(ISBLANK(BH4),(BE4-$L$1),(BH4-BE4))) -> #VALUE! | BQ4: N | BS4: Load-splitting | BT4: TLN 037283 | BU4: Y | BV4: For schedule | BW4: Transferred from Marc to Jimmy | CA4: =IF(AY4="Y",BA4,"0") -> 0 | CB4: =AC4-CA4 -> #VALUE! | CC4: =BA4 -> 0 | CD4: =AC4-BA4 -> #VALUE! | CE4: =(0.3)*(CD4/AK4)+(0.7)*(CD4/AL4) -> #VALUE! | CF4: =IF(AA4="","0",$CF$1-AA4) -> #VALUE! | CH4: =(0.3)*(($CF$1-W4)/AK4)+(0.7)*(($CF$1-W4)/AL4) -> #N/A | CI4: =CH4-CG4 -> #N/A | CJ4: =CF4/AP4 -> #VALUE! | CK4: =IF(AA4>0,"",$CK$1-W4) | CL4: =IF(R4="NEW","REV","NON-REV") -> NON-REV | CM4: =IF(CK4="","",IF(CK4<91,"0-3 MONTHS",(IF(CK4<181,"4-6 MONTHS",(IF(CK4<271,"7-9 MONTHS",IF(CK4>270,"10 MONTHS AND ABOVE",))))))) | CP4: =IF(CQ4,"NTC ISSUED","FOR ISSUANCE") -> FOR ISSUANCE | CS4: =IF(AND(CQ4=0,CR4=0), "0",IF(CR4,(CR4-CQ4),TODAY()-CQ4)) -> 0 | CW4: 'P2006000420', | CX4: =VLOOKUP(E4,'[1]List of Work Orders'!$A:$I,9,FALSE) -> ME185284 | DC4: =VLOOKUP(E4,'[2]List of Work Orders'!$A:$F,6,FALSE) -> CAN | DS4: Jenneth Madrid
A5: 44025 | B5: N/A | D5: MN | E5: P2006000610 | F5: MAINT - 55GG_TLN 271296 Split Loading Inst Addl 50KVA on A8-0735 | G5: JASMIN PUROK 6C LOWER BICUTAN TAGUIG CITY | H5: TAGUIG CITY | I5: PARAÑAQUE | J5: Sept 2023, ayaw magpahukay, for survey wityh design/For survey of C1 Team | K5: W/ ISSUE | L5: VJC | M5: CAN | N5: Jenneth Madrid | O5: 22.1094 | P5: #N/A | Q5: 0 | R5: OLDT | S5: 186406.1 | T5: 23237.07 | V5: =U5/T5 -> 0 | W5: 44042.035 | X5: 44048.449 | Y5: 44025 | AA5: CAN | AC5: =AA5-W5 -> #VALUE! | AD5: =AA5-X5 -> #VALUE! | AE5: =AB5-AA5 -> #VALUE! | AF5: =W5+AO5 -> #N/A | AG5: =W5+AN5 -> #N/A | AH5: =W5+50 -> 44092.035 | AI5: =(0.3)*(AC5/AK5)+(0.7)*(AC5/AL5) -> #VALUE! | AJ5: =AE5/AP5 -> #VALUE! | AK5: =IF(P5<51,20,(IF(P5<101,23,(IF(P5<201,26,IF(P5<301,28,IF(P5<401,30,(IF(P5<501,32,(IF(P5<1001,40,50))))))))))) -> #N/A | AL5: =IF(Q5<51,36,(IF(Q5<101,34,(IF(Q5<201,32,IF(Q5<301,30,IF(Q5<401,28,(IF(Q5<501,26,(IF(Q5<1001,23,20))))))))))) -> 36 | AM5: =(0.75)/((0.3/AK5)+(0.7/AL5)) -> #N/A | AN5: =(0.95)/((0.3/AK5)+(0.7/AL5)) -> #N/A | AO5: =AM5-3 -> #N/A | AP5: 60 | AQ5: =0.95*AP5 -> 57 | AR5: =AQ5-5 -> 52 | AS5: =AA5+AP5 -> #VALUE! | AT5: =IFERROR(TODAY()-AA5,"") | BE5: =AA5+15 -> #VALUE! | BF5: =IF(ISBLANK(AA5),0,IF(ISBLANK(BH5),(BE5-$L$1),(BH5-BE5))) -> #VALUE! | BQ5: N | BS5: Load-splitting | BT5: TLN 271296 | BU5: Y | BV5: For schedule | BW5: Transferred from Marc to Jimmy | CA5: =IF(AY5="Y",BA5,"0") -> 0 | CB5: =AC5-CA5 -> #VALUE! | CC5: =BA5 -> 0 | CD5: =AC5-BA5 -> #VALUE! | CE5: =(0.3)*(CD5/AK5)+(0.7)*(CD5/AL5) -> #VALUE! | CF5: =IF(AA5="","0",$CF$1-AA5) -> #VALUE! | CH5: =(0.3)*(($CF$1-W5)/AK5)+(0.7)*(($CF$1-W5)/AL5) -> #N/A | CI5: =CH5-CG5 -> #N/A | CJ5: =CF5/AP5 -> #VALUE! | CK5: =IF(AA5>0,"",$CK$1-W5) | CL5: =IF(R5="NEW","REV","NON-REV") -> NON-REV | CM5: =IF(CK5="","",IF(CK5<91,"0-3 MONTHS",(IF(CK5<181,"4-6 MONTHS",(IF(CK5<271,"7-9 MONTHS",IF(CK5>270,"10 MONTHS AND ABOVE",))))))) | CP5: =IF(CQ5,"NTC ISSUED","FOR ISSUANCE") -> FOR ISSUANCE | CS5: =IF(AND(CQ5=0,CR5=0), "0",IF(CR5,(CR5-CQ5),TODAY()-CQ5)) -> 0 | CW5: 'P2006000610', | CX5: =VLOOKUP(E5,'[1]List of Work Orders'!$A:$I,9,FALSE) -> ME185284 | DC5: =VLOOKUP(E5,'[2]List of Work Orders'!$A:$F,6,FALSE) -> CAN | DS5: Jenneth Madrid
A6: 44125 | B6: N/A | D6: MN | E6: P2006000921 | F6: MAINT- 45WG Load-Split TLN 068256; Inst New 75KVA on DZ1-2057 | G6: ROAD 3 NORTH DAANG HARI BAGONG TANYAG TAGUIG CITY | H6: TAGUIG CITY | I6: PARAÑAQUE | J6: not feasible; for survey team C1; continue digging on Dec 9 | K6: W/ ISSUE | L6: ECOM | M6: FCOMP | N6: Dean Carl Borjal | O6: 40.19 | P6: 40.19 | Q6: 0 | R6: OLDT | S6: 185553.84 | T6: 24087.84 | V6: =U6/T6 -> 0 | W6: 44102.59 | X6: 44104.336 | Y6: 44120 | AA6: 45720 | AC6: =AA6-W6 -> 1617.4097 | AD6: =AA6-X6 -> 1615.6639 | AE6: =AB6-AA6 -> -45720 | AF6: =W6+AO6 -> 44121.364 | AG6: =W6+AN6 -> 44130.171 | AH6: =W6+50 -> 44152.59 | AI6: =(0.3)*(AC6/AK6)+(0.7)*(AC6/AL6) -> 55.710779 | AJ6: =AE6/AP6 -> -762 | AK6: =IF(P6<51,20,(IF(P6<101,23,(IF(P6<201,26,IF(P6<301,28,IF(P6<401,30,(IF(P6<501,32,(IF(P6<1001,40,50))))))))))) -> 20 | AL6: =IF(Q6<51,36,(IF(Q6<101,34,(IF(Q6<201,32,IF(Q6<301,30,IF(Q6<401,28,(IF(Q6<501,26,(IF(Q6<1001,23,20))))))))))) -> 36 | AM6: =(0.75)/((0.3/AK6)+(0.7/AL6)) -> 21.774194 | AN6: =(0.95)/((0.3/AK6)+(0.7/AL6)) -> 27.580645 | AO6: =AM6-3 -> 18.774194 | AP6: 60 | AQ6: =0.95*AP6 -> 57 | AR6: =AQ6-5 -> 52 | AS6: =AA6+AP6 -> 45780 | AT6: =IFERROR(TODAY()-AA6,"") -> 175 | BC6: NO COC | BE6: =AA6+15 -> 45735 | BF6: =IF(ISBLANK(AA6),0,IF(ISBLANK(BH6),(BE6-$L$1),(BH6-BE6))) -> #VALUE! | BQ6: N | BS6: Load-splitting | BT6: TLN 068256 | BU6: Y | BV6: With concern | BW6: Transferred from Alvin to Jimmy | CA6: =IF(AY6="Y",BA6,"0") -> 0 | CB6: =AC6-CA6 -> 1617.4097 | CC6: =BA6 -> 0 | CD6: =AC6-BA6 -> 1617.4097 | CE6: =(0.3)*(CD6/AK6)+(0.7)*(CD6/AL6) -> 55.710779 | CF6: =IF(AA6="","0",$CF$1-AA6) -> 149 | CH6: =(0.3)*(($CF$1-W6)/AK6)+(0.7)*(($CF$1-W6)/AL6) -> 60.843002 | CI6: =CH6-CG6 -> 60.843002 | CJ6: =CF6/AP6 -> 2.4833333 | CK6: =IF(AA6>0,"",$CK$1-W6) | CL6: =IF(R6="NEW","REV","NON-REV") -> NON-REV | CM6: =IF(CK6="","",IF(CK6<91,"0-3 MONTHS",(IF(CK6<181,"4-6 MONTHS",(IF(CK6<271,"7-9 MONTHS",IF(CK6>270,"10 MONTHS AND ABOVE",))))))) | CP6: =IF(CQ6,"NTC ISSUED","FOR ISSUANCE") -> FOR ISSUANCE | CS6: =IF(AND(CQ6=0,CR6=0), "0",IF(CR6,(CR6-CQ6),TODAY()-CQ6)) -> 0 | CW6: 'P2006000921', | CX6: =VLOOKUP(E6,'[1]List of Work Orders'!$A:$I,9,FALSE) -> ME168443 | DC6: =VLOOKUP(E6,'[2]List of Work Orders'!$A:$F,6,FALSE) -> FCOMP | DS6: RONILO GANGE JR.
A7: 44124 | B7: N/A | D7: MN | E7: P2009000813 | F7: MAINT 424WU Uprate from kVA to 75kVA : [039062|WA372558|A5-0334|QS] | G7: ROSAL STO. NINO STO. NINO PARANAQUE | H7: PARAÑAQUE CITY | I7: PARAÑAQUE | J7: for field survey by crew | K7: W/O ISSUE | L7: CHALLENGER | M7: INPRG | N7: Isan Carlo Lazaro | O7: 15.752 | P7: #N/A | Q7: 0 | R7: OLDT | S7: 160243.02 | T7: 10642.55 | V7: =U7/T7 -> 0 | W7: 44118.688 | X7: 44120.381 | Y7: 44103 | AC7: =AA7-W7 -> -44118.688 | AD7: =AA7-X7 -> -44120.381 | AE7: =AB7-AA7 -> 0 | AF7: =W7+AO7 -> #N/A | AG7: =W7+AN7 -> #N/A | AH7: =W7+50 -> 44168.688 | AI7: =(0.3)*(AC7/AK7)+(0.7)*(AC7/AL7) -> #N/A | AJ7: =AE7/AP7 -> 0 | AK7: =IF(P7<51,20,(IF(P7<101,23,(IF(P7<201,26,IF(P7<301,28,IF(P7<401,30,(IF(P7<501,32,(IF(P7<1001,40,50))))))))))) -> #N/A | AL7: =IF(Q7<51,36,(IF(Q7<101,34,(IF(Q7<201,32,IF(Q7<301,30,IF(Q7<401,28,(IF(Q7<501,26,(IF(Q7<1001,23,20))))))))))) -> 36 | AM7: =(0.75)/((0.3/AK7)+(0.7/AL7)) -> #N/A | AN7: =(0.95)/((0.3/AK7)+(0.7/AL7)) -> #N/A | AO7: =AM7-3 -> #N/A | AP7: 60 | AQ7: =0.95*AP7 -> 57 | AR7: =AQ7-5 -> 52 | AS7: =AA7+AP7 -> 60 | AT7: =IFERROR(TODAY()-AA7,"") -> 45895 | BC7: Transferred to DCB (point person for OLDT) | BE7: =AA7+15 -> 15 | BF7: =IF(ISBLANK(AA7),0,IF(ISBLANK(BH7),(BE7-$L$1),(BH7-BE7))) -> 0 | BQ7: N | BS7: Uprating | BT7: TLN 039062 | BU7: N | BV7: For schedule | BW7: Transferred from Alvin to Jimmy | CA7: =IF(AY7="Y",BA7,"0") -> 0 | CB7: =AC7-CA7 -> -44118.688 | CC7: =BA7 -> 0 | CD7: =AC7-BA7 -> -44118.688 | CE7: =(0.3)*(CD7/AK7)+(0.7)*(CD7/AL7) -> #N/A | CF7: =IF(AA7="","0",$CF$1-AA7) -> 0 | CH7: =(0.3)*(($CF$1-W7)/AK7)+(0.7)*(($CF$1-W7)/AL7) -> #N/A | CI7: =CH7-CG7 -> #N/A | CJ7: =CF7/AP7 -> 0 | CK7: =IF(AA7>0,"",$CK$1-W7) -> 1737.3118 | CL7: =IF(R7="NEW","REV","NON-REV") -> NON-REV | CM7: =IF(CK7="","",IF(CK7<91,"0-3 MONTHS",(IF(CK7<181,"4-6 MONTHS",(IF(CK7<271,"7-9 MONTHS",IF(CK7>270,"10 MONTHS AND ABOVE",))))))) -> 10 MONTHS AND ABOVE | CP7: =IF(CQ7,"NTC ISSUED","FOR ISSUANCE") -> FOR ISSUANCE | CS7: =IF(AND(CQ7=0,CR7=0), "0",IF(CR7,(CR7-CQ7),TODAY()-CQ7)) -> 0 | CW7: 'P2009000813', | CX7: =VLOOKUP(E7,'[1]List of Work Orders'!$A:$I,9,FALSE) -> ME166067 | DC7: =VLOOKUP(E7,'[2]List of Work Orders'!$A:$F,6,FALSE) -> INPRG | DS7: DCB
A8: 44133 | B8: N/A | D8: MN | E8: P2006000924 | F8: MAINT- 45WG Load-Split TLN 033207; Inst Addl 75KVA on DZ2-2222 | G8: ROAD 1 BAGONG TANYAG BAGONG TANYAG TAGUIG CITY | H8: TAGUIG CITY | I8: PARAÑAQUE | J8: ongoing | K8: W/ ISSUE | L8: POWERHOUSE | M8: INPRG | N8: Jenneth Madrid | O8: 59.228 | P8: #N/A | Q8: 0 | R8: OLDT | S8: 293278.03 | T8: 52996.47 | V8: =U8/T8 -> 0 | W8: 44125.726 | X8: 44127.658 | Y8: 44133 | AC8: =AA8-W8 -> -44125.726 | AD8: =AA8-X8 -> -44127.658 | AE8: =AB8-AA8 -> 0 | AF8: =W8+AO8 -> #N/A | AG8: =W8+AN8 -> #N/A | AH8: =W8+50 -> 44175.726 | AI8: =(0.3)*(AC8/AK8)+(0.7)*(AC8/AL8) -> #N/A | AJ8: =AE8/AP8 -> 0 | AK8: =IF(P8<51,20,(IF(P8<101,23,(IF(P8<201,26,IF(P8<301,28,IF(P8<401,30,(IF(P8<501,32,(IF(P8<1001,40,50))))))))))) -> #N/A | AL8: =IF(Q8<51,36,(IF(Q8<101,34,(IF(Q8<201,32,IF(Q8<301,30,IF(Q8<401,28,(IF(Q8<501,26,(IF(Q8<1001,23,20))))))))))) -> 36 | AM8: =(0.75)/((0.3/AK8)+(0.7/AL8)) -> #N/A | AN8: =(0.95)/((0.3/AK8)+(0.7/AL8)) -> #N/A | AO8: =AM8-3 -> #N/A | AP8: 60 | AQ8: =0.95*AP8 -> 57 | AR8: =AQ8-5 -> 52 | AS8: =AA8+AP8 -> 60 | AT8: =IFERROR(TODAY()-AA8,"") -> 45895 | BE8: =AA8+15 -> 15 | BF8: =IF(ISBLANK(AA8),0,IF(ISBLANK(BH8),(BE8-$L$1),(BH8-BE8))) -> 0 | BQ8: N | BS8: Load-splitting | BT8: TLN 033207 | BU8: Y | BV8: For schedule | BW8: Transferred from Marc to Jimmy / With picture after | CA8: =IF(AY8="Y",BA8,"0") -> 0 | CB8: =AC8-CA8 -> -44125.726 | CC8: =BA8 -> 0 | CD8: =AC8-BA8 -> -44125.726 | CE8: =(0.3)*(CD8/AK8)+(0.7)*(CD8/AL8) -> #N/A | CF8: =IF(AA8="","0",$CF$1-AA8) -> 0 | CH8: =(0.3)*(($CF$1-W8)/AK8)+(0.7)*(($CF$1-W8)/AL8) -> #N/A | CI8: =CH8-CG8 -> #N/A | CJ8: =CF8/AP8 -> 0 | CK8: =IF(AA8>0,"",$CK$1-W8) -> 1730.2743 | CL8: =IF(R8="NEW","REV","NON-REV") -> NON-REV | CM8: =IF(CK8="","",IF(CK8<91,"0-3 MONTHS",(IF(CK8<181,"4-6 MONTHS",(IF(CK8<271,"7-9 MONTHS",IF(CK8>270,"10 MONTHS AND ABOVE",))))))) -> 10 MONTHS AND ABOVE | CP8: =IF(CQ8,"NTC ISSUED","FOR ISSUANCE") -> FOR ISSUANCE | CS8: =IF(AND(CQ8=0,CR8=0), "0",IF(CR8,(CR8-CQ8),TODAY()-CQ8)) -> 0 | CW8: 'P2006000924', | CX8: =VLOOKUP(E8,'[1]List of Work Orders'!$A:$I,9,FALSE) -> ME185284 | DC8: =VLOOKUP(E8,'[2]List of Work Orders'!$A:$F,6,FALSE) -> INPRG | DS8: Jenneth Madrid
